Workbook
Name \0: #REF!
Name \0: #REF!
Name \a: #REF!
Name \a: #REF!
Name \b: #REF!
Name \c: #REF!
Name \d: #REF!
Name \e: #REF!
Name \f: #REF!
Name \g: #REF!
Name \h: #REF!
Name \i: #REF!
Name \j: #REF!
Name \k: #REF!
Name \l: #REF!
Name \m: #REF!
Name \s: #REF!
Name \u: #REF!
Name \z: #REF!
Name ____ABS93: #REF!
Name ____ABS94: #REF!
Name ____ABS95: #REF!
Name ____ABS96: #REF!
Name ____ABS97: #REF!
Name ____DEP93: #REF!
Name ____DEP94: #REF!
Name ____DEP95: #REF!
Name ____DEP96: #REF!
Name ____DEP97: #REF!
Name ____DPS93: #REF!
Name ____DPS94: #REF!
Name ____DPS95: #REF!
Name ____DPS96: #REF!
Name ____DPS97: #REF!
Name ___ABS93: #REF!
Name ___ABS94: #REF!
Name ___ABS95: #REF!
Name ___ABS96: #REF!
Name ___ABS97: #REF!
Name ___DEP93: #REF!
Name ___DEP94: #REF!
Name ___DEP95: #REF!
Name ___DEP96: #REF!
Name ___DEP97: #REF!
Name ___DPS93: #REF!
Name ___DPS94: #REF!
Name ___DPS95: #REF!
Name ___DPS96: #REF!
Name ___DPS97: #REF!
Name __ABS93: #REF!
Name __ABS94: #REF!
Name __ABS95: #REF!
Name __ABS96: #REF!
Name __ABS97: #REF!
Name __DBS50: #REF!
Name __DBS50: #REF!
Name __DEP93: #REF!
Name __DEP93: #REF!
Name __DEP94: #REF!
Name __DEP94: #REF!

Sheet Coversheet
C2: GOLDMAN SACHS
C3: GLOBAL INVESTMENT RESEARCH
C4: Consumers Team
B6: 605499.SS
B7: Eastroc Beverage
C8: Rating | H8: Buy | K8: RATING | L8: Buy
C9: Target price | H9: 350 | K9: TARGET_PRICE | L9: 350
C10: M&A probability | H10: 3 | K10: MA_PROB | L10: 3
C11: Market Cap (US$ mn), price as of | F11: 45979 | H11: 18775.432 | K11: CAPI | L11: 18775.432
C12: Current shares outstanding (mn) | H12: 520.013 | K12: NUM_SH1 | L12: 520.013
C13: Currency | H13: CNY | K13: PRICE_CURRENCY_ISO | L13: CNY
C14: Valuation Methodology | H14: P/E
C15: Current Publication Date | H15: 45979 | K15: TARGET_PRICE_CHANGE_DATE | L15: 8-Oct-2025
C16: Previous Publication Date | H16: 16-Oct-2025
B17: Team Contacts
B18: Primary analyst
B19: Leaf Liu, Leaf.Liu@gs.com, +852-3966-4169, Goldman Sachs (Asia) L.L.C.
B20: Associated analyst
B21: Christina Liu, Christina.Liu@gs.com, +852-2978-6983, Goldman Sachs (Asia) L.L.C.

Sheet Summary financial
A1: Eastroc Beverage (605499.SS)
A2: Rmb millions
A3: Divisional P/L | B3: FY17 | C3: FY18 | D3: FY19 | E3: FY20 | F3: FY21 | G3: FY22 | H3: FY23 | I3: FY24 | J3: FY25E | K3: FY26E | L3: FY27E | M3: FY28E | O3: 18-23 5yr CAGR | P3: 23-28 5yr CAGR | Q3: 21-23 2yr CAGR | R3: 24-26E 2yr CAGR | S3: 23-26E 3yr CAGR | U3: 1H20 | V3: 2H20 | W3: 1H21 | X3: 2H21 | Y3: 1H22 | Z3: 2H22 | AA3: 1H23 | AB3: 2H23 | AD3: 1Q20 | AE3: 2Q20 | AF3: 3Q20 | AG3: 4Q20 | AH3: 1Q21 | AI3: 2Q21 | AJ3: 3Q21 | AK3: 4Q21 | AL3: 1Q22 | AM3: 2Q22 | AN3: 3Q22 | AO3: 4Q22 | AP3: 1Q23 | AQ3: 2Q23 | AR3: 3Q23 | AS3: 4Q23 | AT3: 1Q24 | AU3: 2Q24 | AV3: 3Q24 | AW3: 4Q24 | AX3: 1Q25 | AY3: 2Q25E | AZ3: 3Q25E | BA3: 4Q25E | BB3: 1Q26E | BC3: 2Q26E | BD3: 3Q26E | BE3: 4Q26E
A4: Revenue
A5: =+Segment!B11 -> Energy drinks | B5: =+Segment!F11 -> 0 | C5: =+Segment!G11 -> 2885.4971 | D5: =+Segment!H11 -> 4003.0305 | E5: =+Segment!I11 -> 4655.1538 | F5: =+Segment!J11 -> 6591.8979 | G5: =+Segment!K11 -> 8172.3068 | H5: =+Segment!L11 -> 10336.009 | I5: =+Segment!M11 -> 13303.584 | ... L5: =+Segment!P11 -> 21255.922 | M5: =+Segment!#REF! -> #REF! | O5: =(H5/C5)^(1/5)-1 -> 0.29070338 | P5: =(M5/H5)^(1/5)-1 -> #REF! | Q5: =(H5/F5)^(1/2)-1 -> 0.25219281 | R5: =(K5/I5)^(1/2)-1 -> 0.18386781 | S5: =(K5/H5)^(1/3)-1 -> 0.21732742 | U5: =+Segment!V11 -> 2272.3273 | V5: =+Segment!W11 -> 2382.8265 | W5: =+Segment!X11 -> 3547.2256 | X5: =+Segment!Y11 -> 3044.6723 | Y5: =+Segment!Z11 -> 4118.3335 | Z5: =+Segment!AA11 -> 4053.9733 | AA5: =+Segment!AB11 -> 5134.9885 | AB5: =+Segment!AC11 -> 5201.0205 | AD5: =+Segment!BB11 -> 0 | AE5: =+Segment!BC11 -> 0 | AF5: =+Segment!BD11 -> 1493.9188 | AG5: =+Segment!BE11 -> 888.9077 | AH5: =+Segment!BF11 -> 1645.0964 | AI5: =+Segment!BG11 -> 1902.1292 | AJ5: =+Segment!BH11 -> 1791.118 | AK5: =+Segment!BI11 -> 1253.5543 | ... BE5: =+Segment!CC11 -> 3572.7799
A6: =+Segment!B12 -> Other beverage | B6: =+Segment!F12 -> 0 | C6: =+Segment!G12 -> 135.6807 | D6: =+Segment!H12 -> 188.7768 | E6: =+Segment!I12 -> 280.5093 | F6: =+Segment!J12 -> 371.94956 | G6: =+Segment!K12 -> 319.02572 | H6: =+Segment!L12 -> 914.47521 | I6: =+Segment!M12 -> 2518.1799 | ... L6: =+Segment!P12 -> 8490.3589 | M6: =+Segment!#REF! -> #REF! | O6: =(H6/C6)^(1/5)-1 -> 0.4646396 | P6: =(M6/H6)^(1/5)-1 -> #REF! | Q6: =(H6/F6)^(1/2)-1 -> 0.56799236 | R6: =(K6/I6)^(1/2)-1 -> 0.63419531 | S6: =(K6/H6)^(1/3)-1 -> 0.94464759 | U6: =+Segment!V12 -> 186.8873 | V6: =+Segment!W12 -> 134.2044 | W6: =+Segment!X12 -> 125.26 | X6: =+Segment!Y12 -> 246.68956 | Y6: =+Segment!Z12 -> 165.92805 | Z6: =+Segment!AA12 -> 153.09767 | AA6: =+Segment!AB12 -> 319.9848 | AB6: =+Segment!AC12 -> 594.49041 | AD6: =+Segment!BB12 -> 0 | AE6: =+Segment!BC12 -> 0 | AF6: =+Segment!BD12 -> 73.6436 | AG6: =+Segment!BE12 -> 60.5608 | AH6: =+Segment!BF12 -> 61.5905 | AI6: =+Segment!BG12 -> 63.6695 | AJ6: =+Segment!BH12 -> 85.615 | AK6: =+Segment!BI12 -> 161.07456 | ... BE6: =+Segment!CC12 -> 1138.6074
A7: Bushuila | B7: =+Segment!F14 -> 0 | H7: =+Segment!L188 -> 393.04206 | I7: =+Segment!M188 -> 1495.0141 | J7: =+Segment!N188 -> 3303.9811 | K7: =+Segment!O188 -> 4493.4143 | L7: =+Segment!P188 -> 5684.1691 | M7: =+Segment!#REF! -> #REF! | R7: =(K7/I7)^(1/2)-1 -> 0.73366663 | S7: =(K7/H7)^(1/3)-1 -> 1.2527473 | U7: =+Segment!V14 -> 0 | V7: =+Segment!W14 -> 0 | W7: =+Segment!X14 -> 0 | X7: =+Segment!Y14 -> 0 | Y7: =+Segment!Z14 -> 0 | Z7: =+Segment!AA14 -> 0 | AA7: =+Segment!AB14 -> 0 | AB7: =+Segment!AC14 -> 0 | AD7: =+Segment!BB14 -> 0 | AE7: =+Segment!BC14 -> 0 | AF7: =+Segment!BD14 -> 0 | AG7: =+Segment!BE14 -> 0 | AH7: =+Segment!BF14 -> 0 | AI7: =+Segment!BG14 -> 0 | AJ7: =+Segment!BH14 -> 0 | AK7: =+Segment!BI14 -> 0 | AT7: =Segment!BR13 -> 157.65 | AU7: =Segment!BS13 -> 318.1878 | AV7: =Segment!BT13 -> 736.6667 | AW7: =Segment!BU13 -> 282.50957 | AX7: =Segment!BV13 -> 569.8415 | AY7: =Segment!BW13 -> 922.89694 | AZ7: =Segment!BX13 -> 1354.0319 | BA7: =Segment!BY13 -> 457.21079 | ... BE7: =Segment!CC13 -> 700.12431
A8: =+Segment!B16 -> Others | B8: =+Segment!F16 -> 0 | H8: =Segment!L190 -> 521.43315 | I8: =I6-I7 -> 1023.1658 | J8: =J6-J7 -> 1727.8459 | K8: =K6-K7 -> 2231.6225 | L8: =L6-L7 -> 2806.1898 | M8: =M6-M7 -> #REF! | R8: =(K8/I8)^(1/2)-1 -> 0.47685331 | S8: =(K8/H8)^(1/3)-1 -> 0.62358126 | U8: =+Segment!V16 -> 10.248172 | V8: =+Segment!W16 -> 12.591228 | W8: =+Segment!X16 -> 9.7761564 | X8: =+Segment!Y16 -> 4.1988779 | Y8: =+Segment!Z16 -> 7.0124213 | Z8: =+Segment!AA16 -> 7.0447582 | AA8: =+Segment!AB16 -> 5.2116289 | AB8: =+Segment!AC16 -> 7.0982465 | AD8: =+Segment!BB16 -> 0 | AE8: =+Segment!BC16 -> 0 | AF8: =+Segment!BD16 -> 6.5718274 | AG8: =+Segment!BE16 -> 6.0194004 | AH8: =+Segment!BF16 -> 4.5748272 | AI8: =+Segment!BG16 -> 5.2013272 | AJ8: =+Segment!BH16 -> 1.2177031 | AK8: =+Segment!BI16 -> 2.9811769 | AT8: =+Segment!BR15 -> 217.1284 | AU8: =+Segment!BS15 -> 310.6186 | AV8: =+Segment!BT15 -> 279.6263 | AW8: =+Segment!BU15 -> 215.79248 | AX8: =+Segment!BV15 -> 374.7969 | AY8: =+Segment!BW15 -> 502.50692 | AZ8: =+Segment!BX15 -> 547.02008 | BA8: =+Segment!BY15 -> 303.52199 | ... BE8: =+Segment!CC15 -> 438.48307
A9: Total | B9: =+Segment!F9 -> 2843.8076 | C9: =+Segment!G9 -> 3037.536 | D9: =+Segment!H9 -> 4208.7285 | E9: =+Segment!I9 -> 4958.5026 | F9: =+Segment!J9 -> 6977.8225 | G9: =+Segment!K9 -> 8505.3897 | H9: =+Segment!L9 -> 11262.794 | I9: =+Segment!M9 -> 15838.852 | ... L9: =+Segment!P9 -> 29791.987 | M9: =+Segment!#REF! -> #REF! | O9: =(H9/C9)^(1/5)-1 -> 0.2996456 | P9: =(M9/H9)^(1/5)-1 -> #REF! | Q9: =(H9/F9)^(1/2)-1 -> 0.2704662 | R9: =(K9/I9)^(1/2)-1 -> 0.26644112 | S9: =(K9/H9)^(1/3)-1 -> 0.31144229 | U9: =+Segment!V9 -> 2469.4627 | V9: =+Segment!W9 -> 2489.0399 | W9: =+Segment!X9 -> 3682.2618 | X9: =+Segment!Y9 -> 3295.5607 | Y9: =+Segment!Z9 -> 4291.274 | Z9: =+Segment!AA9 -> 4214.1157 | AA9: =+Segment!AB9 -> 5460.1849 | AB9: =+Segment!AC9 -> 5802.6092 | AD9: =+Segment!BB9 -> 933.21619 | AE9: =+Segment!BC9 -> 1536.2465 | AF9: =+Segment!BD9 -> 1574.1342 | AG9: =+Segment!BE9 -> 914.90569 | AH9: =+Segment!BF9 -> 1711.2617 | AI9: =+Segment!BG9 -> 1971 | AJ9: =+Segment!BH9 -> 1877.9507 | AK9: =+Segment!BI9 -> 1417.61 | ... BE9: =+Segment!CC9 -> 4744.3135
A11: Gross Profit | BA11: =SUM(AZ9:BA9)/SUM(AV9:AW9)-1 -> 0.28745217
A12: =+A5 -> Energy drinks | B12: =+Segment!F30 -> 0 | C12: =+Segment!G30 -> 1387.4148 | D12: =+Segment!H30 -> 1961.9362 | E12: =+Segment!I30 -> 2265.5034 | F12: =+Segment!J30 -> 3038.1215 | G12: =+Segment!K30 -> 3535.6389 | H12: =+Segment!L30 -> 4684.7677 | I12: =+Segment!M30 -> 6413.2648 | ... L12: =+Segment!P30 -> 11072.91 | M12: =+Segment!#REF! -> #REF! | O12: =(H12/C12)^(1/5)-1 -> 0.27554665 | P12: =(M12/H12)^(1/5)-1 -> #REF! | Q12: =(H12/F12)^(1/2)-1 -> 0.24177085 | R12: =(K12/I12)^(1/2)-1 -> 0.23066221 | S12: =(K12/H12)^(1/3)-1 -> 0.27513533
A13: =+A6 -> Other beverage | B13: =+Segment!F31 -> 0 | C13: =+Segment!G31 -> -3.481 | D13: =+Segment!H31 -> -8.97 | E13: =+Segment!I31 -> 22.271 | F13: =+Segment!J31 -> 48.353632 | G13: =+Segment!K31 -> 54.449432 | H13: =+Segment!L31 -> 157.75569 | I13: =+Segment!M31 -> 672.06462 | ... L13: =+Segment!P31 -> 2664.3521 | M13: =+Segment!#REF! -> #REF! | O13: =(H13/C13)^(1/5)-1 -> -3.1441551 | P13: =(M13/H13)^(1/5)-1 -> #REF! | Q13: =(H13/F13)^(1/2)-1 -> 0.80625044 | R13: =(K13/I13)^(1/2)-1 -> 0.69026364 | S13: =(K13/H13)^(1/3)-1 -> 1.3002673
A14: Bushuila | H14: =Segment!L232 -> 104.03547 | I14: =Segment!M232 -> 444.24392 | J14: =Segment!N232 -> 1063.8819 | K14: =Segment!O232 -> 1545.7345 | L14: =Segment!P232 -> 2069.0375 | M14: =Segment!#REF! -> #REF!
A15: =+A7 -> Bushuila | B15: =+Segment!F32 -> 0 | C15: =+Segment!G32 -> -0.9663 | D15: =+Segment!H32 -> 2.9421 | E15: =+Segment!I32 -> 6.5172 | F15: =+Segment!J32 -> 0 | G15: =+Segment!K32 -> 0 | H15: =+Segment!L32 -> 0 | I15: =+Segment!M32 -> 0 | ... L15: =+Segment!P32 -> 0 | M15: =+Segment!#REF! -> #REF! | S15: n.m.
A16: Others | H16: =Segment!L235 -> 63.047421 | I16: =Segment!M235 -> 227.8207 | J16: =Segment!N235 -> 241.00764 | K16: =Segment!O235 -> 374.34817 | L16: =Segment!P235 -> 595.31455 | M16: =Segment!#REF! -> #REF!
A17: Others | B17: =+Segment!F33 -> 0 | C17: =+Segment!G33 -> 12.360143 | D17: =+Segment!H33 -> 14.04294 | E17: =+Segment!I33 -> 22.880594 | F17: =+Segment!J33 -> 9.782524 | G17: =+Segment!K33 -> 9.8400256 | H17: =+Segment!L33 -> 8.6169128 | I17: =+Segment!M33 -> 11.961381 | ... L17: =+Segment!P33 -> 31.994119 | M17: =+Segment!#REF! -> #REF! | S17: =(K17/H17)^(1/3)-1 -> 0.38812832
A18: Total | B18: =+Segment!F29 -> 1362.8128 | C18: =+Segment!G29 -> 1396.2939 | D18: =+Segment!H29 -> 1967.0092 | E18: =+Segment!I29 -> 2310.6551 | F18: =+Segment!J29 -> 3096.2577 | G18: =+Segment!K29 -> 3599.9284 | H18: =+Segment!L29 -> 4851.1403 | I18: =+Segment!M29 -> 7097.2908 | ... L18: =+Segment!P29 -> 13769.256 | M18: =+Segment!#REF! -> #REF! | O18: =(H18/C18)^(1/5)-1 -> 0.28284267 | P18: =(M18/H18)^(1/5)-1 -> #REF! | Q18: =(H18/F18)^(1/2)-1 -> 0.25170899 | R18: =(K18/I18)^(1/2)-1 -> 0.28154062 | S18: =(K18/H18)^(1/3)-1 -> 0.33938214
A20: Group OP | B20: =B70 -> 380.8296 | C20: =C70 -> 243.64619 | D20: =D70 -> 709.8522 | E20: =E70 -> 1000.5113 | F20: =F70 -> 1356.6212 | G20: =G70 -> 1758.7333 | H20: =H70 -> 2351.473 | I20: =I70 -> 3768.0932 | ... M20: =M70 -> #REF! | O20: =(H20/C20)^(1/5)-1 -> 0.57367873 | P20: =(M20/H20)^(1/5)-1 -> #REF! | Q20: =(H20/F20)^(1/2)-1 -> 0.3165601 | R20: =(K20/I20)^(1/2)-1 -> 0.33523701 | S20: =(K20/H20)^(1/3)-1 -> 0.41894683
A22: Breakdown
A23: Revenues
A24: =+A5 -> Energy drinks | B24: =B5/B$9 -> 0 | C24: =C5/C$9 -> 0.94994663 | D24: =D5/D$9 -> 0.95112586 | E24: =E5/E$9 -> 0.9388225 | F24: =F5/F$9 -> 0.94469269 | G24: =G5/G$9 -> 0.96083861 | H24: =H5/H$9 -> 0.91771269 | I24: =I5/I$9 -> 0.83993363 | ... M24: =M5/M$9 -> #REF!
A25: =+A6 -> Other beverage | B25: =B6/B$9 -> 0 | C25: =C6/C$9 -> 0.044668014 | D25: =D6/D$9 -> 0.044853642 | E25: =E6/E$9 -> 0.056571373 | F25: =F6/F$9 -> 0.053304532 | G25: =G6/G$9 -> 0.037508654 | H25: =H6/H$9 -> 0.081194347 | I25: =I6/I$9 -> 0.15898753 | ... M25: =M6/M$9 -> #REF!
A26: Bushuila | H26: =H7/H5 -> 0.038026482 | I26: =I7/I5 -> 0.11237679 | J26: =J7/J5 -> 0.2073234 | K26: =K7/K5 -> 0.2409913 | L26: =L7/L5 -> 0.26741579 | M26: =M7/M5 -> #REF!
A27: =+A7 -> Bushuila | B27: =B7/B$9 -> 0 | C27: =C7/C$9 -> 0 | D27: =D7/D$9 -> 0 | E27: =E7/E$9 -> 0 | F27: =F7/F$9 -> 0 | G27: =G7/G$9 -> 0 | H27: =H7/H$9 -> 0.034897385 | I27: =I7/I$9 -> 0.094389043 | ... M27: =M7/M$9 -> #REF!
A28: Others | B28: =B8/B$9 -> 0 | C28: =C8/C$9 -> 0 | D28: =D8/D$9 -> 0 | E28: =E8/E$9 -> 0 | F28: =F8/F$9 -> 0 | G28: =G8/G$9 -> 0 | H28: =H8/H$9 -> 0.046296962 | I28: =I8/I$9 -> 0.064598482 | ... M28: =M8/M$9 -> #REF!
A29: Others | H29: =H8/H9 -> 0.046296962 | I29: =I8/I9 -> 0.064598482 | J29: =J8/J9 -> 0.082310083 | K29: =K8/K9 -> 0.087847018 | L29: =L8/L9 -> 0.094192773 | M29: =M8/M9 -> #REF!
A30: Total | B30: =+SUM(B24:B28) -> 0 | C30: =+SUM(C24:C28) -> 0.99461465 | D30: =+SUM(D24:D28) -> 0.9959795 | E30: =+SUM(E24:E28) -> 0.99539387 | F30: =+SUM(F24:F28) -> 0.99799722 | G30: =+SUM(G24:G28) -> 0.99834726 | H30: =+SUM(H24:H25) -> 0.99890703 | I30: =+SUM(I24:I25) -> 0.99892115 | J30: =+SUM(J24:J25) -> 0.99887005 | K30: =+SUM(K24:K25) -> 0.99870387 | L30: =+SUM(L24:L25) -> 0.99846583 | M30: =+SUM(M24:M25) -> #REF!
A32: Gross Profit
A33: =+A24 -> Energy drinks | B33: =B12/B$18 -> 0 | C33: =C12/C$18 -> 0.99364092 | D33: =D12/D$18 -> 0.99742095 | E33: =E12/E$18 -> 0.98045935 | F33: =F12/F$18 -> 0.98122373 | G33: =G12/G$18 -> 0.98214146 | H33: =H12/H$18 -> 0.96570443 | I33: =I12/I$18 -> 0.90362153 | ... M33: =M12/M$18 -> #REF!
A34: =+A25 -> Other beverage | B34: =B13/B$18 -> 0 | C34: =C13/C$18 -> -0.0024930281 | D34: =D13/D$18 -> -0.0045602227 | E34: =E13/E$18 -> 0.0096383921 | F34: =F13/F$18 -> 0.015616798 | G34: =G13/G$18 -> 0.015125143 | H34: =H13/H$18 -> 0.0325193 | I34: =I13/I$18 -> 0.094693121 | ... M34: =M13/M$18 -> #REF!
A35: =+A27 -> Bushuila | B35: =B15/B$18 -> 0 | C35: =C15/C$18 -> -0.00069204626 | D35: =D15/D$18 -> 0.0014957225 | E35: =E15/E$18 -> 0.0028204988 | F35: =F15/F$18 -> 0 | G35: =G15/G$18 -> 0 | H35: =H15/H$18 -> 0 | I35: =I15/I$18 -> 0 | ... M35: =M15/M$18 -> #REF!
A36: Others | B36: =B17/B$18 -> 0 | C36: =C17/C$18 -> 0.0088521065 | D36: =D17/D$18 -> 0.0071392347 | E36: =E17/E$18 -> 0.0099022108 | F36: =F17/F$18 -> 0.003159467 | G36: =G17/G$18 -> 0.0027333948 | H36: =H17/H$18 -> 0.0017762654 | I36: =I17/I$18 -> 0.0016853446 | ... M36: =M17/M$18 -> #REF!
A37: Total | B37: =+SUM(B33:B36) -> 0 | C37: =+SUM(C33:C36) -> 0.99930795 | D37: =+SUM(D33:D36) -> 1.0014957 | E37: =+SUM(E33:E36) -> 1.0028204 | F37: =+SUM(F33:F36) -> 1 | G37: =+SUM(G33:G36) -> 1 | H37: =+SUM(H33:H36) -> 1 | I37: =+SUM(I33:I36) -> 1 | ... M37: =+SUM(M33:M36) -> #REF!
A39: YoY Growth (%) | B39: FY17 | C39: =+C3 -> FY18 | D39: =+D3 -> FY19 | E39: =+E3 -> FY20 | F39: =+F3 -> FY21 | G39: =+G3 -> FY22 | H39: =+H3 -> FY23 | I39: =+I3 -> FY24 | J39: =+J3 -> FY25E | ... M39: =+M3 -> FY28E | U39: =+U3 -> 1H20 | V39: =+V3 -> 2H20 | W39: =+W3 -> 1H21 | X39: =+X3 -> 2H21 | Y39: =+Y3 -> 1H22 | Z39: =+Z3 -> 2H22 | AA39: =+AA3 -> 1H23 | AB39: =+AB3 -> 2H23 | AD39: =+AD3 -> 1Q20 | AE39: =+AE3 -> 2Q20 | AF39: =+AF3 -> 3Q20 | AG39: =+AG3 -> 4Q20 | AH39: =+AH3 -> 1Q21 | AI39: =+AI3 -> 2Q21 | AJ39: =+AJ3 -> 3Q21 | AK39: =+AK3 -> 4Q21 | ... BE39: =+BE3 -> 4Q26E
A40: By segment
A41: =+A33 -> Energy drinks | D41: =D5/C5-1 -> 0.3872932 | E41: =E5/D5-1 -> 0.1629074 | F41: =F5/E5-1 -> 0.41604298 | G41: =G5/F5-1 -> 0.23975022 | H41: =H5/G5-1 -> 0.26476027 | I41: =I5/H5-1 -> 0.28711036 | J41: =J5/I5-1 -> 0.1979 | K41: =K5/J5-1 -> 0.17 | ... M41: =M5/L5-1 -> #REF! | AX41: =AX5/AT5-1 -> 0.25795408 | AY41: =AY5/AU5-1 -> 0.18766627 | AZ41: =AZ5/AV5-1 -> 0.1459288 | BA41: =BA5/AW5-1 -> 0.21422676 | BB41: =BB5/AX5-1 -> 0.21 | BC41: =BC5/AY5-1 -> 0.2 | BD41: =BD5/AZ5-1 -> 0.19 | BE41: =BE5/BA5-1 -> 0.059163814
A42: =+A34 -> Other beverage | D42: =D6/C6-1 -> 0.39133127 | E42: =E6/D6-1 -> 0.485931 | F42: =F6/E6-1 -> 0.32597943 | G42: =G6/F6-1 -> -0.14228767 | H42: =H6/G6-1 -> 1.8664623 | I42: =I6/H6-1 -> 1.7536885 | J42: =J6/I6-1 -> 0.9982 | K42: =K6/J6-1 -> 0.3365 | ... M42: =M6/L6-1 -> #REF! | AX42: =AX6/AT6-1 -> 1.5063795 | AY42: =AY6/AU6-1 -> 1.2668406 | AZ42: =AZ6/AV6-1 -> 0.87057466 | BA42: =BA6/AW6-1 -> 0.52664991 | BB42: =BB6/AX6-1 -> 0.31636426 | BC42: =BC6/AY6-1 -> 0.28529187 | BD42: =BD6/AZ6-1 -> 0.32078515 | BE42: =BE6/BA6-1 -> 0.49672448
A43: =+A35 -> Bushuila | I43: =I7/H7-1 -> 2.8037 | J43: =J7/I7-1 -> 1.21 | K43: =K7/J7-1 -> 0.36 | L43: =L7/K7-1 -> 0.265 | M43: =M7/L7-1 -> #REF! | AX43: =AX7/AT7-1 -> 2.6145988 | AY43: =AY7/AU7-1 -> 1.9004787 | AZ43: =AZ7/AV7-1 -> 0.83805221 | BA43: =BA7/AW7-1 -> 0.61839046 | BB43: =BB7/AX7-1 -> 0.35 | BC43: =BC7/AY7-1 -> 0.34 | BD43: =BD7/AZ7-1 -> 0.32 | BE43: =BE7/BA7-1 -> 0.53129436
A44: Others | I44: =I8/H8-1 -> 0.96221851 | J44: =J8/I8-1 -> 0.68872525 | K44: =K8/J8-1 -> 0.29156338 | L44: =L8/K8-1 -> 0.2574662 | M44: =M8/L8-1 -> #REF! | AX44: =AX8/AT8-1 -> 0.72615328 | AY44: =AY8/AU8-1 -> 0.61776185 | AZ44: =AZ8/AV8-1 -> 0.95625404 | BA44: =BA8/AW8-1 -> 0.4065457 | BB44: =BB8/AX8-1 -> 0.26522445 | BC44: =BC8/AY8-1 -> 0.1848157 | BD44: =BD8/AZ8-1 -> 0.32272862 | BE44: =BE8/BA8-1 -> 0.44465009
A45: Total | C45: =C9/B9-1 -> 0.068122893 | D45: =D9/C9-1 -> 0.3855732 | E45: =E9/D9-1 -> 0.17814742 | F45: =F9/E9-1 -> 0.40724388 | G45: =G9/F9-1 -> 0.21891747 | H45: =H9/G9-1 -> 0.32419494 | I45: =I9/H9-1 -> 0.40629862 | J45: =J9/I9-1 -> 0.32534294 | ... M45: =M9/L9-1 -> #REF! | AX45: =AX9/AT9-1 -> 0.39225679 | AY45: =AY9/AU9-1 -> 0.3410146 | AZ45: =AZ9/AV9-1 -> 0.30359623 | BA45: =BA9/AW9-1 -> 0.2643968 | BB45: =BB9/AX9-1 -> 0.23 | BC45: =BC9/AY9-1 -> 0.22 | BD45: =BD9/AZ9-1 -> 0.23 | BE45: =BE9/BA9-1 -> 0.14377511
...

Sheet Act Vs Est
A2: Do not delete Column A & B | C2: =Coversheet!B6 -> 605499.SS
C3: =Coversheet!B7 -> Eastroc Beverage
D5: 2017 | E5: 2018 | F5: 2019 | G5: 2020 | H5: 2021 | I5: 2022 | J5: 2023 | K5: 2024 | L5: 2024 | Q5: 1Q20 | R5: 2Q20 | S5: 3Q20 | T5: 4Q20 | U5: 1Q21 | V5: 2Q21 | W5: 3Q21 | X5: 4Q21 | Y5: 1Q22 | Z5: 2Q22 | AA5: 3Q22 | AB5: 4Q22 | AC5: 1Q23 | AD5: 2Q23 | AE5: 3Q23 | AF5: 4Q23 | AG5: 1Q24 | AH5: 2Q24 | AI5: 3Q24 | AJ5: 4Q24 | AK5: 1Q25 | AL5: 2Q25 | AM5: 3Q25 | AN5: 3Q25
C6: Summary P&L (Rmb mn) | D6: Actual | E6: Actual | F6: Actual | G6: Actual | H6: Actual | I6: Actual | J6: Actual | K6: Actual | L6: GSe | N6: Diff | O6: yoy | Q6: Actual | R6: Actual | S6: Actual | T6: Actual | U6: Actual | V6: Actual | W6: Actual | X6: Actual | Y6: Actual | Z6: Actual | AA6: Actual | AB6: Actual | AC6: Actual | AD6: Actual | AE6: Actual | AF6: Actual | AG6: Actual | AH6: Actual | AI6: Actual | AJ6: Actual | AK6: Actual | AL6: Actual | AM6: Actual | AN6: GSe | AP6: Diff | AQ6: yoy
A7: Linked to Model | B7: Linked to Raw Data | AS7: Check actual | AT7: Check Gse
A8: =Model!B13 -> Total sales/revenues | B8: ='Raw Data'!B8 -> Turnover | C8: Total revenues | D8: =Segment!F9 -> 2843.8076 | E8: =Segment!G9 -> 3037.536 | F8: =Segment!H9 -> 4208.7285 | G8: =Segment!I9 -> 4958.5026 | H8: =Segment!J9 -> 6977.8225 | I8: =Segment!K9 -> 8505.3897 | J8: =Segment!L9 -> 11262.794 | K8: =Segment!M9 -> 15838.852 | L8: 16329.345 | N8: =K8/L8-1 -> -0.030037541 | O8: =+K8/J8-1 -> 0.40629862 | Q8: =Segment!BB9 -> 933.21619 | R8: =Segment!BC9 -> 1536.2465 | S8: =Segment!BD9 -> 1574.1342 | T8: =Segment!BE9 -> 914.90569 | U8: =Segment!BF9 -> 1711.2617 | V8: =Segment!BG9 -> 1971 | W8: =Segment!BH9 -> 1877.9507 | X8: =Segment!BI9 -> 1417.61 | ... AM8: =Segment!BX9 -> 6107.34 | AN8: 6137.3417 | AP8: =AM8/AN8-1 -> -0.0048883778 | AQ8: =AM8/AI8-1 -> 0.30359623 | AR8: =SUM(AG8:AJ8) -> 15838.852 | AS8: =AR8=K8 -> TRUE | AT8: =SUM(AG8:AI8,#REF!)=L8 -> #REF!
AR9: =SUM(AF9:AI9) -> 0
A10: =Model!B16 -> COGS | B10: ='Raw Data'!B15 -> COGS | C10: COGS | D10: =-Segment!F23 -> -1480.9948 | E10: =-Segment!G23 -> -1641.2421 | F10: =-Segment!H23 -> -2241.7193 | G10: =-Segment!I23 -> -2647.8475 | H10: =-Segment!J23 -> -3881.5648 | I10: =-Segment!K23 -> -4905.4613 | J10: =-Segment!L23 -> -6411.6538 | K10: =-Segment!M23 -> -8741.561 | L10: -8969.8905 | N10: =K10/L10-1 -> -0.0254551 | O10: =+K10/J10-1 -> 0.36338632 | Q10: =-Segment!BB23 -> -474.49274 | R10: =-Segment!BC23 -> -848.15726 | S10: =-Segment!BD23 -> -828.35415 | T10: =-Segment!BE23 -> -496.84336 | U10: =-Segment!BF23 -> -863.46211 | V10: =-Segment!BG23 -> -989.4525 | W10: =-Segment!BH23 -> -1011.1236 | X10: =-Segment!BI23 -> -1017.5266 | ... AM10: =-Segment!BX23 -> -3346.3351 | AN10: -3326.4392 | AP10: =AM10/AN10-1 -> 0.0059811435 | AQ10: =AM10/AI10-1 -> 0.31796203 | AR10: =SUM(AG10:AJ10) -> -8741.561 | AS10: =AR10=K10 -> TRUE | AT10: =SUM(AG10:AI10,#REF!)=L10 -> #REF!
C11: Gross profit | D11: =D10+D8 -> 1362.8128 | E11: =E10+E8 -> 1396.2939 | F11: =F10+F8 -> 1967.0092 | G11: =G10+G8 -> 2310.6551 | H11: =H10+H8 -> 3096.2577 | I11: =I10+I8 -> 3599.9284 | J11: =J10+J8 -> 4851.1403 | K11: =K10+K8 -> 7097.2908 | L11: 7359.4547 | N11: =K11/L11-1 -> -0.035622736 | O11: =+K11/J11-1 -> 0.46301495 | Q11: =Q10+Q8 -> 458.72345 | R11: =R10+R8 -> 688.08925 | S11: =S10+S8 -> 745.78008 | T11: =T10+T8 -> 418.06233 | U11: =U10+U8 -> 847.79962 | V11: =V10+V8 -> 981.54753 | W11: =W10+W8 -> 866.82714 | X11: =X10+X8 -> 400.0834 | ... AM11: =AM10+AM8 -> 2761.0049 | AN11: 2810.9025 | AP11: =AM11/AN11-1 -> -0.017751436 | AQ11: =AM11/AI11-1 -> 0.28659921 | AR11: =SUM(AG11:AJ11) -> 7097.2908 | AS11: =AR11=K11 -> TRUE | AT11: =SUM(AG11:AI11,#REF!)=L11 -> #REF!
A12: =Model!B23 -> SG&A | B12: ='Raw Data'!B23 -> SG&A | C12: SG&A | D12: =-(Segment!F47+Segment!F49) -> -936.0386 | E12: =-(Segment!G47+Segment!G49) -> -1113.0787 | F12: =-(Segment!H47+Segment!H49) -> -1212.8507 | G12: =-(Segment!I47+Segment!I49) -> -1259.7863 | H12: =-(Segment!J47+Segment!J49) -> -1662.8259 | I12: =-(Segment!K47+Segment!K49) -> -1748.5559 | J12: =-(Segment!L47+Segment!L49) -> -2378.6565 | K12: =-(Segment!M47+Segment!M49) -> -3169.4049 | L12: -3338.5171 | N12: =K12/L12-1 -> -0.050654903 | O12: =+K12/J12-1 -> 0.33243488 | Q12: =-(Segment!BB47+Segment!BB49) -> -246.99134 | R12: =-(Segment!BC47+Segment!BC49) -> -308.56686 | S12: =-(Segment!BD47+Segment!BD49) -> -413.78431 | T12: =-(Segment!BE47+Segment!BE49) -> -290.44376 | U12: =-(Segment!BF47+Segment!BF49) -> -399.85931 | V12: =-(Segment!BG47+Segment!BG49) -> -551.3145 | W12: =-(Segment!BH47+Segment!BH49) -> -470.77279 | X12: =-(Segment!BI47+Segment!BI49) -> -240.87931 | ... AM12: =-(Segment!BX47+Segment!BX49) -> -1105.4547 | AN12: -1172.2323 | AP12: =(AM12/AN12-1) -> -0.056966139 | AQ12: =AM12/AI12-1 -> 0.1390994 | AR12: =SUM(AG12:AJ12) -> -3169.4049 | AS12: =AR12=K12 -> TRUE | AT12: =SUM(AG12:AI12,#REF!)=L12 -> #REF!
C13: Selling expense | D13: =-(Segment!F47) -> -825.2498 | E13: =-(Segment!G47) -> -969.45034 | F13: =-(Segment!H47) -> -983.59316 | G13: =-(Segment!I47) -> -1040.3473 | H13: =-(Segment!J47) -> -1368.3844 | I13: =-(Segment!K47) -> -1449.2761 | J13: =-(Segment!L47) -> -1955.6714 | K13: =-(Segment!M47) -> -2681.0798 | L13: -2830.5284 | Q13: =-(Segment!BB47) -> -201.55927 | R13: =-(Segment!BC47) -> -250.64873 | S13: =-(Segment!BD47) -> -360.37018 | T13: =-(Segment!BE47) -> -227.76911 | U13: =-(Segment!BF47) -> -336.21724 | V13: =-(Segment!BG47) -> -462.44102 | W13: =-(Segment!BH47) -> -399.24318 | X13: =-(Segment!BI47) -> -170.48293 | ... AM13: =-(Segment!BX47) -> -931.82559 | AN13: -1000.3867 | AP13: =(AM13/AN13-1) -> -0.068534604 | AQ13: =AM13/AI13-1 -> 0.11339806 | AR13: =SUM(AG13:AJ13) -> -2681.0798 | AS13: =AR13=K13 -> TRUE | AT13: =SUM(AG13:AI13,#REF!)=L13 -> #REF!
C14: Admin expense | D14: =-(Segment!F49) -> -110.7888 | E14: =-(Segment!G49) -> -143.62836 | F14: =-(Segment!H49) -> -229.25756 | G14: =-(Segment!I49) -> -219.43897 | H14: =-(Segment!J49) -> -294.44155 | I14: =-(Segment!K49) -> -299.27981 | J14: =-(Segment!L49) -> -422.98511 | K14: =-(Segment!M49) -> -488.32508 | L14: -507.9887 | Q14: =-(Segment!BB49) -> -45.432064 | R14: =-(Segment!BC49) -> -57.918136 | S14: =-(Segment!BD49) -> -53.414128 | T14: =-(Segment!BE49) -> -62.674645 | U14: =-(Segment!BF49) -> -63.642069 | V14: =-(Segment!BG49) -> -88.873486 | W14: =-(Segment!BH49) -> -71.529616 | X14: =-(Segment!BI49) -> -70.396378 | ... AM14: =-(Segment!BX49) -> -173.62913 | AN14: -171.84557 | AP14: =(AM14/AN14-1) -> 0.010378856 | AQ14: =AM14/AI14-1 -> 0.30017053 | AR14: =SUM(AG14:AJ14) -> -488.32508 | AS14: =AR14=K14 -> TRUE | AT14: =SUM(AG14:AI14,#REF!)=L14 -> #REF!
A15: =Model!B27 -> Other operating expense | B15: ='Raw Data'!B27 -> Other operating gains/expenses | C15: Other operating expenses, net | D15: =-Segment!F45+Model!C27 -> -46.48 | E15: =-Segment!G45+Model!D27 -> -41.853673 | F15: =-Segment!H45+Model!E27 -> -50.867283 | G15: =-Segment!I45+Model!F27 -> -49.740057 | H15: =-Segment!J45+Model!G27 -> 39.074537 | I15: =-Segment!K45+Model!H27 -> -80.209477 | J15: =-Segment!L45+Model!I27 -> -93.330828 | K15: =-Segment!M45+Model!J27 -> -127.80209 | L15: -144.83013 | N15: =K15/L15-1 -> -0.11757249 | O15: =+K15/J15-1 -> 0.36934488 | Q15: =-Segment!BB45+Segment!BB54+Segment!BB55 -> -6.6531128 | R15: =-Segment!BC45+Segment!BC54+Segment!BC55 -> -18.077787 | S15: =-Segment!BD45+Segment!BD54+Segment!BD55 -> -15.362783 | T15: =-Segment!BE45+Segment!BE54+Segment!BE55 -> -9.6463742 | U15: =-Segment!BF45+Segment!BF54+Segment!BF55 -> -18.664352 | V15: =-Segment!BG45+Segment!BG54+Segment!BG55 -> -17.477149 | W15: =-Segment!BH45+Segment!BH54+Segment!BH55 -> -6.2363417 | X15: =-Segment!BI45+Segment!BI54+Segment!BI55 -> 81.45238 | ... AM15: =-Segment!BX45+Segment!BX54+Segment!BX55 -> 57.695611 | AN15: -56.096248 | AP15: =-(AM15/AN15-1) -> 2.028511 | AQ15: =-(AM15/AI15-1) -> 3.2574353 | AR15: =SUM(AG15:AJ15) -> -127.80209 | AS15: =AR15=K15 -> TRUE | AT15: =SUM(AG15:AI15,#REF!)=L15 -> #REF!
C16: EBIT | D16: =D8+SUM(D10,D12,D15) -> 380.2942 | E16: =E8+SUM(E10,E12,E15) -> 241.36158 | F16: =F8+SUM(F10,F12,F15) -> 703.29121 | G16: =G8+SUM(G10,G12,G15) -> 1001.1288 | H16: =H8+SUM(H10,H12,H15) -> 1472.5063 | I16: =I8+SUM(I10,I12,I15) -> 1771.163 | J16: =J8+SUM(J10,J12,J15) -> 2379.153 | K16: =K8+SUM(K10,K12,K15) -> 3800.0839 | L16: 3876.1075 | N16: =K16/L16-1 -> -0.019613391 | O16: =+K16/J16-1 -> 0.59724232 | Q16: =Q8+SUM(Q10,Q12,Q15) -> 205.079 | R16: =R8+SUM(R10,R12,R15) -> 361.4446 | S16: =S8+SUM(S10,S12,S15) -> 316.63299 | T16: =T8+SUM(T10,T12,T15) -> 117.9722 | U16: =U8+SUM(U10,U12,U15) -> 429.27595 | V16: =V8+SUM(V10,V12,V15) -> 412.75588 | W16: =W8+SUM(W10,W12,W15) -> 389.818 | X16: =X8+SUM(X10,X12,X15) -> 240.65647 | ... AM16: =AM8+SUM(AM10,AM12,AM15) -> 1713.2458 | AN16: 1582.574 | AP16: =AM16/AN16-1 -> 0.082569189 | AQ16: =AM16/AI16-1 -> 0.48984447 | AR16: =SUM(AG16:AJ16) -> 3800.0839 | AS16: =AR16=K16 -> TRUE | AT16: =SUM(AG16:AI16,#REF!)=L16 -> #REF!
AR17: =SUM(AG17:AJ17) -> 0 | AS17: =AR17=K17 -> TRUE | AT17: =SUM(AG17:AI17,#REF!)=L17 -> #REF!
A18: =Model!B33 -> Depreciation | B18: ='Raw Data'!B31 -> Depreciation | C18: Depreciation | D18: =Model!C$33 -> 0 | E18: =Model!D$33 -> -77.859575 | F18: =Model!E$33 -> -102.17591 | G18: =Model!F$33 -> -124.5853 | H18: =Model!G$33 -> -173.1049 | I18: =Model!H$33 -> -211.99102 | J18: =Model!I$33 -> -241.69914 | K18: =Model!J$33 -> -325.93172 | L18: -337.90731 | N18: =K18/L18-1 -> -0.035440471 | O18: =+K18/J18-1 -> 0.34850179 | Q18: =Model!$F$33/4 -> -31.146326 | R18: =Model!$F$33/4 -> -31.146326 | S18: =Model!$F$33/4 -> -31.146326 | T18: =Model!$F$33/4 -> -31.146326 | U18: =Model!$G$33/4 -> -43.276224 | V18: =Model!$G$33/4 -> -43.276224 | W18: =Model!$G$33/4 -> -43.276224 | X18: =Model!$G$33/4 -> -43.276224 | Y18: =Model!$G$33/4 -> -43.276224 | Z18: =Model!$G$33/4 -> -43.276224 | AA18: =Model!$G$33/4 -> -43.276224 | AB18: =Model!$G$33/4 -> -43.276224 | ... AF18: =Model!$G$33/4 -> -43.276224 | AG18: =Model!$J$33/4 -> -81.482929 | AH18: =Model!$J$33/4 -> -81.482929 | AI18: =Model!$J$33/4 -> -81.482929 | AJ18: =Model!$J$33/4 -> -81.482929 | AK18: =Model!$J$33/4 -> -81.482929 | AL18: =Model!$J$33/4 -> -81.482929 | AM18: =Model!$J$33/4 -> -81.482929 | AN18: -81.482929 | AP18: =AM18/AN18-1 -> 0 | AQ18: =AM18/AI18-1 -> 0 | AR18: =SUM(AG18:AJ18) -> -325.93172 | AS18: =AR18=K18 -> TRUE | AT18: =SUM(AG18:AI18,#REF!)=L18 -> #REF!
A19: =Model!B34 -> Amortization | B19: ='Raw Data'!B32 -> Amortization | C19: Amortization | D19: =Model!C$34 -> 0 | E19: =Model!D$34 -> -7.1119131 | F19: =Model!E$34 -> -7.5485512 | G19: =Model!F$34 -> -9.8574461 | H19: =Model!G$34 -> -12.007907 | I19: =Model!H$34 -> -11.95035 | J19: =Model!I$34 -> -12.33999 | K19: =Model!J$34 -> -17.11997 | L19: -18.608242 | N19: =K19/L19-1 -> -0.079979169 | O19: =+K19/J19-1 -> 0.38735683 | Q19: =Model!$F$34/4 -> -2.4643615 | R19: =Model!$F$34/4 -> -2.4643615 | S19: =Model!$F$34/4 -> -2.4643615 | T19: =Model!$F$34/4 -> -2.4643615 | U19: =Model!$G$34/4 -> -3.0019768 | V19: =Model!$G$34/4 -> -3.0019768 | W19: =Model!$G$34/4 -> -3.0019768 | X19: =Model!$G$34/4 -> -3.0019768 | Y19: =Model!$G$34/4 -> -3.0019768 | Z19: =Model!$G$34/4 -> -3.0019768 | AA19: =Model!$G$34/4 -> -3.0019768 | AB19: =Model!$G$34/4 -> -3.0019768 | ... AF19: =Model!$G$34/4 -> -3.0019768 | AG19: =Model!$J$34/4 -> -4.2799925 | AH19: =Model!$J$34/4 -> -4.2799925 | AI19: =Model!$J$34/4 -> -4.2799925 | AJ19: =Model!$J$34/4 -> -4.2799925 | AK19: =Model!$J$34/4 -> -4.2799925 | AL19: =Model!$J$34/4 -> -4.2799925 | AM19: =Model!$J$34/4 -> -4.2799925 | AN19: -4.2799925 | AP19: =AM19/AN19-1 -> 0 | AQ19: =AM19/AI19-1 -> 0 | AR19: =SUM(AG19:AJ19) -> -17.11997 | AS19: =AR19=K19 -> TRUE | AT19: =SUM(AG19:AI19,#REF!)=L19 -> #REF!
C20: EBITDA | D20: =D16-SUM(D18:D19) -> 380.2942 | E20: =E16-SUM(E18:E19) -> 326.33306 | F20: =F16-SUM(F18:F19) -> 813.01568 | G20: =G16-SUM(G18:G19) -> 1135.5715 | H20: =H16-SUM(H18:H19) -> 1657.6191 | I20: =I16-SUM(I18:I19) -> 1995.1044 | J20: =J16-SUM(J18:J19) -> 2633.1921 | K20: =K16-SUM(K18:K19) -> 4143.1356 | L20: 4232.623 | N20: =K20/L20-1 -> -0.021142322 | O20: =+K20/J20-1 -> 0.57342698 | Q20: =Q16-SUM(Q18:Q19) -> 238.68969 | R20: =R16-SUM(R18:R19) -> 395.05529 | S20: =S16-SUM(S18:S19) -> 350.24367 | T20: =T16-SUM(T18:T19) -> 151.58289 | U20: =U16-SUM(U18:U19) -> 475.55415 | V20: =V16-SUM(V18:V19) -> 459.03408 | W20: =W16-SUM(W18:W19) -> 436.0962 | X20: =X16-SUM(X18:X19) -> 286.93467 | ... AM20: =AM16-SUM(AM18:AM19) -> 1799.0088 | AN20: 1668.3369 | AP20: =AM20/AN20-1 -> 0.078324617 | AQ20: =AM20/AI20-1 -> 0.45584749 | AR20: =SUM(AG20:AJ20) -> 4143.1356 | AS20: =AR20=K20 -> TRUE | AT20: =SUM(AG20:AI20,#REF!)=L20 -> #REF!
C21: Core op | AG21: =AG11+AG13+AG14 -> 779.65011 | AH21: =AH11+AH13+AH14 -> 1284.0511 | AI21: =AI11+AI13+AI14 -> 1175.5075 | AJ21: =AJ11+AJ13+AJ14 -> 688.67723 | AK21: =AK11+AK13+AK14 -> 1210.1845 | AL21: =AL11+AL13+AL14 -> 1664.0751 | AM21: =AM11+AM13+AM14 -> 1655.5502 | AN21: =AN11+AN13+AN14 -> 1638.6702 | AP21: =(AM21/AN21-1) -> 0.01030103 | AQ21: =(AM21/AI21-1) -> 0.40837063 | AR21: =SUM(AG21:AJ21) -> 3927.886 | AS21: =AR21=K21 -> FALSE | AT21: =SUM(AG21:AI21,#REF!)=L21 -> #REF!
A22: =Model!B39 -> Interest income | B22: ='Raw Data'!B38 -> Interest income | C22: Interest income | O22: =IF(ISERROR(#REF!/K22-1)," ",(#REF!/K22-1)) | AR22: =SUM(AG22:AJ22) -> 0 | AS22: =AR22=K22 -> TRUE | AT22: =SUM(AG22:AI22,#REF!)=L22 -> #REF!
A23: =Model!B40 -> Interest expense | B23: ='Raw Data'!B93 -> Total finance costs | C23: Interest expense | O23: =IF(ISERROR(#REF!/K23-1)," ",(#REF!/K23-1)) | AR23: =SUM(AG23:AJ23) -> 0 | AS23: =AR23=K23 -> TRUE | AT23: =SUM(AG23:AI23,#REF!)=L23 -> #REF!
C24: Net interest income/(expense) | D24: =Segment!F53 -> -10.454 | E24: =Segment!G53 -> -5.0820752 | F24: =Segment!H53 -> 13.965657 | G24: =Segment!I53 -> 15.93094 | H24: =Segment!J53 -> 11.393957 | I24: =Segment!K53 -> -41.039484 | J24: =Segment!L53 -> -2.2856168 | K24: =Segment!M53 -> 190.53573 | L24: 91.666162 | N24: =K24/L24-1 -> 1.0785831 | O24: n.m. | Q24: =-Segment!BB53 -> 3.7269526 | R24: =-Segment!BC53 -> 3.0950474 | S24: =-Segment!BD53 -> 4.6195695 | T24: =-Segment!BE53 -> -27.372509 | U24: =-Segment!BF53 -> 2.3103464 | V24: =-Segment!BG53 -> 1.9861142 | W24: =-Segment!BH53 -> 6.3750549 | X24: =-Segment!BI53 -> -22.065473 | ... AM24: =-Segment!BX53 -> 9.4679811 | AN24: 25.469264 | AP24: =AM24/AN24-1 -> -0.62825855 | AQ24: =AM24/AI24-1 -> -0.68926125 | AR24: =SUM(AG24:AJ24) -> 190.53573 | AS24: =AR24=K24 -> TRUE | AT24: =SUM(AG24:AI24,#REF!)=L24 -> #REF!
A25: =Model!B47 -> Other non-operating income/expense | B25: ='Raw Data'!B49 -> Other non operating income/expense | C25: Non-operating income/(loss) | D25: =Segment!F56++Segment!F58+Segment!F59-Segment!F60 -> 19.9649 | E25: =Segment!G56++Segment!G58+Segment!G59-Segment!G60 -> 37.048354 | F25: =Segment!H56++Segment!H58+Segment!H59-Segment!H60 -> 19.246076 | G25: =Segment!I56++Segment!I58+Segment!I59-Segment!I60 -> 12.489926 | H25: =Segment!J56++Segment!J58+Segment!J59-Segment!J60 -> 29.616555 | I25: =Segment!K56++Segment!K58+Segment!K59-Segment!K60 -> 105.8862 | J25: =Segment!L56++Segment!L58+Segment!L59-Segment!L60 -> 202.40354 | K25: =Segment!M56++Segment!M58+Segment!M59-Segment!M60 -> 116.6927 | L25: 160.998 | N25: =K25/L25-1 -> -0.27519165 | O25: =+K25/J25-1 -> -0.42346514 | Q25: =Segment!BB56++Segment!BB58+Segment!BB59-Segment!BB60 -> -10.680693 | R25: =Segment!BC56++Segment!BC58+Segment!BC59-Segment!BC60 -> 2.2769927 | S25: =Segment!BD56++Segment!BD58+Segment!BD59-Segment!BD60 -> 11.521198 | T25: =Segment!BE56++Segment!BE58+Segment!BE59-Segment!BE60 -> 9.3724281 | U25: =Segment!BF56++Segment!BF58+Segment!BF59-Segment!BF60 -> 6.7116032 | V25: =Segment!BG56++Segment!BG58+Segment!BG59-Segment!BG60 -> 6.8262857 | W25: =Segment!BH56++Segment!BH58+Segment!BH59-Segment!BH60 -> 7.2202687 | X25: =Segment!BI56++Segment!BI58+Segment!BI59-Segment!BI60 -> 8.8583974 | ... AM25: =Segment!BX56++Segment!BX58+Segment!BX59-Segment!BX60 -> 53.4941 | AN25: 34.613452 | AP25: =AM25/AN25-1 -> 0.54547137 | AQ25: =AM25/AI25-1 -> 0.6921309 | AR25: =SUM(AG25:AJ25) -> 116.6927 | AS25: =AR25=K25 -> TRUE | AT25: =SUM(AG25:AI25,#REF!)=L25 -> #REF!
B26: ='Raw Data'!B51 -> Pre-tax profits | C26: Pre-tax profit | D26: =D16+D24+D25 -> 389.8051 | E26: =E16+E24+E25 -> 273.32785 | F26: =F16+F24+F25 -> 736.50294 | G26: =G16+G24+G25 -> 1029.5497 | H26: =H16+H24+H25 -> 1513.5168 | I26: =I16+I24+I25 -> 1836.0097 | J26: =J16+J24+J25 -> 2579.2709 | K26: =K16+K24+K25 -> 4107.3123 | L26: 4128.7716 | N26: =K26/L26-1 -> -0.0051975142 | O26: =+K26/J26-1 -> 0.59243151 | Q26: =Q16+Q24+Q25 -> 198.12526 | R26: =R16+R24+R25 -> 366.81664 | S26: =S16+S24+S25 -> 332.77375 | T26: =T16+T24+T25 -> 99.97212 | U26: =U16+U24+U25 -> 438.2979 | V26: =V16+V24+V25 -> 421.56828 | W26: =W16+W24+W25 -> 403.41333 | X26: =X16+X24+X25 -> 227.44939 | ... AM26: =AM16+AM24+AM25 -> 1776.2079 | AN26: 1642.6567 | AP26: =AM26/AN26-1 -> 0.081301963 | AQ26: =AM26/AI26-1 -> 0.46547918 | AR26: =SUM(AG26:AJ26) -> 4107.3123 | AS26: =AR26=K26 -> TRUE | AT26: =SUM(AG26:AI26,#REF!)=L26 -> #REF!
B27: ='Raw Data'!B49 -> Other non operating income/expense | AR27: =SUM(AG27:AJ27) -> 0 | AS27: =AR27=K27 -> TRUE | AT27: =SUM(AG27:AI27,#REF!)=L27 -> #REF!
A28: =Model!B53 -> Income taxes | B28: ='Raw Data'!B54 -> Taxation | C28: Provision for taxes | D28: =-Segment!F62 -> -93.6393 | E28: =-Segment!G62 -> -57.496914 | F28: =-Segment!H62 -> -165.92903 | G28: =-Segment!I62 -> -217.48614 | H28: =-Segment!J62 -> -320.55641 | I28: =-Segment!K62 -> -395.48918 | J28: =-Segment!L62 -> -539.49813 | K28: =-Segment!M62 -> -780.88329 | L28: -822.31469 | N28: =K28/L28-1 -> -0.050383871 | O28: =+K28/J28-1 -> 0.44742539 | Q28: =-Segment!BB62 -> -44.475694 | R28: =-Segment!BC62 -> -79.157006 | S28: =-Segment!BD62 -> -70.040576 | T28: =-Segment!BE62 -> -23.812862 | U28: =-Segment!BF62 -> -96.408437 | V28: =-Segment!BG62 -> -87.631611 | W28: =-Segment!BH62 -> -83.205508 | X28: =-Segment!BI62 -> -53.310851 | ... AM28: =-Segment!BX62 -> -390.90976 | AN28: -321.96071 | AP28: =AM28/AN28-1 -> 0.21415359 | AQ28: =AM28/AI28-1 -> 0.66181041 | AR28: =SUM(AG28:AJ28) -> -780.88329 | AS28: =AR28=K28 -> TRUE | AT28: =SUM(AG28:AI28,#REF!)=L28 -> #REF!
AR29: =SUM(AG29:AJ29) -> 0 | AS29: =AR29=K29 -> TRUE | AT29: =SUM(AG29:AI29,#REF!)=L29 -> #REF!
A30: =Model!B54 -> Minority interest | B30: ='Raw Data'!B55 -> Minority interest | C30: Minority interest | D30: =-Segment!F64 -> 0 | E30: =-Segment!G64 -> 0 | F30: =-Segment!H64 -> 0 | G30: =-Segment!I64 -> 0 | H30: =-Segment!J64 -> 0 | I30: =-Segment!K64 -> 0 | J30: =-Segment!L64 -> 0 | K30: =-Segment!M64 -> 0.27984775 | L30: 0 | Q30: =-Segment!BB64 -> 0 | R30: =-Segment!BC64 -> 0 | S30: =-Segment!BD64 -> 0 | T30: =-Segment!BE64 -> 0 | U30: =-Segment!BF64 -> 0 | V30: =-Segment!BG64 -> 0 | W30: =-Segment!BH64 -> 0 | X30: =-Segment!BI64 -> 0 | ... AM30: =-Segment!BX64 -> 0.87434546 | AN30: 0 | AR30: =SUM(AG30:AJ30) -> 0.27984775 | AS30: =AR30=K30 -> TRUE | AT30: =SUM(AG30:AI30,#REF!)=L30 -> #REF!
A31: =+Model!B55 -> Preferred dividends | B31: =+'Raw Data'!B56 -> Preferred dividend | C31: Exceptionals (including preference dividend) | AR31: =SUM(AG31:AJ31) -> 0 | AS31: =AR31=K31 -> TRUE | AT31: =SUM(AG31:AI31,#REF!)=L31 -> #REF!
A32: =+Model!B56 -> Extraordinary gain/(loss) | B32: =+'Raw Data'!B60 -> Extraordinary gain/(loss) | C32: Net income | D32: =D26+D28+D30 -> 296.1658 | E32: =E26+E28+E30 -> 215.83094 | F32: =F26+F28+F30 -> 570.57391 | G32: =G26+G28+G30 -> 812.06352 | H32: =H26+H28+H30 -> 1192.9604 | I32: =I26+I28+I30 -> 1440.5206 | J32: =J26+J28+J30 -> 2039.7728 | K32: =K26+K28+K30 -> 3326.7089 | L32: 3306.457 | N32: =K32/L32-1 -> 0.0061249537 | O32: =+K32/J32-1 -> 0.63092127 | Q32: =Q26+Q28+Q30 -> 153.64956 | R32: =R26+R28+R30 -> 287.65964 | S32: =S26+S28+S30 -> 262.73318 | T32: =T26+T28+T30 -> 76.159258 | U32: =U26+U28+U30 -> 341.88947 | V32: =V26+V28+V30 -> 333.93666 | W32: =W26+W28+W30 -> 320.20782 | X32: =X26+X28+X30 -> 174.13854 | ... AM32: =AM26+AM28+AM30 -> 1386.1725 | AN32: 1320.696 | AP32: =AM32/AN32-1 -> 0.049577281 | AQ32: =AM32/AI32-1 -> 0.4190942 | AR32: =SUM(AG32:AJ32) -> 3326.7089 | AS32: =AR32=K32 -> TRUE | AT32: =SUM(AG32:AI32,#REF!)=L32 -> #REF!
C33: Recurring net income | AG33: =Quarterly!T74 -> 624.42605 | AH33: =Quarterly!U74 -> 1082.4856 | AI33: =Quarterly!V74 -> 956.31947 | AJ33: =Quarterly!W74 -> 599.01777 | AK33: =Quarterly!X74 -> 958.79253 | AL33: =Quarterly!Y74 -> 1311.6708 | AM33: =Quarterly!Z74 -> 1269.3895 | AN33: 1320.696 | AP33: =AM33/AN33-1 -> -0.038848077 | AQ33: =AM33/AI33-1 -> 0.3273697
A36: =Model!B60 -> EPS - basic | B36: ='Raw Data'!B66 -> Basic | C36: YoY Growth %
C37: Sales | E37: =E8/D8-1 -> 0.068122893 | F37: =F8/E8-1 -> 0.3855732 | G37: =G8/F8-1 -> 0.17814742 | H37: =H8/G8-1 -> 0.40724388 | I37: =I8/H8-1 -> 0.21891747 | J37: =J8/I8-1 -> 0.32419494 | K37: =K8/J8-1 -> 0.40629862 | L37: 0.44984851 | Y37: =Y8/U8-1 -> 0.17255171 | Z37: =Z8/V8-1 -> 0.15917357 | AA37: =AA8/W8-1 -> 0.25300085 | AB37: =AB8/X8-1 -> 0.31280246 | AC37: =AC8/Y8-1 -> 0.24137196 | AD37: =AD8/Z8-1 -> 0.29963602 | AE37: =AE8/AA8-1 -> 0.35173296 | AF37: =AF8/AB8-1 -> 0.40882464 | ... AM37: =AM8/AI8-1 -> 0.30359623 | AN37: 0.31
C38: Gross profit | E38: =E11/D11-1 -> 0.024567675 | F38: =F11/E11-1 -> 0.40873577 | G38: =G11/F11-1 -> 0.17470477 | H38: =H11/G11-1 -> 0.33999127 | I38: =I11/H11-1 -> 0.1626708 | J38: =J11/I11-1 -> 0.34756578 | K38: =K11/J11-1 -> 0.46301495 | L38: 0.51705666 | Y38: =Y11/U11-1 -> 0.022132968 | Z38: =Z11/V11-1 -> -0.016891467 | AA38: =AA11/W11-1 -> 0.087230441 | AB38: =AB11/X11-1 -> 1.0644592 | AC38: =AC11/Y11-1 -> 0.25117109 | AD38: =AD11/Z11-1 -> 0.31543707 | AE38: =AE11/AA11-1 -> 0.40096809 | AF38: =AF11/AB11-1 -> 0.42530216 | ... AM38: =AM11/AI11-1 -> 0.28659921 | AN38: 0.30985094 | AS38: 980.00953
C39: EBIT | E39: =E16/D16-1 -> -0.36532933 | F39: =F16/E16-1 -> 1.9138491 | G39: =G16/F16-1 -> 0.42349111 | H39: =H16/G16-1 -> 0.47084603 | I39: =I16/H16-1 -> 0.20282204 | J39: =J16/I16-1 -> 0.34327161 | K39: =K16/J16-1 -> 0.59724232 | L39: 0.62919638 | Y39: =Y16/U16-1 -> 0.019661345 | Z39: =Z16/V16-1 -> 0.26983024 | AA39: =AA16/W16-1 -> 0.19688989 | AB39: =AB16/X16-1 -> 0.42422025 | AC39: =AC16/Y16-1 -> 0.38720002 | AD39: =AD16/Z16-1 -> 0.34617903 | AE39: =AE16/AA16-1 -> 0.30022036 | AF39: =AF16/AB16-1 -> 0.34132948 | ... AM39: =AM16/AI16-1 -> 0.48984447 | AN39: 0.37621178
C40: EBITDA | E40: =E20/D20-1 -> -0.14189314 | F40: =F20/E20-1 -> 1.4913678 | G40: =G20/F20-1 -> 0.39674003 | H40: =H20/G20-1 -> 0.45972231 | I40: =I20/H20-1 -> 0.20359641 | J40: =J20/I20-1 -> 0.31982674 | K40: =K20/J20-1 -> 0.57342698 | L40: 0.60741139 | Y40: =Y20/U20-1 -> 0.017748016 | Z40: =Z20/V20-1 -> 0.2426269 | AA40: =AA20/W20-1 -> 0.17599608 | AB40: =AB20/X20-1 -> 0.35579997 | AC40: =AC20/Y20-1 -> 0.35017702 | AD40: =AD20/Z20-1 -> 0.31809293 | AE40: =AE20/AA20-1 -> 0.27312915 | AF40: =AF20/AB20-1 -> 0.30072522 | ... AM40: =AM20/AI20-1 -> 0.45584749 | AN40: 0.35010132
C41: NPAT | E41: =E32/D32-1 -> -0.27124962 | F41: =F32/E32-1 -> 1.643615 | G41: =G32/F32-1 -> 0.42323983 | H41: =H32/G32-1 -> 0.46904815 | I41: =I32/H32-1 -> 0.2075175 | J41: =J32/I32-1 -> 0.415997 | K41: =K32/J32-1 -> 0.63092127 | L41: 0.62099276 | Y41: =Y32/U32-1 -> 0.0080711882 | Z41: =Z32/V32-1 -> 0.2277204 | AA41: =AA32/W32-1 -> 0.28315503 | AB41: =AB32/X32-1 -> 0.57928575 | AC41: =AC32/Y32-1 -> 0.44277757 | AD41: =AD32/Z32-1 -> 0.48999278 | AE41: =AE32/AA32-1 -> 0.33247072 | AF41: =AF32/AB32-1 -> 0.39691515 | ... AM41: =AM32/AI32-1 -> 0.4190942 | AN41: 0.35206261
C43: Margin analysis
C44: Gross margin | D44: =(D8+D10)/D8 -> 0.47922117 | E44: =(E8+E10)/E8 -> 0.4596798 | F44: =(F8+F10)/F8 -> 0.46736425 | G44: =(G8+G10)/G8 -> 0.46599857 | H44: =(H8+H10)/H8 -> 0.44372835 | I44: =(I8+I10)/I8 -> 0.42325261 | J44: =(J8+J10)/J8 -> 0.43072263 | K44: =(K8+K10)/K8 -> 0.44809377 | L44: 0.45068891 | N44: =(K44-L44)*100 -> -0.25951371 | O44: =(+K44-J44)*100 -> 1.7371137 | Q44: =(Q8+Q10)/Q8 -> 0.49155111 | R44: =(R8+R10)/R8 -> 0.44790289 | S44: =(S8+S10)/S8 -> 0.47377159 | T44: =(T8+T10)/T8 -> 0.45694582 | U44: =(U8+U10)/U8 -> 0.4954237 | V44: =(V8+V10)/V8 -> 0.49799468 | W44: =(W8+W10)/W8 -> 0.46158141 | X44: =(X8+X10)/X8 -> 0.28222388 | ... AM44: =(AM8+AM10)/AM8 -> 0.45207978 | AN44: 0.458 | AP44: =(AM44-AN44)*100 -> -0.59202208 | AQ44: =(+AM44-AI44)*100 -> -0.597234
C45: EBITDA margin | D45: =D20/D8 -> 0.13372712 | E45: =E20/E8 -> 0.10743348 | F45: =F20/F8 -> 0.19317371 | G45: =G20/G8 -> 0.22901501 | H45: =H20/H8 -> 0.23755536 | I45: =I20/I8 -> 0.23456943 | J45: =J20/J8 -> 0.23379564 | K45: =K20/K8 -> 0.26158055 | L45: 0.25920348 | N45: =(K45-L45)*100 -> 0.23770731 | O45: =(+K45-J45)*100 -> 2.778491 | Q45: =Q20/Q8 -> 0.25577105 | R45: =R20/R8 -> 0.25715618 | S45: =S20/S8 -> 0.22249924 | T45: =T20/T8 -> 0.16568144 | U45: =U20/U8 -> 0.2778968 | V45: =V20/V8 -> 0.232894 | W45: =W20/W8 -> 0.2322192 | X45: =X20/X8 -> 0.20240734 | ... AM45: =AM20/AM8 -> 0.29456502 | AN45: 0.2718338 | AP45: =(AM45-AN45)*100 -> 2.2731223 | AQ45: =(+AM45-AI45)*100 -> 3.0805353
...

Sheet Model
A2: =#REF! -> #REF! | B2: Eastroc Beverage (605499.SS)
A3: =#REF! -> #REF!
C4: 2017 | D4: 2018 | E4: 2019 | F4: 2020 | G4: 2021 | H4: 2022 | I4: 2023 | J4: 2024 | K4: 2025E | L4: 2026E | M4: 2027E | O4: 1H20 | P4: 2H20 | Q4: 1H21 | R4: 2H21 | S4: 1H22 | T4: 2H22 | U4: 1H23 | V4: 2H23 | W4: 1H24 | X4: 2H24 | Y4: 1H25
B5: EPS - basic | C5: =IF(ISERROR(C60)," ",(C60)) -> 1.9637077 | D5: =IF(ISERROR(D60)," ",(D60)) -> 0.47435372 | E5: =IF(ISERROR(E60)," ",(E60)) -> 1.219175 | F5: =IF(ISERROR(F60)," ",(F60)) -> 1.7351785 | G5: =IF(ISERROR(G60)," ",(G60)) -> 2.2940973 | H5: =IF(ISERROR(H60)," ",(H60)) -> 2.7701626 | I5: =IF(ISERROR(I60)," ",(I60)) -> 3.9225419 | J5: =IF(ISERROR(J60)," ",(J60)) -> 6.3973571 | ... M5: =IF(ISERROR(M60)," ",(M60)) -> 12.988135
B6: EPS - fully diluted
B7: yoy % | C7: =IF(ISERROR(C5/#REF!-1)," ",(C5/#REF!-1)) | D7: =IF(ISERROR(D5/C5-1)," ",(D5/C5-1)) -> -0.75843975 | E7: =IF(ISERROR(E5/D5-1)," ",(E5/D5-1)) -> 1.5701812 | F7: =IF(ISERROR(F5/E5-1)," ",(F5/E5-1)) -> 0.42323983 | G7: =IF(ISERROR(G5/F5-1)," ",(G5/F5-1)) -> 0.32211028 | H7: =IF(ISERROR(H5/G5-1)," ",(H5/G5-1)) -> 0.2075175 | I7: =IF(ISERROR(I5/H5-1)," ",(I5/H5-1)) -> 0.415997 | J7: =IF(ISERROR(J5/I5-1)," ",(J5/I5-1)) -> 0.63092127 | K7: =IF(ISERROR(K5/J5-1)," ",(K5/J5-1)) -> 0.37158013 | ... M7: =IF(ISERROR(M5/L5-1)," ",(M5/L5-1)) -> 0.19417229
B8: Consensus estimates
B9: Variance from consensus (%) | I9: =(I13/G13)^(1/2)-1 -> 0.2704662 | J9: =(J13/H13)^(1/2)-1 -> 0.36462945 | L9: =(L13/J13)^(1/2)-1 -> 0.26644112
I10: =(I57/G57)^(1/2)-1 -> 0.30760895 | J10: =(J57/H57)^(1/2)-1 -> 0.51966431 | L10: =(L57/J57)^(1/2)-1 -> 0.30388595
B11: Income statements | C11: =C4 -> 2017 | D11: =D4 -> 2018 | E11: =E4 -> 2019 | F11: =F4 -> 2020 | G11: =G4 -> 2021 | H11: =H4 -> 2022 | I11: =I4 -> 2023 | J11: =J4 -> 2024 | ... M11: =M4 -> 2027E | O11: =O4 -> 1H20 | P11: =P4 -> 2H20 | Q11: =Q4 -> 1H21 | R11: =R4 -> 2H21 | S11: =S4 -> 1H22 | T11: =T4 -> 2H22 | U11: =U4 -> 1H23 | V11: =V4 -> 2H23 | ... X11: =X4 -> 2H24
B13: Total sales/revenues | C13: =+'Raw Data'!C8 -> 2843.8076 | D13: =+'Raw Data'!D8 -> 3037.536 | E13: =+'Raw Data'!E8 -> 4208.7285 | F13: =+'Raw Data'!F8 -> 4958.5026 | G13: =+'Raw Data'!G8 -> 6977.8225 | H13: =+'Raw Data'!H8 -> 8505.3897 | I13: =+'Raw Data'!I8 -> 11262.794 | J13: =+'Raw Data'!J8 -> 15838.852 | K13: =Segment!N9 -> 20991.911 | L13: =Segment!O9 -> 25403.508 | M13: =Segment!P9 -> 29791.987 | O13: =+Segment!V9 -> 2469.4627 | P13: =+Segment!W9 -> 2489.0399 | Q13: =+Segment!X9 -> 3682.2618 | R13: =+Segment!Y9 -> 3295.5607 | S13: =+Segment!Z9 -> 4291.274 | T13: =+Segment!AA9 -> 4214.1157 | U13: =+Segment!AB9 -> 5460.1849 | V13: =+Segment!AC9 -> 5802.6092 | ... Y13: =+Segment!AF9 -> 10736.628
B14: yoy % | C14: =IF(ISERROR(C13/#REF!-1)," ",(C13/#REF!-1)) | D14: =IF(ISERROR(D13/C13-1)," ",(D13/C13-1)) -> 0.068122893 | E14: =IF(ISERROR(E13/D13-1)," ",(E13/D13-1)) -> 0.3855732 | F14: =IF(ISERROR(F13/E13-1)," ",(F13/E13-1)) -> 0.17814742 | G14: =IF(ISERROR(G13/F13-1)," ",(G13/F13-1)) -> 0.40724388 | H14: =IF(ISERROR(H13/G13-1)," ",(H13/G13-1)) -> 0.21891747 | I14: =IF(ISERROR(I13/H13-1)," ",(I13/H13-1)) -> 0.32419494 | J14: =IF(ISERROR(J13/I13-1)," ",(J13/I13-1)) -> 0.40629862 | K14: =IF(ISERROR(K13/J13-1)," ",(K13/J13-1)) -> 0.32534294 | ... M14: =IF(ISERROR(M13/L13-1)," ",(M13/L13-1)) -> 0.17275087 | Q14: =Q13/O13-1 -> 0.4911186 | R14: =R13/P13-1 -> 0.32402887 | S14: =S13/Q13-1 -> 0.16539081 | T14: =T13/R13-1 -> 0.27872495 | U14: =U13/S13-1 -> 0.27239252 | V14: =V13/T13-1 -> 0.37694585 | W14: =W13/U13-1 -> 0.44194527 | X14: =X13/V13-1 -> 0.37275556 | Y14: =Y13/W13-1 -> 0.3636778
B16: COGS | C16: =+'Raw Data'!C15 -> -1480.9948 | D16: =+'Raw Data'!D15 -> -1641.2421 | E16: =+'Raw Data'!E15 -> -2241.7193 | F16: =+'Raw Data'!F15 -> -2647.8475 | G16: =+'Raw Data'!G15 -> -3881.5648 | H16: =+'Raw Data'!H15 -> -4905.4613 | I16: =+'Raw Data'!I15 -> -6411.6538 | J16: =+'Raw Data'!J15 -> -8741.561 | K16: =-Segment!N23 -> -11564.399 | L16: =-Segment!O23 -> -13747.299 | M16: =-Segment!P23 -> -16022.731 | O16: =-Segment!V23 -> -1322.65 | P16: =-Segment!W23 -> -1325.1975 | Q16: =-Segment!X23 -> -1852.9146 | R16: =-Segment!Y23 -> -2028.6502 | S16: =-Segment!Z23 -> -2459.7423 | T16: =-Segment!AA23 -> -2445.719 | U16: =-Segment!AB23 -> -3106.6108 | V16: =-Segment!AC23 -> -3305.0429 | ... Y16: =-Segment!AF23 -> -5889.4142
B17: Others | C17: =+'Raw Data'!C16 -> 0 | D17: =+'Raw Data'!D16 -> 0 | E17: =+'Raw Data'!E16 -> 0 | F17: =+'Raw Data'!F16 -> 0 | G17: =+'Raw Data'!G16 -> 0 | H17: =+'Raw Data'!H16 -> 0 | I17: =+'Raw Data'!I16 -> 0 | J17: =+'Raw Data'!J16 -> 0 | K17: =-K$13*K79 -> 0 | L17: =-L$13*L79 -> 0 | M17: =-M$13*M79 -> 0
B18: Total COGS | C18: =C16+C17 -> -1480.9948 | D18: =D16+D17 -> -1641.2421 | E18: =E16+E17 -> -2241.7193 | F18: =F16+F17 -> -2647.8475 | G18: =G16+G17 -> -3881.5648 | H18: =H16+H17 -> -4905.4613 | I18: =I16+I17 -> -6411.6538 | J18: =J16+J17 -> -8741.561 | ... M18: =M16+M17 -> -16022.731 | O18: =O16+O17 -> -1322.65 | P18: =P16+P17 -> -1325.1975 | Q18: =Q16+Q17 -> -1852.9146 | R18: =R16+R17 -> -2028.6502 | S18: =S16+S17 -> -2459.7423 | T18: =T16+T17 -> -2445.719 | U18: =U16+U17 -> -3106.6108 | V18: =V16+V17 -> -3305.0429 | ... Y18: =Y16+Y17 -> -5889.4142
B20: Gross profit | C20: =C13+C18 -> 1362.8128 | D20: =D13+D18 -> 1396.2939 | E20: =E13+E18 -> 1967.0092 | F20: =F13+F18 -> 2310.6551 | G20: =G13+G18 -> 3096.2577 | H20: =H13+H18 -> 3599.9284 | I20: =I13+I18 -> 4851.1403 | J20: =J13+J18 -> 7097.2908 | ... M20: =M13+M18 -> 13769.256 | O20: =O13+O18 -> 1146.8127 | P20: =P13+P18 -> 1163.8424 | Q20: =Q13+Q18 -> 1829.3471 | R20: =R13+R18 -> 1266.9105 | S20: =S13+S18 -> 1831.5317 | T20: =T13+T18 -> 1768.3967 | U20: =U13+U18 -> 2353.5741 | V20: =V13+V18 -> 2497.5662 | ... Y20: =Y13+Y18 -> 4847.2136
B21: yoy % | C21: =IF(ISERROR(C20/#REF!-1)," ",(C20/#REF!-1)) | D21: =IF(ISERROR(D20/C20-1)," ",(D20/C20-1)) -> 0.024567675 | E21: =IF(ISERROR(E20/D20-1)," ",(E20/D20-1)) -> 0.40873577 | F21: =IF(ISERROR(F20/E20-1)," ",(F20/E20-1)) -> 0.17470477 | G21: =IF(ISERROR(G20/F20-1)," ",(G20/F20-1)) -> 0.33999127 | H21: =IF(ISERROR(H20/G20-1)," ",(H20/G20-1)) -> 0.1626708 | I21: =IF(ISERROR(I20/H20-1)," ",(I20/H20-1)) -> 0.34756578 | J21: =IF(ISERROR(J20/I20-1)," ",(J20/I20-1)) -> 0.46301495 | K21: =IF(ISERROR(K20/J20-1)," ",(K20/J20-1)) -> 0.32832537 | ... M21: =IF(ISERROR(M20/L20-1)," ",(M20/L20-1)) -> 0.18128073
B23: SG&A | C23: =+'Raw Data'!C23 -> -981.9832 | D23: =+'Raw Data'!D23 -> -1152.6478 | E23: =+'Raw Data'!E23 -> -1257.157 | F23: =+'Raw Data'!F23 -> -1310.1438 | G23: =+'Raw Data'!G23 -> -1739.6364 | H23: =+'Raw Data'!H23 -> -1841.1951 | I23: =+'Raw Data'!I23 -> -2499.6673 | J23: =+'Raw Data'!J23 -> -3329.1976 | K23: =K24+K25+K26 -> -4191.9135 | L23: =L24+L25+L26 -> -4938.2351 | M23: =M24+M25+M26 -> -5684.0683 | O23: =O24+O25+O26 -> -579.2962 | P23: =P24+P25+P26 -> -730.84764 | Q23: =Q24+Q25+Q26 -> -992.75571 | R23: =R24+R25+R26 -> -746.88072 | S23: =S24+S25+S26 -> -901.70576 | T23: =T24+T25+T26 -> -939.4893 | U23: =U24+U25+U26 -> -1111.8714 | V23: =V24+V25+V26 -> -1387.7959 | ... Y23: =Y24+Y25+Y26 -> -2082.2833
B24: Sales tax and add-on | C24: ='Raw Data'!C20 -> -45.9446 | D24: ='Raw Data'!D20 -> -39.569062 | E24: ='Raw Data'!E20 -> -44.306298 | F24: ='Raw Data'!F20 -> -50.357577 | G24: ='Raw Data'!G20 -> -76.810518 | H24: ='Raw Data'!H20 -> -92.639167 | I24: ='Raw Data'!I20 -> -121.01084 | J24: ='Raw Data'!J20 -> -159.79275 | K24: =-Segment!N45 -> -211.78019 | L24: =-Segment!O45 -> -256.28729 | M24: =-Segment!P45 -> -300.56114 | O24: =-Segment!V45 -> -23.738 | P24: =-Segment!W45 -> -26.619577 | Q24: =-Segment!X45 -> -41.581897 | R24: =-Segment!Y45 -> -35.228621 | S24: =-Segment!Z45 -> -47.650708 | T24: =-Segment!AA45 -> -44.988459 | U24: =-Segment!AB45 -> -59.469351 | V24: =-Segment!AC45 -> -61.541491 | ... Y24: =-Segment!AF45 -> -109.32921
B25: Sales expense | C25: ='Raw Data'!C21 -> -825.2498 | D25: ='Raw Data'!D21 -> -969.45034 | E25: ='Raw Data'!E21 -> -983.59316 | F25: ='Raw Data'!F21 -> -1040.3473 | G25: ='Raw Data'!G21 -> -1368.3844 | H25: ='Raw Data'!H21 -> -1449.2761 | I25: ='Raw Data'!I21 -> -1955.6714 | J25: ='Raw Data'!J21 -> -2681.0798 | K25: =-Segment!N47 -> -3370.7206 | L25: =-Segment!O47 -> -3972.4065 | M25: =-Segment!P47 -> -4584.1632 | O25: =-Segment!V47 -> -452.208 | P25: =-Segment!W47 -> -588.13929 | Q25: =-Segment!X47 -> -798.65826 | R25: =-Segment!Y47 -> -569.72611 | S25: =-Segment!Z47 -> -702.69818 | T25: =-Segment!AA47 -> -746.5779 | U25: =-Segment!AB47 -> -863.23476 | V25: =-Segment!AC47 -> -1092.4366 | ... Y25: =-Segment!AF47 -> -1681.5191
B26: Administrative expense | C26: ='Raw Data'!C22 -> -110.7888 | D26: ='Raw Data'!D22 -> -143.62836 | E26: ='Raw Data'!E22 -> -229.25756 | F26: ='Raw Data'!F22 -> -219.43897 | G26: ='Raw Data'!G22 -> -294.44155 | H26: ='Raw Data'!H22 -> -299.27981 | I26: ='Raw Data'!I22 -> -422.98511 | J26: ='Raw Data'!J22 -> -488.32508 | K26: =-Segment!N49 -> -609.41275 | L26: =-Segment!O49 -> -709.54128 | M26: =-Segment!P49 -> -799.34397 | O26: =-Segment!V49 -> -103.3502 | P26: =-Segment!W49 -> -116.08877 | Q26: =-Segment!X49 -> -152.51556 | R26: =-Segment!Y49 -> -141.92599 | S26: =-Segment!Z49 -> -151.35686 | T26: =-Segment!AA49 -> -147.92294 | U26: =-Segment!AB49 -> -189.16727 | V26: =-Segment!AC49 -> -233.81784 | ... Y26: =-Segment!AF49 -> -291.43502
B27: Other operating expense | C27: =SUM(C28:C29) -> -0.5354 | D27: =SUM(D28:D29) -> -2.2846109 | E27: =SUM(E28:E29) -> -6.5609849 | F27: =SUM(F28:F29) -> 0.6175207 | G27: =SUM(G28:G29) -> 115.88506 | H27: =SUM(H28:H29) -> 12.42969 | I27: =SUM(I28:I29) -> 27.680013 | J27: =SUM(J28:J29) -> 31.990655 | ... M27: =SUM(M28:M29) -> 54.042073 | O27: =+O28+O29 -> -0.9929 | P27: =+P28+P29 -> 1.6104207 | Q27: =+Q28+Q29 -> 5.4403959 | R27: =+R28+R29 -> 110.44466 | S27: =+S28+S29 -> 32.020056 | T27: =+T28+T29 -> -19.590366 | U27: =+U28+U29 -> 71.069749 | V27: =+V28+V29 -> -43.389736 | ... Y27: =+Y28+Y29 -> 77.368274
B28: Impairment losses on property, plant and equipment | C28: ='Raw Data'!C25 -> -0.5354 | D28: ='Raw Data'!D25 -> -2.2846109 | E28: ='Raw Data'!E25 -> -6.5609849 | F28: ='Raw Data'!F25 -> 0.6175207 | G28: ='Raw Data'!G25 -> -0.78503444 | H28: ='Raw Data'!H25 -> -0.35814105 | I28: ='Raw Data'!I25 -> -1.6924196 | J28: ='Raw Data'!J25 -> -0.95792708 | K28: =+J28 -> -0.95792708 | L28: =+K28 -> -0.95792708 | M28: =+L28 -> -0.95792708 | O28: =Segment!V54 -> -0.9929 | P28: =Segment!W54 -> 1.6104207 | Q28: =Segment!X54 -> -0.76998364 | R28: =Segment!Y54 -> -0.0150508 | S28: =Segment!Z54 -> -0.8589465 | T28: =Segment!AA54 -> 0.50080545 | U28: =Segment!AB54 -> -1.24818 | V28: =Segment!AC54 -> -0.44423958 | ... Y28: =Segment!AF54 -> -1.9277012
B29: net gains/loss of fair value | C29: ='Raw Data'!C26 -> 0 | D29: ='Raw Data'!D26 -> 0 | E29: ='Raw Data'!E26 -> 0 | F29: ='Raw Data'!F26 -> 0 | G29: ='Raw Data'!G26 -> 116.67009 | H29: ='Raw Data'!H26 -> 12.787831 | I29: ='Raw Data'!I26 -> 29.372433 | J29: ='Raw Data'!J26 -> 32.948582 | K29: 201 | L29: 50 | M29: =+L29*1.1 -> 55 | O29: =Segment!V55 -> 0 | P29: =Segment!W55 -> 0 | Q29: =Segment!X55 -> 6.2103795 | R29: =Segment!Y55 -> 110.45971 | S29: =Segment!Z55 -> 32.879002 | T29: =Segment!AA55 -> -20.091171 | U29: =Segment!AB55 -> 72.317929 | V29: =Segment!AC55 -> -42.945496 | ... Y29: =Segment!AF55 -> 79.295975
B30: EBITDA | C30: =C20+C27+C23-C33-C34 -> 380.2942 | D30: =D20+D27+D23-D33-D34 -> 326.33306 | E30: =E20+E27+E23-E33-E34 -> 813.01568 | F30: =F20+F27+F23-F33-F34 -> 1135.5715 | G30: =G20+G27+G23-G33-G34 -> 1657.6191 | H30: =H20+H27+H23-H33-H34 -> 1995.1044 | I30: =I20+I27+I23-I33-I34 -> 2633.1921 | J30: =J20+J27+J23-J33-J34 -> 4143.1356 | ... M30: =M20+M27+M23-M33-M34 -> 8873.3424 | O30: =O20+O27+O23-O33-O34 -> 566.5236 | P30: =P20+P27+P23-P33-P34 -> 434.60519 | Q30: =Q20+Q27+Q23-Q33-Q34 -> 931.64747 | R30: =R20+R27+R23-R33-R34 -> 725.97164 | S30: =S20+S27+S23-S33-S34 -> 1078.2342 | T30: =T20+T27+T23-T33-T34 -> 916.87019 | U30: =U20+U27+U23-U33-U34 -> 1442.3025 | V30: =V20+V27+V23-V33-V34 -> 1190.8897 | ... Y30: =Y20+Y27+Y23-Y33-Y34 -> 3087.0991
B31: yoy % | C31: =IF(ISERROR(C30/#REF!-1)," ",(C30/#REF!-1)) | D31: =IF(ISERROR(D30/C30-1)," ",(D30/C30-1)) -> -0.14189314 | E31: =IF(ISERROR(E30/D30-1)," ",(E30/D30-1)) -> 1.4913678 | F31: =IF(ISERROR(F30/E30-1)," ",(F30/E30-1)) -> 0.39674003 | G31: =IF(ISERROR(G30/F30-1)," ",(G30/F30-1)) -> 0.45972231 | H31: =IF(ISERROR(H30/G30-1)," ",(H30/G30-1)) -> 0.20359641 | I31: =IF(ISERROR(I30/H30-1)," ",(I30/H30-1)) -> 0.31982674 | J31: =IF(ISERROR(J30/I30-1)," ",(J30/I30-1)) -> 0.57342698 | K31: =IF(ISERROR(K30/J30-1)," ",(K30/J30-1)) -> 0.41242202 | ... M31: =IF(ISERROR(M30/L30-1)," ",(M30/L30-1)) -> 0.22004005
B33: Depreciation | C33: =+'Raw Data'!C31 -> 0 | D33: =+'Raw Data'!D31 -> -77.859575 | E33: =+'Raw Data'!E31 -> -102.17591 | F33: =+'Raw Data'!F31 -> -124.5853 | G33: =+'Raw Data'!G31 -> -173.1049 | H33: =+'Raw Data'!H31 -> -211.99102 | I33: =+'Raw Data'!I31 -> -241.69914 | J33: =+'Raw Data'!J31 -> -325.93172 | K33: =-Capex!L21 -> -392.57668 | L33: =-Capex!M21 -> -473.34602 | M33: =-Capex!N21 -> -691.37348 | Q33: =-Wind!CG237 -> -79.766064 | R33: =+G33-Q33 -> -93.338832 | S33: =-Wind!CK237 -> -99.823009 | T33: =+H33-S33 -> -112.16801 | U33: =-Wind!CO237 -> -114.75822 | V33: =+I33-U33 -> -126.94092 | W33: =-Wind!CS237 -> -154.38297 | X33: =+J33-W33 -> -171.54875 | Y33: =+K33-X33 -> -221.02793
B34: Amortization | C34: =+'Raw Data'!C32 -> 0 | D34: =+'Raw Data'!D32 -> -7.1119131 | E34: =+'Raw Data'!E32 -> -7.5485512 | F34: =+'Raw Data'!F32 -> -9.8574461 | G34: =+'Raw Data'!G32 -> -12.007907 | H34: =+'Raw Data'!H32 -> -11.95035 | I34: =+'Raw Data'!I32 -> -12.33999 | J34: =+'Raw Data'!J32 -> -17.11997 | K34: =-(Capex!L30+Capex!L38) -> -23.639184 | L34: =-(Capex!M30+Capex!M38) -> -32.629976 | M34: =-(Capex!N30+Capex!N38) -> -42.739316 | Q34: =-SUM(Wind!CG238:CG240) -> -9.8495758 | R34: =+G34-Q34 -> -2.1583314 | S34: =-SUM(Wind!CK238:CK240) -> -16.565221 | T34: =+H34-S34 -> 4.6148708 | U34: =-SUM(Wind!CO238:CO240) -> -14.771789 | V34: =+I34-U34 -> 2.4317986 | W34: =-SUM(Wind!CS238:CS240) -> -17.253343 | X34: =+J34-W34 -> 0.13337303 | Y34: =+K34-X34 -> -23.772557
B35: EBIT (operating profit) | C35: =C30+C33+C34 -> 380.2942 | D35: =D30+D33+D34 -> 241.36158 | E35: =E30+E33+E34 -> 703.29121 | F35: =F30+F33+F34 -> 1001.1288 | G35: =G30+G33+G34 -> 1472.5063 | H35: =H30+H33+H34 -> 1771.163 | I35: =I30+I33+I34 -> 2379.153 | J35: =J30+J33+J34 -> 3800.0839 | ... M35: =M30+M33+M34 -> 8139.2296 | O35: =O30+O33+O34 -> 566.5236 | P35: =P30+P33+P34 -> 434.60519 | Q35: =Q30+Q33+Q34 -> 842.03183 | R35: =R30+R33+R34 -> 630.47447 | S35: =S30+S33+S34 -> 961.84599 | T35: =T30+T33+T34 -> 809.31704 | U35: =U30+U33+U34 -> 1312.7725 | V35: =V30+V33+V34 -> 1066.3806 | ... Y35: =Y30+Y33+Y34 -> 2842.2986
B36: yoy % | C36: =IF(ISERROR(C35/#REF!-1)," ",(C35/#REF!-1)) | D36: =IF(ISERROR(D35/C35-1)," ",(D35/C35-1)) -> -0.36532933 | E36: =IF(ISERROR(E35/D35-1)," ",(E35/D35-1)) -> 1.9138491 | F36: =IF(ISERROR(F35/E35-1)," ",(F35/E35-1)) -> 0.42349111 | G36: =IF(ISERROR(G35/F35-1)," ",(G35/F35-1)) -> 0.47084603 | H36: =IF(ISERROR(H35/G35-1)," ",(H35/G35-1)) -> 0.20282204 | I36: =IF(ISERROR(I35/H35-1)," ",(I35/H35-1)) -> 0.34327161 | J36: =IF(ISERROR(J35/I35-1)," ",(J35/I35-1)) -> 0.59724232 | K36: =IF(ISERROR(K35/J35-1)," ",(K35/J35-1)) -> 0.43040001 | ... M36: =IF(ISERROR(M35/L35-1)," ",(M35/L35-1)) -> 0.2027796
B37: EBIT margin | C37: =C35/C13 -> 0.13372712 | D37: =D35/D13 -> 0.079459659 | E37: =E35/E13 -> 0.16710301 | F37: =F35/F13 -> 0.20190143 | G37: =G35/G13 -> 0.21102662 | H37: =H35/H13 -> 0.20824008 | I37: =I35/I13 -> 0.21124003 | J37: =J35/J13 -> 0.23992168 | ... M37: =M35/M13 -> 0.27320198
B38: Net financial expenses | C38: ='Raw Data'!C42 -> -10.454 | D38: ='Raw Data'!D42 -> -5.0820752 | E38: ='Raw Data'!E42 -> 13.965657 | F38: ='Raw Data'!F42 -> 15.93094 | G38: ='Raw Data'!G42 -> 11.393957 | H38: ='Raw Data'!H42 -> -41.039484 | I38: ='Raw Data'!I42 -> -2.2856168 | J38: ='Raw Data'!J42 -> 190.53573 | K38: =SUM(K39:K42) -> 139.04711 | L38: =SUM(L39:L42) -> 191.45248 | M38: =SUM(M39:M42) -> 208.22262 | O38: =Segment!V53 -> -6.822 | P38: =Segment!W53 -> 22.75294 | Q38: =Segment!X53 -> -4.2964605 | R38: =Segment!Y53 -> 15.690418 | S38: =Segment!Z53 -> 20.767388 | T38: =Segment!AA53 -> -61.806872 | U38: =Segment!AB53 -> -5.2930758 | V38: =Segment!AC53 -> 3.007459 | ... Y38: =Segment!AF53 -> 64.222622
B39: Interest income | C39: ='Raw Data'!C38 -> 0 | D39: ='Raw Data'!D38 -> 2.7387298 | E39: ='Raw Data'!E38 -> 20.080901 | F39: ='Raw Data'!F38 -> 26.040389 | G39: ='Raw Data'!G38 -> 29.262542 | H39: ='Raw Data'!H38 -> 19.820948 | I39: ='Raw Data'!I38 -> 122.48631 | J39: ='Raw Data'!J38 -> 260.35607 | K39: =K96 -> 270.40038 | L39: =L96 -> 322.80575 | M39: =M96 -> 339.57589 | U39: -39.203 | V39: =I39-U39 -> 161.68931 | W39: -137.1066 | X39: =J39-W39 -> 397.46267 | Y39: =K39-X39 -> -127.06229
