Workbook
Name A_ALL_BOX: #REF!
Name A_ALL_DBX: #REF!
Name A_ALL_KEYWORDS_TYPE_ScalarContributed_EQTY_200019588: #REF!,#REF!,#REF!,#REF!
Name A_ALL_KEYWORDS_TYPE_ScalarContributed_ISSR_208018133: #REF!,#REF!,#REF!,#REF!,#REF!,#REF!,#REF!,#REF!,#REF!,#REF!,#REF!,#REF!
Name A_ALL_KEYWORDS_TYPE_Vector_EQTY_200019588: #REF!,#REF!,#REF!,#REF!,#REF!,#REF!,#REF!
Name A_ALL_KEYWORDS_TYPE_Vector_ISSR_208018133: #REF!,#REF!,#REF!,#REF!,#REF!,#REF!,#REF!,#REF!,#REF!,#REF!,#REF!,#REF!,#REF!,#REF!,#REF!,#REF!,#REF!,#REF!,#REF!,#REF!,#REF!,#REF!,#REF!
Name A_ALL_MDB: #REF!
Name A_ALL_NTNX: [1]NTNX_Annotation_Sheet!$A$1:$CB$331
Name A_ALL_PVTL: #REF!
Name A_ALL_SECTION_KEYWORDS_EQTY_200019588_13A: #REF!
Name A_ALL_SECTION_KEYWORDS_EQTY_200019588_13K: #REF!
Name A_ALL_SECTION_KEYWORDS_ISSR_208018133_1314: #REF!
Name A_ALL_SECTION_KEYWORDS_ISSR_208018133_1319: #REF!
Name A_ALL_SECTION_KEYWORDS_ISSR_208018133_131E: #REF!
Name A_ALL_SECTION_KEYWORDS_ISSR_208018133_13V: #REF!,#REF!
Name A_ALL_SECTION_KEYWORDS_ISSR_208020111_136J: #REF!,#REF!
Name A_ALL_SNOW: #REF!
Name A_ALL_TTAN: #REF!
Name AL_email: "alamba@isigrp.com"
Name AL_phone: "(XXX) XXX-XXXX"
Name AVELIFE: 3
Name BB_email: "bbaytosh@isigrp.com"
Name BB_phone: "(212) 446-9469"
Name CUR3MTH: 6
Name CURCYTD: 9
Name CURMTH: 1
Name CURMYTD: 12
Name CURRENT_MONTH_FIXING: 23
Name CURRENT_MONTH_SPOT: 6
Name CURWEEK: 1
Name CYTDVOL: 11
Name DB: "WIRENYPROD"
Name E_ALL_BOX: #REF!
Name E_ALL_DBX: #REF!
Name E_ALL_MDB: #REF!
Name E_ALL_MSFT: [2]MSFT_Exchange_Sheet!$A$1:$FE$331
Name E_ALL_NTNX: [1]NTNX_Exchange_Sheet!$A$1:$CB$331
Name E_ALL_PING: #REF!
Name E_ALL_PVTL: #REF!
Name E_ALL_SECTION_KEYWORDS_ISSR_208020111_136J: #REF!,#REF!
Name E_ALL_SNOW: #REF!
Name E_ALL_TTAN: #REF!
Name FINCriteriaType: 1
Name fx: 120
Name FYE: "FYE"
Name HB_email: "hbellini@isigrp.com"
Name HB_phone: "(XXX) XXX-XXXX"
Name L_ALL_BOX: #REF!
Name L_ALL_DBX: #REF!
Name L_ALL_DOCU: #REF!
Name L_ALL_KEYWORDS_TYPE_ScalarContributed_EQTY_200019588: #REF!,#REF!,#REF!,#REF!
Name L_ALL_KEYWORDS_TYPE_ScalarContributed_ISSR_208018133: #REF!,#REF!,#REF!,#REF!,#REF!,#REF!,#REF!,#REF!,#REF!,#REF!,#REF!,#REF!
Name L_ALL_KEYWORDS_TYPE_Vector_EQTY_200019588: #REF!,#REF!,#REF!,#REF!,#REF!,#REF!,#REF!
Name L_ALL_KEYWORDS_TYPE_Vector_ISSR_208018133: #REF!,#REF!,#REF!,#REF!,#REF!,#REF!,#REF!,#REF!,#REF!,#REF!,#REF!,#REF!,#REF!,#REF!,#REF!,#REF!,#REF!,#REF!,#REF!,#REF!,#REF!,#REF!,#REF!
Name L_ALL_MDB: #REF!
Name L_ALL_MSFT: [2]MSFT_Live_Sheet!$A$1:$FE$331
Name L_ALL_NTNX: [1]NTNX_Live_Sheet!$A$1:$CB$331
Name L_ALL_PING: #REF!
Name L_ALL_PVTL: #REF!
Name L_ALL_SECTION_KEYWORDS_EQTY_200019588_13A: #REF!

Sheet __FDSCACHE__
B1: This sheet contains FactSet XML data for use with this workbook's =FDS codes. Modifying the worksheet's contents may damage the workbook's =FDS functionality.

Sheet Cover
C2: Snowflake Analyst Model
C3: Ticker: | D3: SNOW
C4: Date: | D4: =TODAY() -> 45995
B6: Kash Rangan
B7: (415) 249-7318
B8: kash.rangan@gs.com
B10: Matthew Martino
B11: (212) 902-0695
B12: matt.martino@gs.com
B14: Selina Zhang
B15: (212) 357-9979
B16: selina.zhang@gs.com
B18: Nishad Patwardhan
B19: (332) 245-7726
B20: nishad.patwardhan@gs.com

Sheet Revenue Build
B2: Snowflake Inc.
B3: Income Statement (Non-GAAP)
B4: Fiscal Year Ends Jan 31
B5: ($ millions, except per share amounts)
C7: =Dates!M3 -> 2018 (A) | H7: =Dates!R3 -> 2019 (A) | M7: =Dates!W3 -> 2020 (A) | R7: =Dates!AB3 -> 2021 (A) | W7: =Dates!AG3 -> 2022 (A) | AB7: =Dates!AL3 -> 2023 (A) | AG7: =Dates!AQ3 -> 2024 (A) | AL7: =Dates!AV3 -> 2025 (A) | AQ7: =Dates!BA3 -> 2026 (E) | AV7: =Dates!BF3 -> 2027 (E) | BA7: =Dates!BK3 -> 2028 (E) | BF7: =Dates!BP3 -> 2029 (E) | BK7: =Dates!BU3 -> 2030 (E)
C8: =Dates!M4 -> 1Q18 (A) | D8: =Dates!N4 -> 2Q18 (A) | E8: =Dates!O4 -> 3Q18 (A) | F8: =Dates!P4 -> 4Q18 (A) | G8: =Dates!Q4 -> FY18 (A) | H8: =Dates!R4 -> 1Q19 (A) | I8: =Dates!S4 -> 2Q19 (A) | J8: =Dates!T4 -> 3Q19 (A) | ... BO8: =Dates!BY4 -> FY30 (E)
C9: =Dates!M5 -> 42855 | D9: =Dates!N5 -> 42947 | E9: =Dates!O5 -> 43039 | F9: =Dates!P5 -> 43131 | G9: =Dates!Q5 -> 43131 | H9: =Dates!R5 -> 43220 | I9: =Dates!S5 -> 43312 | J9: =Dates!T5 -> 43404 | ... BO9: =Dates!BY5 -> 47514
A11: TREV | B11: Total revenue | H11: =H15+H51 -> 13.403 | I11: =I15+I51 -> 17.905 | J11: =J15+J51 -> 28.68 | K11: =K15+K51 -> 36.678 | L11: =L15+L51 -> 96.666 | M11: =M15+M51 -> 43.705 | N11: =N15+N51 -> 60.339 | O11: =O15+O51 -> 73.012 | ... BO11: =BO15+BO51 -> 10933.987
A12: TREVYY | B12: % yoy | H12: =IFERROR(H11/C11-1,"--") -> -- | I12: =IFERROR(I11/D11-1,"--") -> -- | J12: =IFERROR(J11/E11-1,"--") -> -- | K12: =IFERROR(K11/F11-1,"--") -> -- | L12: =IFERROR(L11/G11-1,"--") -> -- | M12: =IFERROR(M11/H11-1,"--") -> 2.2608371 | N12: =IFERROR(N11/I11-1,"--") -> 2.3699525 | O12: =IFERROR(O11/J11-1,"--") -> 1.5457462 | ... BO12: =IFERROR(BO11/BJ11-1,"--") -> 0.23213886
A13: TREVQQ | B13: % qoq | H13: =IFERROR(H11/F11-1,"--") -> -- | I13: =IFERROR(I11/H11-1,"--") -> 0.33589495 | J13: =IFERROR(J11/I11-1,"--") -> 0.60178721 | K13: =IFERROR(K11/J11-1,"--") -> 0.27887029 | L13: -- | M13: =IFERROR(M11/K11-1,"--") -> 0.19158624 | N13: =IFERROR(N11/M11-1,"--") -> 0.38059719 | O13: =IFERROR(O11/N11-1,"--") -> 0.21003 | P13: =IFERROR(P11/O11-1,"--") -> 0.20106284 | Q13: -- | R13: =IFERROR(R11/P11-1,"--") -> 0.24087716 | S13: =IFERROR(S11/R11-1,"--") -> 0.2235905 | T13: =IFERROR(T11/S11-1,"--") -> 0.19887341 | U13: =IFERROR(U11/T11-1,"--") -> 0.19321029 | V13: -- | W13: =IFERROR(W11/U11-1,"--") -> 0.20186911 | X13: =IFERROR(X11/W11-1,"--") -> 0.18908411 | Y13: =IFERROR(Y11/X11-1,"--") -> 0.2286681 | Z13: =IFERROR(Z11/Y11-1,"--") -> 0.14750883 | AA13: -- | AB13: =IFERROR(AB11/Z11-1,"--") -> 0.10057221 | AC13: =IFERROR(AC11/AB11-1,"--") -> 0.1772778 | AD13: =IFERROR(AD11/AC11-1,"--") -> 0.1202217 | AE13: =IFERROR(AE11/AD11-1,"--") -> 0.057419017 | AF13: -- | AG13: =IFERROR(AG11/AE11-1,"--") -> 0.058720366 | AH13: =IFERROR(AH11/AG11-1,"--") -> 0.080851637 | AI13: =IFERROR(AI11/AH11-1,"--") -> 0.089248358 | AJ13: =IFERROR(AJ11/AI11-1,"--") -> 0.055199524 | AK13: -- | AL13: =IFERROR(AL11/AJ11-1,"--") -> 0.0697174 | AM13: =IFERROR(AM11/AL11-1,"--") -> 0.048405411 | AN13: =IFERROR(AN11/AM11-1,"--") -> 0.084333633 | AO13: =IFERROR(AO11/AN11-1,"--") -> 0.047422019 | AP13: -- | AQ13: =IFERROR(AQ11/AO11-1,"--") -> 0.056045482 | AR13: =IFERROR(AR11/AQ11-1,"--") -> 0.098740588 | AS13: =IFERROR(AS11/AR11-1,"--") -> 0.059337851 | AT13: =IFERROR(AT11/AS11-1,"--") -> 0.029593363 | AU13: -- | AV13: =IFERROR(AV11/AT11-1,"--") -> 0.051415566 | AW13: =IFERROR(AW11/AV11-1,"--") -> 0.077702662 | AX13: =IFERROR(AX11/AW11-1,"--") -> 0.061679661 | AY13: =IFERROR(AY11/AX11-1,"--") -> 0.031227037 | AZ13: -- | BA13: =IFERROR(BA11/AY11-1,"--") -> 0.051656838 | BB13: =IFERROR(BB11/BA11-1,"--") -> 0.080750139 | BC13: =IFERROR(BC11/BB11-1,"--") -> 0.06458557 | BD13: =IFERROR(BD11/BC11-1,"--") -> 0.020906453 | BE13: -- | BF13: =IFERROR(BF11/BD11-1,"--") -> 0.043255196 | BG13: =IFERROR(BG11/BF11-1,"--") -> 0.078245432 | BH13: =IFERROR(BH11/BG11-1,"--") -> 0.08362997 | BI13: =IFERROR(BI11/BH11-1,"--") -> 0.025390643 | BJ13: -- | BK13: =IFERROR(BK11/BI11-1,"--") -> 0.037762815 | BL13: =IFERROR(BL11/BK11-1,"--") -> 0.064624957 | BM13: =IFERROR(BM11/BL11-1,"--") -> 0.090957753 | BN13: =IFERROR(BN11/BM11-1,"--") -> 0.014809061 | BO13: --
A15: PRODREV | B15: Product revenue | H15: ='IS (Non-GAAP)'!H14 -> 13.186 | I15: ='IS (Non-GAAP)'!I14 -> 17.675 | J15: ='IS (Non-GAAP)'!J14 -> 28.457 | K15: ='IS (Non-GAAP)'!K14 -> 36.365 | L15: =SUM(H15:K15) -> 95.683 | M15: ='IS (Non-GAAP)'!M14 -> 42.766 | N15: ='IS (Non-GAAP)'!N14 -> 57.818 | O15: ='IS (Non-GAAP)'!O14 -> 69.213 | P15: ='IS (Non-GAAP)'!P14 -> 82.432 | Q15: =SUM(M15:P15) -> 252.229 | R15: ='IS (Non-GAAP)'!R14 -> 101.817 | S15: ='IS (Non-GAAP)'!S14 -> 125.216 | T15: ='IS (Non-GAAP)'!T14 -> 148.473 | U15: ='IS (Non-GAAP)'!U14 -> 178.288 | V15: =SUM(R15:U15) -> 553.794 | W15: ='IS (Non-GAAP)'!W14 -> 213.83 | X15: ='IS (Non-GAAP)'!X14 -> 254.623 | Y15: ='IS (Non-GAAP)'!Y14 -> 312.458 | Z15: ='IS (Non-GAAP)'!Z14 -> 359.558 | AA15: =SUM(W15:Z15) -> 1140.469 | AB15: ='IS (Non-GAAP)'!AB14 -> 394.434 | AC15: ='IS (Non-GAAP)'!AC14 -> 466.268 | AD15: ='IS (Non-GAAP)'!AD14 -> 522.752 | AE15: ='IS (Non-GAAP)'!AE14 -> 555.329 | AF15: =SUM(AB15:AE15) -> 1938.783 | AG15: ='IS (Non-GAAP)'!AG14 -> 590.072 | AH15: ='IS (Non-GAAP)'!AH14 -> 640.209 | AI15: ='IS (Non-GAAP)'!AI14 -> 698.478 | AJ15: ='IS (Non-GAAP)'!AJ14 -> 738.09 | AK15: =SUM(AG15:AJ15) -> 2666.849 | AL15: ='IS (Non-GAAP)'!AL14 -> 789.587 | AM15: ='IS (Non-GAAP)'!AM14 -> 829.25 | AN15: ='IS (Non-GAAP)'!AN14 -> 900.282 | AO15: ='IS (Non-GAAP)'!AO14 -> 943.303 | AP15: =SUM(AL15:AO15) -> 3462.422 | AQ15: ='IS (Non-GAAP)'!AQ14 -> 996.813 | AR15: ='IS (Non-GAAP)'!AR14 -> 1090.496 | AS15: ='IS (Non-GAAP)'!AS14 -> 1158.377 | AT15: =AT96 -> 1198.816 | AU15: =SUM(AQ15:AT15) -> 4444.502 | AV15: =AV96 -> 1261.6397 | AW15: =AW96 -> 1353.2086 | AX15: =AX96 -> 1440.4205 | AY15: =AY96 -> 1492.4918 | AZ15: =SUM(AV15:AY15) -> 5547.7607 | BA15: =BA96 -> 1571.2058 | BB15: =BB96 -> 1690.9536 | BC15: =BC96 -> 1804.6013 | BD15: =BD96 -> 1849.6205 | BE15: =SUM(BA15:BD15) -> 6916.3812 | BF15: =BF96 -> 1931.2045 | BG15: =BG96 -> 2074.1306 | BH15: =BH96 -> 2254.078 | BI15: =BI96 -> 2319.8661 | BJ15: =SUM(BF15:BI15) -> 8579.2792 | BK15: =BK96 -> 2408.8503 | BL15: =BL96 -> 2554.3169 | BM15: =BM96 -> 2794.5987 | BN15: =BN96 -> 2844.6724 | BO15: =SUM(BK15:BN15) -> 10602.438
A16: PRODREVCHG | B16: $ change yoy | H16: -- | I16: =I15-H15 -> 4.489 | J16: =J15-I15 -> 10.782 | K16: =K15-J15 -> 7.908 | L16: =L15-G15 -> 95.683 | M16: =M15-K15 -> 6.401 | N16: =N15-M15 -> 15.052 | O16: =O15-N15 -> 11.395 | P16: =P15-O15 -> 13.219 | Q16: =Q15-L15 -> 156.546 | R16: =R15-P15 -> 19.385 | S16: =S15-R15 -> 23.399 | T16: =T15-S15 -> 23.257 | U16: =U15-T15 -> 29.815 | V16: =V15-Q15 -> 301.565 | W16: =W15-U15 -> 35.542 | X16: =X15-W15 -> 40.793 | Y16: =Y15-X15 -> 57.835 | Z16: =Z15-Y15 -> 47.1 | AA16: =AA15-V15 -> 586.675 | AB16: =AB15-Z15 -> 34.876 | AC16: =AC15-AB15 -> 71.834 | AD16: =AD15-AC15 -> 56.484 | AE16: =AE15-AD15 -> 32.577 | AF16: =AF15-AA15 -> 798.314 | AG16: =AG15-AE15 -> 34.743 | AH16: =AH15-AG15 -> 50.137 | AI16: =AI15-AH15 -> 58.269 | AJ16: =AJ15-AI15 -> 39.612 | AK16: =AK15-AF15 -> 728.066 | AL16: =AL15-AJ15 -> 51.497 | AM16: =AM15-AL15 -> 39.663 | AN16: =AN15-AM15 -> 71.032 | AO16: =AO15-AN15 -> 43.021 | AP16: =AP15-AK15 -> 795.573 | AQ16: =AQ15-AO15 -> 53.51 | AR16: =AR15-AQ15 -> 93.683 | AS16: =AS15-AR15 -> 67.881 | AT16: =AT15-AS15 -> 40.439006 | AU16: =AU15-AP15 -> 982.08001 | AV16: =AV15-AT15 -> 62.823731 | AW16: =AW15-AV15 -> 91.568828 | AX16: =AX15-AW15 -> 87.21194 | AY16: =AY15-AX15 -> 52.071344 | AZ16: =AZ15-AU15 -> 1103.2586 | BA16: =BA15-AY15 -> 78.713983 | BB16: =BB15-BA15 -> 119.74774 | BC16: =BC15-BB15 -> 113.64776 | BD16: =BD15-BC15 -> 45.019135 | BE16: =BE15-AZ15 -> 1368.6206 | BF16: =BF15-BD15 -> 81.584033 | BG16: =BG15-BF15 -> 142.9261 | BH16: =BH15-BG15 -> 179.94745 | BI16: =BI15-BH15 -> 65.788056 | BJ16: =BJ15-BE15 -> 1662.898 | BK16: =BK15-BI15 -> 88.984167 | BL16: =BL15-BK15 -> 145.4666 | BM16: =BM15-BL15 -> 240.28182 | BN16: =BN15-BM15 -> 50.073735 | BO16: =BO15-BJ15 -> 2023.159
A17: PRODREVYY | B17: % yoy | H17: =IFERROR(H15/C15-1,"--") -> -- | I17: =IFERROR(I15/D15-1,"--") -> -- | J17: =IFERROR(J15/E15-1,"--") -> -- | K17: =IFERROR(K15/F15-1,"--") -> -- | L17: =IFERROR(L15/G15-1,"--") -> -- | M17: =IFERROR(M15/H15-1,"--") -> 2.2432883 | N17: =IFERROR(N15/I15-1,"--") -> 2.271174 | O17: =IFERROR(O15/J15-1,"--") -> 1.4321959 | ... BO17: =IFERROR(BO15/BJ15-1,"--") -> 0.23581923
A18: PRODREVQQ | B18: % qoq | H18: =IFERROR(H15/F15-1,"--") -> -- | I18: =IFERROR(I15/H15-1,"--") -> 0.34043683 | J18: =IFERROR(J15/I15-1,"--") -> 0.61001414 | K18: =IFERROR(K15/J15-1,"--") -> 0.27789296 | L18: -- | M18: =IFERROR(M15/K15-1,"--") -> 0.1760209 | N18: =IFERROR(N15/M15-1,"--") -> 0.35196184 | O18: =IFERROR(O15/N15-1,"--") -> 0.19708395 | P18: =IFERROR(P15/O15-1,"--") -> 0.19099013 | Q18: -- | R18: =IFERROR(R15/P15-1,"--") -> 0.23516353 | S18: =IFERROR(S15/R15-1,"--") -> 0.22981427 | T18: =IFERROR(T15/S15-1,"--") -> 0.18573505 | U18: =IFERROR(U15/T15-1,"--") -> 0.20081092 | V18: -- | W18: =IFERROR(W15/U15-1,"--") -> 0.19935161 | X18: =IFERROR(X15/W15-1,"--") -> 0.19077304 | Y18: =IFERROR(Y15/X15-1,"--") -> 0.22713973 | Z18: =IFERROR(Z15/Y15-1,"--") -> 0.15074026 | AA18: -- | AB18: =IFERROR(AB15/Z15-1,"--") -> 0.096996868 | AC18: =IFERROR(AC15/AB15-1,"--") -> 0.18211919 | AD18: =IFERROR(AD15/AC15-1,"--") -> 0.12114063 | AE18: =IFERROR(AE15/AD15-1,"--") -> 0.062318269 | AF18: -- | AG18: =IFERROR(AG15/AE15-1,"--") -> 0.062562913 | AH18: =IFERROR(AH15/AG15-1,"--") -> 0.084967597 | AI18: =IFERROR(AI15/AH15-1,"--") -> 0.09101559 | AJ18: =IFERROR(AJ15/AI15-1,"--") -> 0.056711879 | AK18: -- | AL18: =IFERROR(AL15/AJ15-1,"--") -> 0.069770624 | AM18: =IFERROR(AM15/AL15-1,"--") -> 0.05023259 | AN18: =IFERROR(AN15/AM15-1,"--") -> 0.085658125 | AO18: =IFERROR(AO15/AN15-1,"--") -> 0.047786138 | AP18: -- | AQ18: =IFERROR(AQ15/AO15-1,"--") -> 0.056726206 | AR18: =IFERROR(AR15/AQ15-1,"--") -> 0.093982522 | AS18: =IFERROR(AS15/AR15-1,"--") -> 0.062247821 | AT18: =IFERROR(AT15/AS15-1,"--") -> 0.034910056 | AU18: -- | AV18: =IFERROR(AV15/AT15-1,"--") -> 0.052404815 | AW18: =IFERROR(AW15/AV15-1,"--") -> 0.07257922 | AX18: =IFERROR(AX15/AW15-1,"--") -> 0.064448262 | AY18: =IFERROR(AY15/AX15-1,"--") -> 0.036150099 | AZ18: -- | BA18: =IFERROR(BA15/AY15-1,"--") -> 0.052739975 | BB18: =IFERROR(BB15/BA15-1,"--") -> 0.076213912 | BC18: =IFERROR(BC15/BB15-1,"--") -> 0.067209272 | BD18: =IFERROR(BD15/BC15-1,"--") -> 0.024946859 | BE18: -- | BF18: =IFERROR(BF15/BD15-1,"--") -> 0.044108526 | BG18: =IFERROR(BG15/BF15-1,"--") -> 0.074008783 | BH18: =IFERROR(BH15/BG15-1,"--") -> 0.086758012 | BI18: =IFERROR(BI15/BH15-1,"--") -> 0.029186237 | BJ18: -- | BK18: =IFERROR(BK15/BI15-1,"--") -> 0.038357458 | BL18: =IFERROR(BL15/BK15-1,"--") -> 0.060388394 | BM18: =IFERROR(BM15/BL15-1,"--") -> 0.094068918 | BN18: =IFERROR(BN15/BM15-1,"--") -> 0.017918041 | BO18: --
B19: % total revenue | H19: =H15/H$11 -> 0.98380959 | I19: =I15/I$11 -> 0.98715443 | J19: =J15/J$11 -> 0.99222455 | K19: =K15/K$11 -> 0.99146627 | L19: =L15/L$11 -> 0.98983096 | M19: =M15/M$11 -> 0.97851504 | N19: =N15/N$11 -> 0.95821939 | O19: =O15/O$11 -> 0.94796746 | ... BO19: =BO15/BO$11 -> 0.9696772
B21: Product Revenue (ex. Leap Year) | AL21: =AG15*(1+AL22) -> 778.89504
B22: % yoy | AL22: 0.32
B23: % qoq | AL23: =IFERROR(AL21/AJ15-1,"--") -> 0.05528464
B24: Net New Revenue (YoY) | AL24: =IFERROR(AL15-AG15,"--") -> 199.515
B25: Net New Revenue (QoQ) | AL25: =IFERROR(AL21-AJ15,"--") -> 40.80504
B27: Net New Product Revenue (Q/Q) | I27: =I15-H15 -> 4.489 | J27: =J15-I15 -> 10.782 | K27: =K15-J15 -> 7.908 | M27: =M15-K15 -> 6.401 | N27: =N15-M15 -> 15.052 | O27: =O15-N15 -> 11.395 | P27: =P15-O15 -> 13.219 | Q27: =SUM(M27:P27) -> 46.067 | R27: =R15-P15 -> 19.385 | S27: =S15-R15 -> 23.399 | T27: =T15-S15 -> 23.257 | U27: =U15-T15 -> 29.815 | V27: =SUM(R27:U27) -> 95.856 | W27: =W15-U15 -> 35.542 | X27: =X15-W15 -> 40.793 | Y27: =Y15-X15 -> 57.835 | Z27: =Z15-Y15 -> 47.1 | AA27: =SUM(W27:Z27) -> 181.27 | AB27: =AB15-Z15 -> 34.876 | AC27: =AC15-AB15 -> 71.834 | AD27: =AD15-AC15 -> 56.484 | AE27: =AE15-AD15 -> 32.577 | AF27: =SUM(AB27:AE27) -> 195.771 | AG27: =AG15-AE15 -> 34.743 | AH27: =AH15-AG15 -> 50.137 | AI27: =AI15-AH15 -> 58.269 | AJ27: =AJ15-AI15 -> 39.612 | AK27: =SUM(AG27:AJ27) -> 182.761 | AL27: =AL15-AJ15 -> 51.497 | AM27: =AM15-AL15 -> 39.663 | AN27: =AN15-AM15 -> 71.032 | AO27: =AO15-AN15 -> 43.021 | AP27: =SUM(AL27:AO27) -> 205.213 | AQ27: =AQ15-AO15 -> 53.51 | AR27: =AR15-AQ15 -> 93.683 | AS27: =AS15-AR15 -> 67.881 | AT27: =AT15-AS15 -> 40.439006 | AU27: =SUM(AQ27:AT27) -> 255.51301 | AV27: =AV15-AT15 -> 62.823731 | AW27: =AW15-AV15 -> 91.568828 | AX27: =AX15-AW15 -> 87.21194 | AY27: =AY15-AX15 -> 52.071344 | AZ27: =SUM(AV27:AY27) -> 293.67584 | BA27: =BA15-AY15 -> 78.713983 | BB27: =BB15-BA15 -> 119.74774 | BC27: =BC15-BB15 -> 113.64776 | BD27: =BD15-BC15 -> 45.019135 | BE27: =SUM(BA27:BD27) -> 357.12862 | BF27: =BF15-BD15 -> 81.584033 | BG27: =BG15-BF15 -> 142.9261 | BH27: =BH15-BG15 -> 179.94745 | BI27: =BI15-BH15 -> 65.788056 | BJ27: =SUM(BF27:BI27) -> 470.24563 | BK27: =BK15-BI15 -> 88.984167 | BL27: =BL15-BK15 -> 145.4666 | BM27: =BM15-BL15 -> 240.28182 | BN27: =BN15-BM15 -> 50.073735 | BO27: =SUM(BK27:BN27) -> 524.80633
B28: =B52 -> % yoy | N28: =N27/I27 -> 3.3530853 | O28: =O27/J27 -> 1.056854 | P28: =P27/K27 -> 1.6715984 | R28: =R27/M27-1 -> 2.0284331 | S28: =S27/N27-1 -> 0.55454425 | T28: =T27/O27-1 -> 1.0409829 | U28: =U27/P27-1 -> 1.2554656 | V28: =V27/Q27-1 -> 1.0807954 | W28: =W27/R27-1 -> 0.83347949 | X28: =X27/S27-1 -> 0.7433651 | Y28: =Y27/T27-1 -> 1.4867782 | ... BO28: =BO27/BJ27-1 -> 0.11602595
B30: Storage Revenue | AG30: =AG15*11% -> 64.90792 | AH30: =AH15*11% -> 70.42299 | AI30: =AI15*11% -> 76.83258 | AJ30: =AJ15*11% -> 81.1899 | AK30: =SUM(AG30:AJ30) -> 293.35339 | AL30: =AL15*11% -> 86.85457 | AM30: =AM15*11% -> 91.2175 | AN30: =AN15*11% -> 99.03102 | AO30: =AO15*11% -> 103.76333 | AP30: =SUM(AL30:AO30) -> 380.86642
B31: % Product Revenue | AG31: =AG30/AG15 -> 0.11 | AH31: =AH30/AH15 -> 0.11 | AI31: =AI30/AI15 -> 0.11 | AJ31: =AJ30/AJ15 -> 0.11 | AK31: =AK30/AK15 -> 0.11 | AL31: =AL30/AL15 -> 0.11 | AM31: =AM30/AM15 -> 0.11 | AN31: =AN30/AN15 -> 0.11 | ... AP31: =AP30/AP15 -> 0.11
B32: Implied Compute Revenue | AG32: =AG15-AG30 -> 525.16408 | AH32: =AH15-AH30 -> 569.78601 | AI32: =AI15-AI30 -> 621.64542 | AJ32: =AJ15-AJ30 -> 656.9001 | AK32: =SUM(AG32:AJ32) -> 2373.4956 | AL32: =AL15-AL30 -> 702.73243 | AM32: =AM15-AM30 -> 738.0325 | AN32: =AN15-AN30 -> 801.25098 | AO32: =AO15-AO30 -> 839.53967 | AP32: =SUM(AL32:AO32) -> 3081.5556
B33: =B22 -> % yoy | AL33: =AL32/AG32-1 -> 0.33811975 | AM33: =AM32/AH32-1 -> 0.29528014 | AN33: =AN32/AI32-1 -> 0.28891962 | AO33: =AO32/AJ32-1 -> 0.27803249 | AP33: =AP32/AK32-1 -> 0.29831948
B34: =B23 -> % qoq | AH34: =AH32/AG32-1 -> 0.084967597 | AI34: =AI32/AH32-1 -> 0.09101559 | AJ34: =AJ32/AI32-1 -> 0.056711879 | AL34: =AL32/AJ32-1 -> 0.069770624 | AM34: =AM32/AL32-1 -> 0.05023259 | AN34: =AN32/AM32-1 -> 0.085658125 | AO34: =AO32/AN32-1 -> 0.047786138
B35: Compute Revenue vs. Product Revenue Growth | AP35: =AP33-AP17 -> 0
B37: Snowpark Revenue | AG37: 3.5 | AH37: 6.5 | AI37: 11 | AJ37: 14 | AK37: 35 | AL37: 18 | AM37: 23 | AN37: 27 | AO37: 31 | AP37: 100
B38: % yoy | AL38: =AL37/AG37-1 -> 4.1428571 | AM38: =AM37/AH37-1 -> 2.5384615 | AN38: =AN37/AI37-1 -> 1.4545455 | AO38: =AO37/AJ37-1 -> 1.2142857 | AP38: =AP37/AK37-1 -> 1.8571429
B39: % qoq | AH39: =AH37/AG37-1 -> 0.85714286 | AI39: =AI37/AH37-1 -> 0.69230769 | AJ39: =AJ37/AI37-1 -> 0.27272727 | AL39: =AL37/AJ37-1 -> 0.28571429 | AM39: =AM37/AL37-1 -> 0.27777778 | AN39: =AN37/AM37-1 -> 0.17391304 | AO39: =AO37/AN37-1 -> 0.14814815
B40: % Revenue | AG40: =AG37/AG15 -> 0.0059314795 | AH40: =AH37/AH15 -> 0.010152934 | AI40: =AI37/AI15 -> 0.015748528 | AJ40: =AJ37/AJ15 -> 0.018967877 | AK40: =AK37/AK15 -> 0.013124103 | AL40: =AL37/AL15 -> 0.022796728 | AM40: =AM37/AM15 -> 0.027735906 | AN40: =AN37/AN15 -> 0.029990603 | ... AP40: =AP37/AP15 -> 0.028881517
B41: Growth ex. Snowpark | AL41: =(AL15-AL37)/(AG15-AG37)-1 -> 0.31541737 | AM41: =(AM15-AM37)/(AH15-AH37)-1 -> 0.27227166 | AN41: =(AN15-AN37)/(AI15-AI37)-1 -> 0.27026901 | AO41: =(AO15-AO37)/(AJ15-AJ37)-1 -> 0.2599304 | AP41: =(AP15-AP37)/(AK15-AK37)-1 -> 0.27758925
B43: Data Engineering | AN43: 200
B45: AI Revenue (Run-rate) | AS45: 100
B47: AI/ML Weekly Users | AM47: 2500 | AN47: 3200 | AO47: 4000 | AQ47: 5200 | AR47: 6100 | AS47: 7300
B48: % qoq | AN48: =AN47/AM47-1 -> 0.28 | AO48: =AO47/AN47-1 -> 0.25 | AQ48: =AQ47/AO47-1 -> 0.3 | AR48: =AR47/AQ47-1 -> 0.17307692 | AS48: =AS47/AR47-1 -> 0.19672131
B49: Net Adds | AN49: =AN47-AM47 -> 700 | AO49: =AO47-AN47 -> 800 | AQ49: =AQ47-AO47 -> 1200 | AR49: =AR47-AQ47 -> 900 | AS49: =AS47-AR47 -> 1200
A51: SERVREV | B51: Professional services revenue | H51: ='IS (Non-GAAP)'!H19 -> 0.217 | I51: ='IS (Non-GAAP)'!I19 -> 0.23 | J51: ='IS (Non-GAAP)'!J19 -> 0.223 | K51: ='IS (Non-GAAP)'!K19 -> 0.313 | L51: =SUM(H51:K51) -> 0.983 | M51: ='IS (Non-GAAP)'!M19 -> 0.939 | N51: ='IS (Non-GAAP)'!N19 -> 2.521 | O51: ='IS (Non-GAAP)'!O19 -> 3.799 | P51: ='IS (Non-GAAP)'!P19 -> 5.26 | Q51: =SUM(M51:P51) -> 12.519 | R51: ='IS (Non-GAAP)'!R19 -> 6.998 | S51: ='IS (Non-GAAP)'!S19 -> 7.929 | T51: ='IS (Non-GAAP)'!T19 -> 11.151 | U51: ='IS (Non-GAAP)'!U19 -> 12.177 | V51: =SUM(R51:U51) -> 38.255 | W51: ='IS (Non-GAAP)'!W19 -> 15.084 | X51: ='IS (Non-GAAP)'!X19 -> 17.575 | Y51: ='IS (Non-GAAP)'!Y19 -> 21.983 | Z51: ='IS (Non-GAAP)'!Z19 -> 24.216 | AA51: =SUM(W51:Z51) -> 78.858 | AB51: ='IS (Non-GAAP)'!AB19 -> 27.937 | AC51: ='IS (Non-GAAP)'!AC19 -> 30.98 | AD51: ='IS (Non-GAAP)'!AD19 -> 34.276 | AE51: ='IS (Non-GAAP)'!AE19 -> 33.683 | AF51: =SUM(AB51:AE51) -> 126.876 | AG51: ='IS (Non-GAAP)'!AG19 -> 33.527 | AH51: ='IS (Non-GAAP)'!AH19 -> 33.809 | AI51: ='IS (Non-GAAP)'!AI19 -> 35.695 | AJ51: ='IS (Non-GAAP)'!AJ19 -> 36.609 | AK51: =SUM(AG51:AJ51) -> 139.64 | AL51: ='IS (Non-GAAP)'!AL19 -> 39.122 | AM51: ='IS (Non-GAAP)'!AM19 -> 39.573 | AN51: ='IS (Non-GAAP)'!AN19 -> 41.812 | AO51: ='IS (Non-GAAP)'!AO19 -> 43.467 | AP51: =SUM(AL51:AO51) -> 163.974 | AQ51: ='IS (Non-GAAP)'!AQ19 -> 45.261 | AR51: ='IS (Non-GAAP)'!AR19 -> 54.473 | AS51: ='IS (Non-GAAP)'!AS19 -> 54.532 | AT51: =AO51*(1+AT52) -> 49.98705 | AU51: =SUM(AQ51:AT51) -> 204.25305 | AV51: =AQ51*(1+AV52) -> 51.371235 | AW51: =AR51*(1+AW52) -> 61.826855 | AX51: =AS51*(1+AX52) -> 61.89382 | AY51: =AT51*(1+AY52) -> 56.735302 | AZ51: =SUM(AV51:AY51) -> 231.82721 | BA51: =AV51*(1+BA52) -> 58.049496 | BB51: =AW51*(1+BB52) -> 69.864346 | BC51: =AX51*(1+BC52) -> 69.940017 | BD51: =AY51*(1+BD52) -> 64.110891 | BE51: =SUM(BA51:BD51) -> 261.96475 | BF51: =BA51*(1+BF52) -> 65.305682 | BG51: =BB51*(1+BG52) -> 78.597389 | BH51: =BC51*(1+BH52) -> 78.682519 | BI51: =BD51*(1+BI52) -> 72.124752 | BJ51: =SUM(BF51:BI51) -> 294.71034 | BK51: =BF51*(1+BK52) -> 73.468893 | BL51: =BG51*(1+BL52) -> 88.422063 | BM51: =BH51*(1+BM52) -> 88.517834 | BN51: =BI51*(1+BN52) -> 81.140346 | BO51: =SUM(BK51:BN51) -> 331.54914
A52: SERVREVYY | B52: % yoy | H52: =IFERROR(H51/C51-1,"--") -> -- | I52: =IFERROR(I51/D51-1,"--") -> -- | J52: =IFERROR(J51/E51-1,"--") -> -- | K52: =IFERROR(K51/F51-1,"--") -> -- | L52: =IFERROR(L51/G51-1,"--") -> -- | M52: =IFERROR(M51/H51-1,"--") -> 3.3271889 | N52: =IFERROR(N51/I51-1,"--") -> 9.9608696 | O52: =IFERROR(O51/J51-1,"--") -> 16.035874 | ... AS52: =IFERROR(AS51/AN51-1,"--") -> 0.30421888 | AT52: 0.15 | AU52: =IFERROR(AU51/AP51-1,"--") -> 0.24564291 | AV52: 0.135 | AW52: =AV52 -> 0.135 | AX52: =AW52 -> 0.135 | AY52: =AX52 -> 0.135 | AZ52: =IFERROR(AZ51/AU51-1,"--") -> 0.135 | BA52: 0.13 | BB52: =BA52 -> 0.13 | BC52: =BB52 -> 0.13 | BD52: =BC52 -> 0.13 | BE52: =IFERROR(BE51/AZ51-1,"--") -> 0.13 | BF52: 0.125 | BG52: =BF52 -> 0.125 | BH52: =BG52 -> 0.125 | BI52: =BH52 -> 0.125 | BJ52: =IFERROR(BJ51/BE51-1,"--") -> 0.125 | BK52: 0.125 | BL52: =BK52 -> 0.125 | BM52: =BL52 -> 0.125 | BN52: =BM52 -> 0.125 | BO52: =IFERROR(BO51/BJ51-1,"--") -> 0.125
...

Sheet IS (GAAP)
B2: Snowflake Inc.
B3: Fiscal Year Ends Jan. 31
B4: ($ millions, except per share amounts)
C6: =Dates!M3 -> 2018 (A) | H6: =Dates!R3 -> 2019 (A) | M6: =Dates!W3 -> 2020 (A) | R6: =Dates!AB3 -> 2021 (A) | W6: =Dates!AG3 -> 2022 (A) | AB6: =Dates!AL3 -> 2023 (A) | AG6: =Dates!AQ3 -> 2024 (A) | AL6: =Dates!AV3 -> 2025 (A) | AQ6: =Dates!BA3 -> 2026 (E) | AV6: =Dates!BF3 -> 2027 (E) | BA6: =Dates!BK3 -> 2028 (E) | BF6: =Dates!BP3 -> 2029 (E) | BK6: =Dates!BU3 -> 2030 (E)
C7: =Dates!M4 -> 1Q18 (A) | D7: =Dates!N4 -> 2Q18 (A) | E7: =Dates!O4 -> 3Q18 (A) | F7: =Dates!P4 -> 4Q18 (A) | G7: =Dates!Q4 -> FY18 (A) | H7: =Dates!R4 -> 1Q19 (A) | I7: =Dates!S4 -> 2Q19 (A) | J7: =Dates!T4 -> 3Q19 (A) | ... BO7: =Dates!BY4 -> FY30 (E)
C8: =Dates!M5 -> 42855 | D8: =Dates!N5 -> 42947 | E8: =Dates!O5 -> 43039 | F8: =Dates!P5 -> 43131 | G8: =Dates!Q5 -> 43131 | H8: =Dates!R5 -> 43220 | I8: =Dates!S5 -> 43312 | J8: =Dates!T5 -> 43404 | ... BO8: =Dates!BY5 -> 47514
B10: Total Revenue | C10: =SUM(C14,C19) -> 0 | D10: =SUM(D14,D19) -> 0 | E10: =SUM(E14,E19) -> 0 | F10: =SUM(F14,F19) -> 0 | G10: =SUM(C10:F10) -> 0 | H10: =SUM(H14,H19) -> 13.403 | I10: =SUM(I14,I19) -> 17.905 | J10: =SUM(J14,J19) -> 28.68 | K10: =SUM(K14,K19) -> 36.678 | L10: =SUM(H10:K10) -> 96.666 | M10: =SUM(M14,M19) -> 43.705 | N10: =SUM(N14,N19) -> 60.339 | O10: =SUM(O14,O19) -> 73.012 | P10: =SUM(P14,P19) -> 87.692 | Q10: =SUM(M10:P10) -> 264.748 | R10: =SUM(R14,R19) -> 108.815 | S10: =SUM(S14,S19) -> 133.145 | T10: =SUM(T14,T19) -> 159.624 | U10: =SUM(U14,U19) -> 190.465 | V10: =SUM(R10:U10) -> 592.049 | W10: =SUM(W14,W19) -> 228.914 | X10: =SUM(X14,X19) -> 272.198 | Y10: =SUM(Y14,Y19) -> 334.441 | Z10: =SUM(Z14,Z19) -> 383.774 | AA10: =SUM(W10:Z10) -> 1219.327 | AB10: =SUM(AB14,AB19) -> 422.371 | AC10: =SUM(AC14,AC19) -> 497.248 | AD10: =SUM(AD14,AD19) -> 557.028 | AE10: =SUM(AE14,AE19) -> 589.012 | AF10: =SUM(AB10:AE10) -> 2065.659 | AG10: =SUM(AG14,AG19) -> 623.599 | AH10: =SUM(AH14,AH19) -> 674.018 | AI10: =SUM(AI14,AI19) -> 734.173 | AJ10: =SUM(AJ14,AJ19) -> 774.699 | AK10: =SUM(AG10:AJ10) -> 2806.489 | AL10: =SUM(AL14,AL19) -> 828.709 | AM10: =SUM(AM14,AM19) -> 868.823 | AN10: =SUM(AN14,AN19) -> 942.094 | AO10: =SUM(AO14,AO19) -> 986.77 | AP10: =SUM(AL10:AO10) -> 3626.396 | AQ10: =SUM(AQ14,AQ19) -> 1042.074 | AR10: =SUM(AR14,AR19) -> 1144.969 | AS10: =SUM(AS14,AS19) -> 1212.909 | AT10: =SUM(AT14,AT19) -> 1248.8031 | AU10: =SUM(AQ10:AT10) -> 4648.7551 | AV10: =SUM(AV14,AV19) -> 1313.011 | AW10: =SUM(AW14,AW19) -> 1415.0354 | AX10: =SUM(AX14,AX19) -> 1502.3143 | AY10: =SUM(AY14,AY19) -> 1549.2272 | AZ10: =SUM(AV10:AY10) -> 5779.5879 | BA10: =SUM(BA14,BA19) -> 1629.2553 | BB10: =SUM(BB14,BB19) -> 1760.8179 | BC10: =SUM(BC14,BC19) -> 1874.5414 | BD10: =SUM(BD14,BD19) -> 1913.7314 | BE10: =SUM(BA10:BD10) -> 7178.346 | BF10: =SUM(BF14,BF19) -> 1996.5102 | BG10: =SUM(BG14,BG19) -> 2152.728 | BH10: =SUM(BH14,BH19) -> 2332.7606 | BI10: =SUM(BI14,BI19) -> 2391.9909 | BJ10: =SUM(BF10:BI10) -> 8873.9896 | BK10: =SUM(BK14,BK19) -> 2482.3192 | BL10: =SUM(BL14,BL19) -> 2642.7389 | BM10: =SUM(BM14,BM19) -> 2883.1165 | BN10: =SUM(BN14,BN19) -> 2925.8128 | BO10: =SUM(BK10:BN10) -> 10933.987
B11: % yoy | C11: -- | D11: -- | E11: -- | F11: -- | G11: -- | H11: =IFERROR(H10/C10-1,"--") -> -- | I11: =IFERROR(I10/D10-1,"--") -> -- | J11: =IFERROR(J10/E10-1,"--") -> -- | K11: =IFERROR(K10/F10-1,"--") -> -- | L11: =IFERROR(L10/G10-1,"--") -> -- | M11: =IFERROR(M10/H10-1,"--") -> 2.2608371 | N11: =IFERROR(N10/I10-1,"--") -> 2.3699525 | O11: =IFERROR(O10/J10-1,"--") -> 1.5457462 | ... BO11: =IFERROR(BO10/BJ10-1,"--") -> 0.23213886
B12: % qoq | C12: -- | D12: =IFERROR(D10/C10-1,"--") -> -- | E12: =IFERROR(E10/D10-1,"--") -> -- | F12: =IFERROR(F10/E10-1,"--") -> -- | H12: =IFERROR(H10/F10-1,"--") -> -- | I12: =IFERROR(I10/H10-1,"--") -> 0.33589495 | J12: =IFERROR(J10/I10-1,"--") -> 0.60178721 | K12: =IFERROR(K10/J10-1,"--") -> 0.27887029 | M12: =IFERROR(M10/K10-1,"--") -> 0.19158624 | N12: =IFERROR(N10/M10-1,"--") -> 0.38059719 | O12: =IFERROR(O10/N10-1,"--") -> 0.21003 | P12: =IFERROR(P10/O10-1,"--") -> 0.20106284 | R12: =IFERROR(R10/P10-1,"--") -> 0.24087716 | S12: =IFERROR(S10/R10-1,"--") -> 0.2235905 | T12: =IFERROR(T10/S10-1,"--") -> 0.19887341 | U12: =IFERROR(U10/T10-1,"--") -> 0.19321029 | W12: =IFERROR(W10/U10-1,"--") -> 0.20186911 | X12: =IFERROR(X10/W10-1,"--") -> 0.18908411 | Y12: =IFERROR(Y10/X10-1,"--") -> 0.2286681 | Z12: =IFERROR(Z10/Y10-1,"--") -> 0.14750883 | AB12: =IFERROR(AB10/Z10-1,"--") -> 0.10057221 | AC12: =IFERROR(AC10/AB10-1,"--") -> 0.1772778 | AD12: =IFERROR(AD10/AC10-1,"--") -> 0.1202217 | AE12: =IFERROR(AE10/AD10-1,"--") -> 0.057419017 | AG12: =IFERROR(AG10/AE10-1,"--") -> 0.058720366 | AH12: =IFERROR(AH10/AG10-1,"--") -> 0.080851637 | AI12: =IFERROR(AI10/AH10-1,"--") -> 0.089248358 | AJ12: =IFERROR(AJ10/AI10-1,"--") -> 0.055199524 | AL12: =IFERROR(AL10/AJ10-1,"--") -> 0.0697174 | AM12: =IFERROR(AM10/AL10-1,"--") -> 0.048405411 | AN12: =IFERROR(AN10/AM10-1,"--") -> 0.084333633 | AO12: =IFERROR(AO10/AN10-1,"--") -> 0.047422019 | AQ12: =IFERROR(AQ10/AO10-1,"--") -> 0.056045482 | AR12: =IFERROR(AR10/AQ10-1,"--") -> 0.098740588 | AS12: =IFERROR(AS10/AR10-1,"--") -> 0.059337851 | AT12: =IFERROR(AT10/AS10-1,"--") -> 0.029593363 | AV12: =IFERROR(AV10/AT10-1,"--") -> 0.051415566 | AW12: =IFERROR(AW10/AV10-1,"--") -> 0.077702662 | AX12: =IFERROR(AX10/AW10-1,"--") -> 0.061679661 | AY12: =IFERROR(AY10/AX10-1,"--") -> 0.031227037 | BA12: =IFERROR(BA10/AY10-1,"--") -> 0.051656838 | BB12: =IFERROR(BB10/BA10-1,"--") -> 0.080750139 | BC12: =IFERROR(BC10/BB10-1,"--") -> 0.06458557 | BD12: =IFERROR(BD10/BC10-1,"--") -> 0.020906453 | BF12: =IFERROR(BF10/BD10-1,"--") -> 0.043255196 | BG12: =IFERROR(BG10/BF10-1,"--") -> 0.078245432 | BH12: =IFERROR(BH10/BG10-1,"--") -> 0.08362997 | BI12: =IFERROR(BI10/BH10-1,"--") -> 0.025390643 | BK12: =IFERROR(BK10/BI10-1,"--") -> 0.037762815 | BL12: =IFERROR(BL10/BK10-1,"--") -> 0.064624957 | BM12: =IFERROR(BM10/BL10-1,"--") -> 0.090957753 | BN12: =IFERROR(BN10/BM10-1,"--") -> 0.014809061
A14: TREV | B14: Product Revenue | G14: =SUM(C14:F14) -> 0 | H14: 13.186 | I14: 17.675 | J14: 28.457 | K14: 36.365 | L14: =SUM(H14:K14) -> 95.683 | M14: 42.766 | N14: 57.818 | O14: 69.213 | P14: 82.432 | Q14: =SUM(M14:P14) -> 252.229 | R14: 101.817 | S14: 125.216 | T14: 148.473 | U14: 178.288 | V14: =SUM(R14:U14) -> 553.794 | W14: 213.83 | X14: 254.623 | Y14: 312.458 | Z14: 359.558 | AA14: =SUM(W14:Z14) -> 1140.469 | AB14: 394.434 | AC14: 466.268 | AD14: 522.752 | AE14: 555.329 | AF14: =SUM(AB14:AE14) -> 1938.783 | AG14: 590.072 | AH14: 640.209 | AI14: 698.478 | AJ14: 738.09 | AK14: =SUM(AG14:AJ14) -> 2666.849 | AL14: 789.587 | AM14: 829.25 | AN14: 900.282 | AO14: 943.303 | AP14: =SUM(AL14:AO14) -> 3462.422 | AQ14: 996.813 | AR14: 1090.496 | AS14: 1158.377 | AT14: ='Revenue Build'!AT15 -> 1198.816 | AU14: =SUM(AQ14:AT14) -> 4444.502 | AV14: ='Revenue Build'!AV15 -> 1261.6397 | AW14: ='Revenue Build'!AW15 -> 1353.2086 | AX14: ='Revenue Build'!AX15 -> 1440.4205 | AY14: ='Revenue Build'!AY15 -> 1492.4918 | AZ14: =SUM(AV14:AY14) -> 5547.7607 | BA14: ='Revenue Build'!BA15 -> 1571.2058 | BB14: ='Revenue Build'!BB15 -> 1690.9536 | BC14: ='Revenue Build'!BC15 -> 1804.6013 | BD14: ='Revenue Build'!BD15 -> 1849.6205 | BE14: =SUM(BA14:BD14) -> 6916.3812 | BF14: ='Revenue Build'!BF15 -> 1931.2045 | BG14: ='Revenue Build'!BG15 -> 2074.1306 | BH14: ='Revenue Build'!BH15 -> 2254.078 | BI14: ='Revenue Build'!BI15 -> 2319.8661 | BJ14: =SUM(BF14:BI14) -> 8579.2792 | BK14: ='Revenue Build'!BK15 -> 2408.8503 | BL14: ='Revenue Build'!BL15 -> 2554.3169 | BM14: ='Revenue Build'!BM15 -> 2794.5987 | BN14: ='Revenue Build'!BN15 -> 2844.6724 | BO14: =SUM(BK14:BN14) -> 10602.438
A15: TREVYY | B15: % yoy | C15: -- | D15: -- | E15: -- | F15: -- | G15: -- | H15: =IFERROR(H14/C14-1,"--") -> -- | I15: =IFERROR(I14/D14-1,"--") -> -- | J15: =IFERROR(J14/E14-1,"--") -> -- | K15: =IFERROR(K14/F14-1,"--") -> -- | L15: =IFERROR(L14/G14-1,"--") -> -- | M15: =IFERROR(M14/H14-1,"--") -> 2.2432883 | N15: =IFERROR(N14/I14-1,"--") -> 2.271174 | O15: =IFERROR(O14/J14-1,"--") -> 1.4321959 | ... BO15: =IFERROR(BO14/BJ14-1,"--") -> 0.23581923
A16: TREVQQ | B16: % qoq | C16: -- | D16: =IFERROR(D14/C14-1,"--") -> -- | E16: =IFERROR(E14/D14-1,"--") -> -- | F16: =IFERROR(F14/E14-1,"--") -> -- | H16: =IFERROR(H14/F14-1,"--") -> -- | I16: =IFERROR(I14/H14-1,"--") -> 0.34043683 | J16: =IFERROR(J14/I14-1,"--") -> 0.61001414 | K16: =IFERROR(K14/J14-1,"--") -> 0.27789296 | M16: =IFERROR(M14/K14-1,"--") -> 0.1760209 | N16: =IFERROR(N14/M14-1,"--") -> 0.35196184 | O16: =IFERROR(O14/N14-1,"--") -> 0.19708395 | P16: =IFERROR(P14/O14-1,"--") -> 0.19099013 | R16: =IFERROR(R14/P14-1,"--") -> 0.23516353 | S16: =IFERROR(S14/R14-1,"--") -> 0.22981427 | T16: =IFERROR(T14/S14-1,"--") -> 0.18573505 | U16: =IFERROR(U14/T14-1,"--") -> 0.20081092 | W16: =IFERROR(W14/U14-1,"--") -> 0.19935161 | X16: =IFERROR(X14/W14-1,"--") -> 0.19077304 | Y16: =IFERROR(Y14/X14-1,"--") -> 0.22713973 | Z16: =IFERROR(Z14/Y14-1,"--") -> 0.15074026 | AB16: =IFERROR(AB14/Z14-1,"--") -> 0.096996868 | AC16: =IFERROR(AC14/AB14-1,"--") -> 0.18211919 | AD16: =IFERROR(AD14/AC14-1,"--") -> 0.12114063 | AE16: =IFERROR(AE14/AD14-1,"--") -> 0.062318269 | AG16: =IFERROR(AG14/AE14-1,"--") -> 0.062562913 | AH16: =IFERROR(AH14/AG14-1,"--") -> 0.084967597 | AI16: =IFERROR(AI14/AH14-1,"--") -> 0.09101559 | AJ16: =IFERROR(AJ14/AI14-1,"--") -> 0.056711879 | AL16: =IFERROR(AL14/AJ14-1,"--") -> 0.069770624 | AM16: =IFERROR(AM14/AL14-1,"--") -> 0.05023259 | AN16: =IFERROR(AN14/AM14-1,"--") -> 0.085658125 | AO16: =IFERROR(AO14/AN14-1,"--") -> 0.047786138 | AQ16: =IFERROR(AQ14/AO14-1,"--") -> 0.056726206 | AR16: =IFERROR(AR14/AQ14-1,"--") -> 0.093982522 | AS16: =IFERROR(AS14/AR14-1,"--") -> 0.062247821 | AT16: =IFERROR(AT14/AS14-1,"--") -> 0.034910056 | AV16: =IFERROR(AV14/AT14-1,"--") -> 0.052404815 | AW16: =IFERROR(AW14/AV14-1,"--") -> 0.07257922 | AX16: =IFERROR(AX14/AW14-1,"--") -> 0.064448262 | AY16: =IFERROR(AY14/AX14-1,"--") -> 0.036150099 | BA16: =IFERROR(BA14/AY14-1,"--") -> 0.052739975 | BB16: =IFERROR(BB14/BA14-1,"--") -> 0.076213912 | BC16: =IFERROR(BC14/BB14-1,"--") -> 0.067209272 | BD16: =IFERROR(BD14/BC14-1,"--") -> 0.024946859 | BF16: =IFERROR(BF14/BD14-1,"--") -> 0.044108526 | BG16: =IFERROR(BG14/BF14-1,"--") -> 0.074008783 | BH16: =IFERROR(BH14/BG14-1,"--") -> 0.086758012 | BI16: =IFERROR(BI14/BH14-1,"--") -> 0.029186237 | BK16: =IFERROR(BK14/BI14-1,"--") -> 0.038357458 | BL16: =IFERROR(BL14/BK14-1,"--") -> 0.060388394 | BM16: =IFERROR(BM14/BL14-1,"--") -> 0.094068918 | BN16: =IFERROR(BN14/BM14-1,"--") -> 0.017918041
B17: % total revenue | C17: =IFERROR(C14/C$10,"--") -> -- | D17: =IFERROR(D14/D$10,"--") -> -- | E17: =IFERROR(E14/E$10,"--") -> -- | F17: =IFERROR(F14/F$10,"--") -> -- | G17: =IFERROR(G14/G$10,"--") -> -- | H17: =IFERROR(H14/H$10,"--") -> 0.98380959 | I17: =IFERROR(I14/I$10,"--") -> 0.98715443 | J17: =IFERROR(J14/J$10,"--") -> 0.99222455 | ... BO17: =IFERROR(BO14/BO$10,"--") -> 0.9696772
A19: TREV | B19: Professional Services & Other Revenue | G19: =SUM(C19:F19) -> 0 | H19: 0.217 | I19: 0.23 | J19: 0.223 | K19: 0.313 | L19: =SUM(H19:K19) -> 0.983 | M19: 0.939 | N19: 2.521 | O19: 3.799 | P19: 5.26 | Q19: =SUM(M19:P19) -> 12.519 | R19: 6.998 | S19: 7.929 | T19: 11.151 | U19: 12.177 | V19: =SUM(R19:U19) -> 38.255 | W19: 15.084 | X19: 17.575 | Y19: 21.983 | Z19: 24.216 | AA19: =SUM(W19:Z19) -> 78.858 | AB19: 27.937 | AC19: 30.98 | AD19: 34.276 | AE19: 33.683 | AF19: =SUM(AB19:AE19) -> 126.876 | AG19: 33.527 | AH19: 33.809 | AI19: 35.695 | AJ19: 36.609 | AK19: =SUM(AG19:AJ19) -> 139.64 | AL19: 39.122 | AM19: 39.573 | AN19: 41.812 | AO19: 43.467 | AP19: =SUM(AL19:AO19) -> 163.974 | AQ19: 45.261 | AR19: 54.473 | AS19: 54.532 | AT19: ='Revenue Build'!AT51 -> 49.98705 | AU19: =SUM(AQ19:AT19) -> 204.25305 | AV19: ='Revenue Build'!AV51 -> 51.371235 | AW19: ='Revenue Build'!AW51 -> 61.826855 | AX19: ='Revenue Build'!AX51 -> 61.89382 | AY19: ='Revenue Build'!AY51 -> 56.735302 | AZ19: =SUM(AV19:AY19) -> 231.82721 | BA19: ='Revenue Build'!BA51 -> 58.049496 | BB19: ='Revenue Build'!BB51 -> 69.864346 | BC19: ='Revenue Build'!BC51 -> 69.940017 | BD19: ='Revenue Build'!BD51 -> 64.110891 | BE19: =SUM(BA19:BD19) -> 261.96475 | BF19: ='Revenue Build'!BF51 -> 65.305682 | BG19: ='Revenue Build'!BG51 -> 78.597389 | BH19: ='Revenue Build'!BH51 -> 78.682519 | BI19: ='Revenue Build'!BI51 -> 72.124752 | BJ19: =SUM(BF19:BI19) -> 294.71034 | BK19: ='Revenue Build'!BK51 -> 73.468893 | BL19: ='Revenue Build'!BL51 -> 88.422063 | BM19: ='Revenue Build'!BM51 -> 88.517834 | BN19: ='Revenue Build'!BN51 -> 81.140346 | BO19: =SUM(BK19:BN19) -> 331.54914
A20: TREVYY | B20: % yoy | C20: -- | D20: -- | E20: -- | F20: -- | G20: -- | H20: =IFERROR(H19/C19-1,"--") -> -- | I20: =IFERROR(I19/D19-1,"--") -> -- | J20: =IFERROR(J19/E19-1,"--") -> -- | K20: =IFERROR(K19/F19-1,"--") -> -- | L20: =IFERROR(L19/G19-1,"--") -> -- | M20: =IFERROR(M19/H19-1,"--") -> 3.3271889 | N20: =IFERROR(N19/I19-1,"--") -> 9.9608696 | O20: =IFERROR(O19/J19-1,"--") -> 16.035874 | ... BO20: =IFERROR(BO19/BJ19-1,"--") -> 0.125
A21: TREVQQ | B21: % qoq | C21: -- | D21: =IFERROR(D19/C19-1,"--") -> -- | E21: =IFERROR(E19/D19-1,"--") -> -- | F21: =IFERROR(F19/E19-1,"--") -> -- | H21: =IFERROR(H19/F19-1,"--") -> -- | I21: =IFERROR(I19/H19-1,"--") -> 0.059907834 | J21: =IFERROR(J19/I19-1,"--") -> -0.030434783 | K21: =IFERROR(K19/J19-1,"--") -> 0.40358744 | M21: =IFERROR(M19/K19-1,"--") -> 2 | N21: =IFERROR(N19/M19-1,"--") -> 1.684771 | O21: =IFERROR(O19/N19-1,"--") -> 0.50694169 | P21: =IFERROR(P19/O19-1,"--") -> 0.38457489 | R21: =IFERROR(R19/P19-1,"--") -> 0.33041825 | S21: =IFERROR(S19/R19-1,"--") -> 0.13303801 | T21: =IFERROR(T19/S19-1,"--") -> 0.40635641 | U21: =IFERROR(U19/T19-1,"--") -> 0.092009685 | W21: =IFERROR(W19/U19-1,"--") -> 0.23872875 | X21: =IFERROR(X19/W19-1,"--") -> 0.16514187 | Y21: =IFERROR(Y19/X19-1,"--") -> 0.25081081 | Z21: =IFERROR(Z19/Y19-1,"--") -> 0.10157849 | AB21: =IFERROR(AB19/Z19-1,"--") -> 0.15365874 | AC21: =IFERROR(AC19/AB19-1,"--") -> 0.10892365 | AD21: =IFERROR(AD19/AC19-1,"--") -> 0.10639122 | AE21: =IFERROR(AE19/AD19-1,"--") -> -0.017300735 | AG21: =IFERROR(AG19/AE19-1,"--") -> -0.0046314164 | AH21: =IFERROR(AH19/AG19-1,"--") -> 0.0084111313 | AI21: =IFERROR(AI19/AH19-1,"--") -> 0.055783963 | AJ21: =IFERROR(AJ19/AI19-1,"--") -> 0.025605827 | AL21: =IFERROR(AL19/AJ19-1,"--") -> 0.068644322 | AM21: =IFERROR(AM19/AL19-1,"--") -> 0.01152804 | AN21: =IFERROR(AN19/AM19-1,"--") -> 0.056578981 | AO21: =IFERROR(AO19/AN19-1,"--") -> 0.039581938 | AQ21: =IFERROR(AQ19/AO19-1,"--") -> 0.04127269 | AR21: =IFERROR(AR19/AQ19-1,"--") -> 0.20353063 | AS21: =IFERROR(AS19/AR19-1,"--") -> 0.0010831054 | AT21: =IFERROR(AT19/AS19-1,"--") -> -0.083344642 | AV21: =IFERROR(AV19/AT19-1,"--") -> 0.027690872 | AW21: =IFERROR(AW19/AV19-1,"--") -> 0.20353063 | AX21: =IFERROR(AX19/AW19-1,"--") -> 0.0010831054 | AY21: =IFERROR(AY19/AX19-1,"--") -> -0.083344642 | BA21: =IFERROR(BA19/AY19-1,"--") -> 0.023163599 | BB21: =IFERROR(BB19/BA19-1,"--") -> 0.20353063 | BC21: =IFERROR(BC19/BB19-1,"--") -> 0.0010831054 | BD21: =IFERROR(BD19/BC19-1,"--") -> -0.083344642 | BF21: =IFERROR(BF19/BD19-1,"--") -> 0.018636327 | BG21: =IFERROR(BG19/BF19-1,"--") -> 0.20353063 | BH21: =IFERROR(BH19/BG19-1,"--") -> 0.0010831054 | BI21: =IFERROR(BI19/BH19-1,"--") -> -0.083344642 | BK21: =IFERROR(BK19/BI19-1,"--") -> 0.018636327 | BL21: =IFERROR(BL19/BK19-1,"--") -> 0.20353063 | BM21: =IFERROR(BM19/BL19-1,"--") -> 0.0010831054 | BN21: =IFERROR(BN19/BM19-1,"--") -> -0.083344642
B22: % total revenue | C22: =IFERROR(C19/C$10,"--") -> -- | D22: =IFERROR(D19/D$10,"--") -> -- | E22: =IFERROR(E19/E$10,"--") -> -- | F22: =IFERROR(F19/F$10,"--") -> -- | G22: =IFERROR(G19/G$10,"--") -> -- | H22: =IFERROR(H19/H$10,"--") -> 0.016190405 | I22: =IFERROR(I19/I$10,"--") -> 0.012845574 | J22: =IFERROR(J19/J$10,"--") -> 0.0077754533 | ... BO22: =IFERROR(BO19/BO$10,"--") -> 0.030322802
B24: Total Cost of Revenue | C24: =SUM(C28,C33) -> 0 | D24: =SUM(D28,D33) -> 0 | E24: =SUM(E28,E33) -> 0 | F24: =SUM(F28,F33) -> 0 | G24: =SUM(C24:F24) -> 0 | H24: =SUM(H28,H33) -> 7.439 | I24: =SUM(I28,I33) -> 9.735 | J24: =SUM(J28,J33) -> 13.824 | K24: =SUM(K28,K33) -> 20.389 | L24: =SUM(H24:K24) -> 51.387 | M24: =SUM(M28,M33) -> 24.038 | N24: =SUM(N28,N33) -> 28.508 | O24: =SUM(O28,O33) -> 29.489 | P24: =SUM(P28,P33) -> 34.522 | Q24: =SUM(M24:P24) -> 116.557 | R24: =SUM(R28,R33) -> 42.557 | S24: =SUM(S28,S33) -> 50.446 | T24: =SUM(T28,T33) -> 66.681 | U24: =SUM(U28,U33) -> 82.904 | V24: =SUM(R24:U24) -> 242.588 | W24: =SUM(W28,W33) -> 97.346 | X24: =SUM(X28,X33) -> 106.121 | Y24: =SUM(Y28,Y33) -> 120.786 | Z24: =SUM(Z28,Z33) -> 134.18 | AA24: =SUM(W24:Z24) -> 458.433 | AB24: =SUM(AB28,AB33) -> 147.93 | AC24: =SUM(AC28,AC33) -> 173.232 | AD24: =SUM(AD28,AD33) -> 190.721 | AE24: =SUM(AE28,AE33) -> 205.657 | AF24: =SUM(AB24:AE24) -> 717.54 | AG24: =SUM(AG28,AG33) -> 209.414 | AH24: =SUM(AH28,AH33) -> 218.392 | AI24: =SUM(AI28,AI33) -> 228.948 | AJ24: =SUM(AJ28,AJ33) -> 241.804 | AK24: =SUM(AG24:AJ24) -> 898.558 | AL24: =SUM(AL28,AL33) -> 272.517 | AM24: =SUM(AM28,AM33) -> 288.078 | AN24: =SUM(AN28,AN33) -> 320.894 | AO24: =SUM(AO28,AO33) -> 333.184 | AP24: =SUM(AL24:AO24) -> 1214.673 | AQ24: =SUM(AQ28,AQ33) -> 348.786 | AR24: =SUM(AR28,AR33) -> 371.815 | AS24: =SUM(AS28,AS33) -> 390.873 | AT24: =SUM(AT28,AT33) -> 419.05282 | AU24: =SUM(AQ24:AT24) -> 1530.5268 | AV24: =SUM(AV28,AV33) -> 411.60689 | AW24: =SUM(AW28,AW33) -> 433.85455 | AX24: =SUM(AX28,AX33) -> 462.03589 | AY24: =SUM(AY28,AY33) -> 496.11632 | AZ24: =SUM(AV24:AY24) -> 1803.6137 | BA24: =SUM(BA28,BA33) -> 482.35201 | BB24: =SUM(BB28,BB33) -> 509.02856 | BC24: =SUM(BC28,BC33) -> 544.31546 | BD24: =SUM(BD28,BD33) -> 581.43991 | BE24: =SUM(BA24:BD24) -> 2117.1359 | BF24: =SUM(BF28,BF33) -> 558.81374 | BG24: =SUM(BG28,BG33) -> 587.69456 | BH24: =SUM(BH28,BH33) -> 639.60199 | BI24: =SUM(BI28,BI33) -> 688.70756 | BJ24: =SUM(BF24:BI24) -> 2474.8179 | BK24: =SUM(BK28,BK33) -> 662.84769 | BL24: =SUM(BL28,BL33) -> 687.59166 | BM24: =SUM(BM28,BM33) -> 753.64391 | BN24: =SUM(BN28,BN33) -> 806.45184 | BO24: =SUM(BK24:BN24) -> 2910.5351
B25: % yoy | C25: -- | D25: -- | E25: -- | F25: -- | G25: =IFERROR(G24/B24-1,"--") -> -- | H25: =IFERROR(H24/C24-1,"--") -> -- | I25: =IFERROR(I24/D24-1,"--") -> -- | J25: =IFERROR(J24/E24-1,"--") -> -- | K25: =IFERROR(K24/F24-1,"--") -> -- | L25: =IFERROR(L24/G24-1,"--") -> -- | M25: =IFERROR(M24/H24-1,"--") -> 2.2313483 | N25: =IFERROR(N24/I24-1,"--") -> 1.9284027 | ... BO25: =IFERROR(BO24/BJ24-1,"--") -> 0.17606033
B26: % qoq | C26: -- | D26: =IFERROR(D24/C24-1,"--") -> -- | E26: =IFERROR(E24/D24-1,"--") -> -- | F26: =IFERROR(F24/E24-1,"--") -> -- | H26: =IFERROR(H24/F24-1,"--") -> -- | I26: =IFERROR(I24/H24-1,"--") -> 0.30864363 | J26: =IFERROR(J24/I24-1,"--") -> 0.42003082 | K26: =IFERROR(K24/J24-1,"--") -> 0.47489873 | M26: =IFERROR(M24/K24-1,"--") -> 0.17896905 | N26: =IFERROR(N24/M24-1,"--") -> 0.18595557 | O26: =IFERROR(O24/N24-1,"--") -> 0.034411393 | P26: =IFERROR(P24/O24-1,"--") -> 0.17067381 | R26: =IFERROR(R24/P24-1,"--") -> 0.23275013 | S26: =IFERROR(S24/R24-1,"--") -> 0.18537491 | T26: =IFERROR(T24/S24-1,"--") -> 0.32182928 | U26: =IFERROR(U24/T24-1,"--") -> 0.24329269 | W26: =IFERROR(W24/U24-1,"--") -> 0.17420149 | X26: =IFERROR(X24/W24-1,"--") -> 0.090142379 | Y26: =IFERROR(Y24/X24-1,"--") -> 0.13819131 | Z26: =IFERROR(Z24/Y24-1,"--") -> 0.11089033 | AB26: =IFERROR(AB24/Z24-1,"--") -> 0.10247429 | AC26: =IFERROR(AC24/AB24-1,"--") -> 0.17104036 | AD26: =IFERROR(AD24/AC24-1,"--") -> 0.1009571 | AE26: =IFERROR(AE24/AD24-1,"--") -> 0.078313348 | AG26: =IFERROR(AG24/AE24-1,"--") -> 0.018268282 | AH26: =IFERROR(AH24/AG24-1,"--") -> 0.042872014 | AI26: =IFERROR(AI24/AH24-1,"--") -> 0.048335104 | AJ26: =IFERROR(AJ24/AI24-1,"--") -> 0.056152489 | AL26: =IFERROR(AL24/AJ24-1,"--") -> 0.1270161 | AM26: =IFERROR(AM24/AL24-1,"--") -> 0.057101025 | AN26: =IFERROR(AN24/AM24-1,"--") -> 0.11391359 | AO26: =IFERROR(AO24/AN24-1,"--") -> 0.038299251 | AQ26: =IFERROR(AQ24/AO24-1,"--") -> 0.046826978 | AR26: =IFERROR(AR24/AQ24-1,"--") -> 0.066026159 | AS26: =IFERROR(AS24/AR24-1,"--") -> 0.051256673 | AT26: =IFERROR(AT24/AS24-1,"--") -> 0.072094569 | AV26: =IFERROR(AV24/AT24-1,"--") -> -0.017768473 | AW26: =IFERROR(AW24/AV24-1,"--") -> 0.054050746 | AX26: =IFERROR(AX24/AW24-1,"--") -> 0.064955733 | AY26: =IFERROR(AY24/AX24-1,"--") -> 0.073761419 | BA26: =IFERROR(BA24/AY24-1,"--") -> -0.027744105 | BB26: =IFERROR(BB24/BA24-1,"--") -> 0.055305149 | BC26: =IFERROR(BC24/BB24-1,"--") -> 0.069322036 | BD26: =IFERROR(BD24/BC24-1,"--") -> 0.068203928 | BF26: =IFERROR(BF24/BD24-1,"--") -> -0.038914021 | BG26: =IFERROR(BG24/BF24-1,"--") -> 0.051682356 | BH26: =IFERROR(BH24/BG24-1,"--") -> 0.088323839 | BI26: =IFERROR(BI24/BH24-1,"--") -> 0.076775186 | BK26: =IFERROR(BK24/BI24-1,"--") -> -0.037548395 | BL26: =IFERROR(BL24/BK24-1,"--") -> 0.037329799 | BM26: =IFERROR(BM24/BL24-1,"--") -> 0.096063179 | BN26: =IFERROR(BN24/BM24-1,"--") -> 0.070070142
A28: TREV | B28: Cost of Product Revenue | G28: =SUM(C28:F28) -> 0 | H28: 6.945 | I28: 8.211 | J28: 11.141 | K28: 15.101 | L28: =SUM(H28:K28) -> 41.398 | M28: 19.637 | N28: 23.562 | O28: 24.646 | P28: 28.777 | Q28: =SUM(M28:P28) -> 96.622 | R28: 35.533 | S28: 42.716 | T28: 51.816 | U28: 63.77 | V28: =SUM(R28:U28) -> 193.835 | W28: 72.08 | X28: 81.048 | Y28: 92.292 | Z28: 102.397 | AA28: =SUM(W28:Z28) -> 347.817 | AB28: 111.411 | AC28: 131.606 | AD28: 145.929 | AE28: 158.601 | AF28: =SUM(AB28:AE28) -> 547.547 | AG28: 159.378 | AH28: 169.046 | AI28: 180 | AJ28: 192.776 | AK28: =SUM(AG28:AJ28) -> 701.2 | AL28: 219.657 | AM28: 235.582 | AN28: 263.622 | AO28: 273.208 | AP28: =SUM(AL28:AO28) -> 992.069 | AQ28: 285.276 | AR28: 302.316 | AS28: 320.81 | AT28: ='IS (Non-GAAP)'!AT28+'IS (Non-GAAP)'!AT95+'IS (Non-GAAP)'!AT113 -> 354.63743 | AU28: =SUM(AQ28:AT28) -> 1263.0394 | AV28: ='IS (Non-GAAP)'!AV28+'IS (Non-GAAP)'!AV95+'IS (Non-GAAP)'!AV113 -> 346.90912 | AW28: ='IS (Non-GAAP)'!AW28+'IS (Non-GAAP)'!AW95+'IS (Non-GAAP)'!AW113 -> 359.36958 | AX28: ='IS (Non-GAAP)'!AX28+'IS (Non-GAAP)'!AX95+'IS (Non-GAAP)'!AX113 -> 388.16851 | AY28: ='IS (Non-GAAP)'!AY28+'IS (Non-GAAP)'!AY95+'IS (Non-GAAP)'!AY113 -> 428.4082 | AZ28: =SUM(AV28:AY28) -> 1522.8554 | BA28: ='IS (Non-GAAP)'!BA28+'IS (Non-GAAP)'!BA95+'IS (Non-GAAP)'!BA113 -> 414.87579 | BB28: ='IS (Non-GAAP)'!BB28+'IS (Non-GAAP)'!BB95+'IS (Non-GAAP)'!BB113 -> 431.01173 | BC28: ='IS (Non-GAAP)'!BC28+'IS (Non-GAAP)'!BC95+'IS (Non-GAAP)'!BC113 -> 467.48651 | BD28: ='IS (Non-GAAP)'!BD28+'IS (Non-GAAP)'!BD95+'IS (Non-GAAP)'!BD113 -> 512.00681 | BE28: =SUM(BA28:BD28) -> 1825.3808 | BF28: ='IS (Non-GAAP)'!BF28+'IS (Non-GAAP)'!BF95+'IS (Non-GAAP)'!BF113 -> 490.523 | BG28: ='IS (Non-GAAP)'!BG28+'IS (Non-GAAP)'!BG95+'IS (Non-GAAP)'!BG113 -> 508.28983 | BH28: ='IS (Non-GAAP)'!BH28+'IS (Non-GAAP)'!BH95+'IS (Non-GAAP)'!BH113 -> 562.19675 | BI28: ='IS (Non-GAAP)'!BI28+'IS (Non-GAAP)'!BI95+'IS (Non-GAAP)'!BI113 -> 620.03209 | BJ28: =SUM(BF28:BI28) -> 2181.0417 | BK28: ='IS (Non-GAAP)'!BK28+'IS (Non-GAAP)'!BK95+'IS (Non-GAAP)'!BK113 -> 595.4056 | BL28: ='IS (Non-GAAP)'!BL28+'IS (Non-GAAP)'!BL95+'IS (Non-GAAP)'!BL113 -> 608.54561 | BM28: ='IS (Non-GAAP)'!BM28+'IS (Non-GAAP)'!BM95+'IS (Non-GAAP)'!BM113 -> 678.01485 | BN28: ='IS (Non-GAAP)'!BN28+'IS (Non-GAAP)'!BN95+'IS (Non-GAAP)'!BN113 -> 741.05878 | BO28: =SUM(BK28:BN28) -> 2623.0248
A29: TREVYY | B29: % yoy | C29: -- | D29: -- | E29: -- | F29: -- | G29: -- | H29: =IFERROR(H28/C28-1,"--") -> -- | I29: =IFERROR(I28/D28-1,"--") -> -- | J29: =IFERROR(J28/E28-1,"--") -> -- | K29: =IFERROR(K28/F28-1,"--") -> -- | L29: =IFERROR(L28/G28-1,"--") -> -- | M29: =IFERROR(M28/H28-1,"--") -> 1.8275018 | N29: =IFERROR(N28/I28-1,"--") -> 1.8695652 | O29: =IFERROR(O28/J28-1,"--") -> 1.2121892 | ... BO29: =IFERROR(BO28/BJ28-1,"--") -> 0.20264774
A30: TREVQQ | B30: % qoq | C30: -- | D30: =IFERROR(D28/C28-1,"--") -> -- | E30: =IFERROR(E28/D28-1,"--") -> -- | F30: =IFERROR(F28/E28-1,"--") -> -- | H30: =IFERROR(H28/F28-1,"--") -> -- | I30: =IFERROR(I28/H28-1,"--") -> 0.18228942 | J30: =IFERROR(J28/I28-1,"--") -> 0.35683839 | K30: =IFERROR(K28/J28-1,"--") -> 0.35544386 | M30: =IFERROR(M28/K28-1,"--") -> 0.30037746 | N30: =IFERROR(N28/M28-1,"--") -> 0.19987778 | O30: =IFERROR(O28/N28-1,"--") -> 0.046006281 | P30: =IFERROR(P28/O28-1,"--") -> 0.16761341 | R30: =IFERROR(R28/P28-1,"--") -> 0.23477082 | S30: =IFERROR(S28/R28-1,"--") -> 0.20215011 | T30: =IFERROR(T28/S28-1,"--") -> 0.21303493 | U30: =IFERROR(U28/T28-1,"--") -> 0.23070094 | W30: =IFERROR(W28/U28-1,"--") -> 0.13031206 | X30: =IFERROR(X28/W28-1,"--") -> 0.12441731 | Y30: =IFERROR(Y28/X28-1,"--") -> 0.1387326 | Z30: =IFERROR(Z28/Y28-1,"--") -> 0.10948945 | AB30: =IFERROR(AB28/Z28-1,"--") -> 0.088029923 | AC30: =IFERROR(AC28/AB28-1,"--") -> 0.18126576 | AD30: =IFERROR(AD28/AC28-1,"--") -> 0.10883242 | AE30: =IFERROR(AE28/AD28-1,"--") -> 0.086836749 | AG30: =IFERROR(AG28/AE28-1,"--") -> 0.0048990864 | AH30: =IFERROR(AH28/AG28-1,"--") -> 0.060660819 | AI30: =IFERROR(AI28/AH28-1,"--") -> 0.06479893 | AJ30: =IFERROR(AJ28/AI28-1,"--") -> 0.070977778 | AL30: =IFERROR(AL28/AJ28-1,"--") -> 0.13944163 | AM30: =IFERROR(AM28/AL28-1,"--") -> 0.072499397 | AN30: =IFERROR(AN28/AM28-1,"--") -> 0.11902437 | AO30: =IFERROR(AO28/AN28-1,"--") -> 0.036362671 | AQ30: =IFERROR(AQ28/AO28-1,"--") -> 0.044171474 | AR30: =IFERROR(AR28/AQ28-1,"--") -> 0.059731628 | AS30: =IFERROR(AS28/AR28-1,"--") -> 0.0611744 | AT30: =IFERROR(AT28/AS28-1,"--") -> 0.10544381 | AV30: =IFERROR(AV28/AT28-1,"--") -> -0.021792124 | AW30: =IFERROR(AW28/AV28-1,"--") -> 0.035918492 | AX30: =IFERROR(AX28/AW28-1,"--") -> 0.080137362 | AY30: =IFERROR(AY28/AX28-1,"--") -> 0.10366554 | BA30: =IFERROR(BA28/AY28-1,"--") -> -0.031587669 | BB30: =IFERROR(BB28/BA28-1,"--") -> 0.038893439 | BC30: =IFERROR(BC28/BB28-1,"--") -> 0.084625959 | BD30: =IFERROR(BD28/BC28-1,"--") -> 0.095233319 | BF30: =IFERROR(BF28/BD28-1,"--") -> -0.041960003 | BG30: =IFERROR(BG28/BF28-1,"--") -> 0.036220175 | BH30: =IFERROR(BH28/BG28-1,"--") -> 0.10605549 | BI30: =IFERROR(BI28/BH28-1,"--") -> 0.10287384 | BK30: =IFERROR(BK28/BI28-1,"--") -> -0.039718086 | BL30: =IFERROR(BL28/BK28-1,"--") -> 0.022069 | BM30: =IFERROR(BM28/BL28-1,"--") -> 0.11415618 | BN30: =IFERROR(BN28/BM28-1,"--") -> 0.09298312
B31: % gross margins | C31: =IFERROR((C14-C28)/C14,"--") -> -- | D31: =IFERROR((D14-D28)/D14,"--") -> -- | E31: =IFERROR((E14-E28)/E14,"--") -> -- | F31: =IFERROR((F14-F28)/F14,"--") -> -- | G31: =IFERROR((G14-G28)/G14,"--") -> -- | H31: =IFERROR((H14-H28)/H14,"--") -> 0.47330502 | I31: =IFERROR((I14-I28)/I14,"--") -> 0.53544554 | J31: =IFERROR((J14-J28)/J14,"--") -> 0.60849703 | ... BO31: =IFERROR((BO14-BO28)/BO14,"--") -> 0.75260173
A33: TREV | B33: Cost of Professional Services & Other Revenue | G33: =SUM(C33:F33) -> 0 | H33: 0.494 | I33: 1.524 | J33: =13.824-J28 -> 2.683 | K33: =20.389-K28 -> 5.288 | L33: =SUM(H33:K33) -> 9.989 | M33: =24.038-M28 -> 4.401 | N33: =28.508-N28 -> 4.946 | O33: =29.489-O28 -> 4.843 | P33: =34.522-P28 -> 5.745 | Q33: =SUM(M33:P33) -> 19.935 | R33: =42.557-R28 -> 7.024 | S33: =50.446-S28 -> 7.73 | T33: 14.865 | U33: 19.134 | V33: =SUM(R33:U33) -> 48.753 | W33: 25.266 | X33: 25.073 | Y33: 28.494 | Z33: 31.783 | AA33: =SUM(W33:Z33) -> 110.616 | AB33: 36.519 | AC33: 41.626 | AD33: 44.792 | AE33: 47.056 | AF33: =SUM(AB33:AE33) -> 169.993 | AG33: 50.036 | AH33: 49.346 | AI33: 48.948 | AJ33: 49.028 | AK33: =SUM(AG33:AJ33) -> 197.358 | AL33: 52.86 | AM33: 52.496 | AN33: 57.272 | AO33: 59.976 | AP33: =SUM(AL33:AO33) -> 222.604 | AQ33: 63.51 | AR33: 69.499 | AS33: 70.063 | AT33: ='IS (Non-GAAP)'!AT33+'IS (Non-GAAP)'!AT96+'IS (Non-GAAP)'!AT117 -> 64.415393 | AU33: =SUM(AQ33:AT33) -> 267.48739 | AV33: ='IS (Non-GAAP)'!AV33+'IS (Non-GAAP)'!AV96+'IS (Non-GAAP)'!AV117 -> 64.697767 | AW33: ='IS (Non-GAAP)'!AW33+'IS (Non-GAAP)'!AW96+'IS (Non-GAAP)'!AW117 -> 74.484975 | AX33: ='IS (Non-GAAP)'!AX33+'IS (Non-GAAP)'!AX96+'IS (Non-GAAP)'!AX117 -> 73.867385 | AY33: ='IS (Non-GAAP)'!AY33+'IS (Non-GAAP)'!AY96+'IS (Non-GAAP)'!AY117 -> 67.708112 | AZ33: =SUM(AV33:AY33) -> 280.75824 | BA33: ='IS (Non-GAAP)'!BA33+'IS (Non-GAAP)'!BA96+'IS (Non-GAAP)'!BA117 -> 67.476225 | BB33: ='IS (Non-GAAP)'!BB33+'IS (Non-GAAP)'!BB96+'IS (Non-GAAP)'!BB117 -> 78.016829 | BC33: ='IS (Non-GAAP)'!BC33+'IS (Non-GAAP)'!BC96+'IS (Non-GAAP)'!BC117 -> 76.828944 | BD33: ='IS (Non-GAAP)'!BD33+'IS (Non-GAAP)'!BD96+'IS (Non-GAAP)'!BD117 -> 69.433104 | BE33: =SUM(BA33:BD33) -> 291.7551 | BF33: ='IS (Non-GAAP)'!BF33+'IS (Non-GAAP)'!BF96+'IS (Non-GAAP)'!BF117 -> 68.290746 | BG33: ='IS (Non-GAAP)'!BG33+'IS (Non-GAAP)'!BG96+'IS (Non-GAAP)'!BG117 -> 79.404728 | BH33: ='IS (Non-GAAP)'!BH33+'IS (Non-GAAP)'!BH96+'IS (Non-GAAP)'!BH117 -> 77.405242 | BI33: ='IS (Non-GAAP)'!BI33+'IS (Non-GAAP)'!BI96+'IS (Non-GAAP)'!BI117 -> 68.675467 | BJ33: =SUM(BF33:BI33) -> 293.77618 | BK33: ='IS (Non-GAAP)'!BK33+'IS (Non-GAAP)'!BK96+'IS (Non-GAAP)'!BK117 -> 67.442091 | BL33: ='IS (Non-GAAP)'!BL33+'IS (Non-GAAP)'!BL96+'IS (Non-GAAP)'!BL117 -> 79.046056 | BM33: ='IS (Non-GAAP)'!BM33+'IS (Non-GAAP)'!BM96+'IS (Non-GAAP)'!BM117 -> 75.629057 | BN33: ='IS (Non-GAAP)'!BN33+'IS (Non-GAAP)'!BN96+'IS (Non-GAAP)'!BN117 -> 65.393056 | BO33: =SUM(BK33:BN33) -> 287.51026
A34: TREVYY | B34: % yoy | C34: -- | D34: -- | E34: -- | F34: -- | G34: -- | H34: =IFERROR(H33/C33-1,"--") -> -- | I34: =IFERROR(I33/D33-1,"--") -> -- | J34: =IFERROR(J33/E33-1,"--") -> -- | K34: =IFERROR(K33/F33-1,"--") -> -- | L34: =IFERROR(L33/G33-1,"--") -> -- | M34: =IFERROR(M33/H33-1,"--") -> 7.9089069 | N34: =IFERROR(N33/I33-1,"--") -> 2.2454068 | O34: =IFERROR(O33/J33-1,"--") -> 0.80506895 | ... BO34: =IFERROR(BO33/BJ33-1,"--") -> -0.021328896
A35: TREVQQ | B35: % qoq | C35: -- | D35: =IFERROR(D33/C33-1,"--") -> -- | E35: =IFERROR(E33/D33-1,"--") -> -- | F35: =IFERROR(F33/E33-1,"--") -> -- | H35: =IFERROR(H33/F33-1,"--") -> -- | I35: =IFERROR(I33/H33-1,"--") -> 2.0850202 | J35: =IFERROR(J33/I33-1,"--") -> 0.76049869 | K35: =IFERROR(K33/J33-1,"--") -> 0.97092807 | M35: =IFERROR(M33/K33-1,"--") -> -0.16773828 | N35: =IFERROR(N33/M33-1,"--") -> 0.12383549 | O35: =IFERROR(O33/N33-1,"--") -> -0.020824909 | P35: =IFERROR(P33/O33-1,"--") -> 0.18624819 | R35: =IFERROR(R33/P33-1,"--") -> 0.22262837 | S35: =IFERROR(S33/R33-1,"--") -> 0.10051253 | T35: =IFERROR(T33/S33-1,"--") -> 0.92302717 | U35: =IFERROR(U33/T33-1,"--") -> 0.28718466 | W35: =IFERROR(W33/U33-1,"--") -> 0.32047664 | X35: =IFERROR(X33/W33-1,"--") -> -0.007638724 | Y35: =IFERROR(Y33/X33-1,"--") -> 0.13644159 | Z35: =IFERROR(Z33/Y33-1,"--") -> 0.11542781 | AB35: =IFERROR(AB33/Z33-1,"--") -> 0.14901048 | AC35: =IFERROR(AC33/AB33-1,"--") -> 0.13984501 | AD35: =IFERROR(AD33/AC33-1,"--") -> 0.076058233 | AE35: =IFERROR(AE33/AD33-1,"--") -> 0.05054474 | AG35: =IFERROR(AG33/AE33-1,"--") -> 0.0633288 | AH35: =IFERROR(AH33/AG33-1,"--") -> -0.013790071 | AI35: =IFERROR(AI33/AH33-1,"--") -> -0.0080654967 | AJ35: =IFERROR(AJ33/AI33-1,"--") -> 0.0016343875 | AL35: =IFERROR(AL33/AJ33-1,"--") -> 0.078159419 | AM35: =IFERROR(AM33/AL33-1,"--") -> -0.0068861143 | AN35: =IFERROR(AN33/AM33-1,"--") -> 0.09097836 | AO35: =IFERROR(AO33/AN33-1,"--") -> 0.047213298 | AQ35: =IFERROR(AQ33/AO33-1,"--") -> 0.058923569 | AR35: =IFERROR(AR33/AQ33-1,"--") -> 0.09430011 | AS35: =IFERROR(AS33/AR33-1,"--") -> 0.0081152247 | AT35: =IFERROR(AT33/AS33-1,"--") -> -0.080607548 | AV35: =IFERROR(AV33/AT33-1,"--") -> 0.004383643 | AW35: =IFERROR(AW33/AV33-1,"--") -> 0.15127581 | AX35: =IFERROR(AX33/AW33-1,"--") -> -0.0082914621 | AY35: =IFERROR(AY33/AX33-1,"--") -> -0.083382848 | BA35: =IFERROR(BA33/AY33-1,"--") -> -0.0034248028 | BB35: =IFERROR(BB33/BA33-1,"--") -> 0.15621211 | BC35: =IFERROR(BC33/BB33-1,"--") -> -0.01522601 | BD35: =IFERROR(BD33/BC33-1,"--") -> -0.096263724 | BF35: =IFERROR(BF33/BD33-1,"--") -> -0.016452644 | BG35: =IFERROR(BG33/BF33-1,"--") -> 0.16274507 | BH35: =IFERROR(BH33/BG33-1,"--") -> -0.025180945 | BI35: =IFERROR(BI33/BH33-1,"--") -> -0.11278015 | BK35: =IFERROR(BK33/BI33-1,"--") -> -0.017959477 | BL35: =IFERROR(BL33/BK33-1,"--") -> 0.1720582 | BM35: =IFERROR(BM33/BL33-1,"--") -> -0.043227948 | BN35: =IFERROR(BN33/BM33-1,"--") -> -0.13534482
B36: % gross margins | C36: =IFERROR((C19-C33)/C19,"--") -> -- | D36: =IFERROR((D19-D33)/D19,"--") -> -- | E36: =IFERROR((E19-E33)/E19,"--") -> -- | F36: =IFERROR((F19-F33)/F19,"--") -> -- | G36: =IFERROR((G19-G33)/G19,"--") -> -- | H36: =IFERROR((H19-H33)/H19,"--") -> -1.2764977 | I36: =IFERROR((I19-I33)/I19,"--") -> -5.626087 | J36: =IFERROR((J19-J33)/J19,"--") -> -11.03139 | ... BO36: =IFERROR((BO19-BO33)/BO19,"--") -> 0.1328276
B38: Gross Profit | C38: =C10-C24 -> 0 | D38: =D10-D24 -> 0 | E38: =E10-E24 -> 0 | F38: =F10-F24 -> 0 | G38: =SUM(C38:F38) -> 0 | H38: =H10-H24 -> 5.964 | I38: =I10-I24 -> 8.17 | J38: =J10-J24 -> 14.856 | K38: =K10-K24 -> 16.289 | L38: =SUM(H38:K38) -> 45.279 | M38: =M10-M24 -> 19.667 | N38: =N10-N24 -> 31.831 | O38: =O10-O24 -> 43.523 | P38: =P10-P24 -> 53.17 | Q38: =SUM(M38:P38) -> 148.191 | R38: =R10-R24 -> 66.258 | S38: =S10-S24 -> 82.699 | T38: =T10-T24 -> 92.943 | U38: =U10-U24 -> 107.561 | V38: =SUM(R38:U38) -> 349.461 | W38: =W10-W24 -> 131.568 | X38: =X10-X24 -> 166.077 | Y38: =Y10-Y24 -> 213.655 | Z38: =Z10-Z24 -> 249.594 | AA38: =SUM(W38:Z38) -> 760.894 | AB38: =AB10-AB24 -> 274.441 | AC38: =AC10-AC24 -> 324.016 | AD38: =AD10-AD24 -> 366.307 | AE38: =AE10-AE24 -> 383.355 | AF38: =SUM(AB38:AE38) -> 1348.119 | AG38: =AG10-AG24 -> 414.185 | AH38: =AH10-AH24 -> 455.626 | AI38: =AI10-AI24 -> 505.225 | AJ38: =AJ10-AJ24 -> 532.895 | AK38: =SUM(AG38:AJ38) -> 1907.931 | AL38: =AL10-AL24 -> 556.192 | AM38: =AM10-AM24 -> 580.745 | AN38: =AN10-AN24 -> 621.2 | AO38: =AO10-AO24 -> 653.586 | AP38: =SUM(AL38:AO38) -> 2411.723 | AQ38: =AQ10-AQ24 -> 693.288 | AR38: =AR10-AR24 -> 773.154 | AS38: =AS10-AS24 -> 822.036 | AT38: =AT10-AT24 -> 829.75024 | AU38: =SUM(AQ38:AT38) -> 3118.2282 | AV38: =AV10-AV24 -> 901.40408 | AW38: =AW10-AW24 -> 981.18087 | AX38: =AX10-AX24 -> 1040.2784 | AY38: =AY10-AY24 -> 1053.1108 | AZ38: =SUM(AV38:AY38) -> 3975.9742 | BA38: =BA10-BA24 -> 1146.9033 | BB38: =BB10-BB24 -> 1251.7894 | BC38: =BC10-BC24 -> 1330.2259 | BD38: =BD10-BD24 -> 1332.2915 | BE38: =SUM(BA38:BD38) -> 5061.21 | BF38: =BF10-BF24 -> 1437.6964 | BG38: =BG10-BG24 -> 1565.0334 | BH38: =BH10-BH24 -> 1693.1586 | BI38: =BI10-BI24 -> 1703.2833 | BJ38: =SUM(BF38:BI38) -> 6399.1717 | BK38: =BK10-BK24 -> 1819.4715 | BL38: =BL10-BL24 -> 1955.1473 | BM38: =BM10-BM24 -> 2129.4726 | BN38: =BN10-BN24 -> 2119.3609 | BO38: =SUM(BK38:BN38) -> 8023.4523
B39: % yoy | C39: -- | D39: -- | E39: -- | F39: -- | G39: -- | H39: =IFERROR(H38/C38-1,"--") -> -- | I39: =IFERROR(I38/D38-1,"--") -> -- | J39: =IFERROR(J38/E38-1,"--") -> -- | K39: =IFERROR(K38/F38-1,"--") -> -- | L39: =IFERROR(L38/G38-1,"--") -> -- | M39: =IFERROR(M38/H38-1,"--") -> 2.297619 | N39: =IFERROR(N38/I38-1,"--") -> 2.8960832 | O39: =IFERROR(O38/J38-1,"--") -> 1.9296581 | ... BO39: =IFERROR(BO38/BJ38-1,"--") -> 0.25382669
