Workbook
Name __FDS_UNIQUE_RANGE_ID_GENERATOR_COUNTER: 50
Name __FDS_USED_FOR_REUSING_RANGE_IDS_RECYCLE: {22,8,23,4,14,18,17,43,48,47,45,46,1,51,50,49}
Name A_ALL_CRWV: #REF!
Name A_ALL_MNDY: #REF!
Name A_ALL_MSFT: #REF!
Name A_ALL_NTNX: [1]NTNX_Annotation_Sheet!$A$1:$CB$331
Name A_ALL_TTAN: #REF!
Name AL_email: "alamba@isigrp.com"
Name AL_phone: "(XXX) XXX-XXXX"
Name AVELIFE: 3
Name BB_email: "bbaytosh@isigrp.com"
Name BB_phone: "(212) 446-9469"
Name CUR3MTH: 6
Name CURCYTD: 9
Name CURMTH: 1
Name CURMYTD: 12
Name CURRENT_MONTH_FIXING: 23
Name CURRENT_MONTH_SPOT: 6
Name CURWEEK: 1
Name CYTDVOL: 11
Name DB: "WIRENYPROD"
Name E_ALL_CRWV: #REF!
Name E_ALL_MNDY: #REF!
Name E_ALL_MSFT: #REF!
Name E_ALL_NTNX: [1]NTNX_Exchange_Sheet!$A$1:$CB$331
Name E_ALL_TTAN: #REF!
Name FINCriteriaType: 1
Name fx: 120
Name FYE: "FYE"
Name HB_email: "hbellini@isigrp.com"
Name HB_phone: "(XXX) XXX-XXXX"
Name L_ALL_CRWV: #REF!
Name L_ALL_MNDY: #REF!
Name L_ALL_MSFT: #REF!
Name L_ALL_NTNX: [1]NTNX_Live_Sheet!$A$1:$CB$331
Name L_ALL_TTAN: #REF!
Name LastListUpdate: 0
Name Low: 1
Name M1_Seasonality: 0.3
Name M2_Seasonality: 0.3
Name M3_Seasonality: 0.4
Name MyBegOfYEar: IF(BegOfYear5253week<>"",BegOfYear5253week,IF(TaxYearEnd="","",TaxYearEnd-364))
Name MyBookIncome: IF(BookIncome = "","",BookIncome)
Name MyFEIN: IF(FEIN="","",FEIN)
Name MyLastYear: IF(TaxYearEnd="","",TaxYearEnd-366)
Name MyName: IF(TheName = "","",TheName)
Name MyNextYear: IF(TaxYearEnd="","",TaxYearEnd+365)
Name MyTaxYear: IF(TaxYearEnd="","",TaxYearEnd)
Name MYTDVOL: 14
Name NextButton: "Button 18"
Name NvsASD: "V1999-12-31"
Name NvsAutoDrillOk: "VN"
Name NvsElapsedTime: 0.00102581018290948
Name NvsEndTime: 36558.0571400463
Name NvsInstSpec1: ","
Name NvsInstSpec2: ","
Name NvsInstSpec3: ","
Name NvsInstSpec4: ","
Name NvsInstSpec5: ","
Name NvsInstSpec6: ","

Sheet __FDSCACHE__
B1: This sheet contains FactSet XML data for use with this workbook's =FDS codes. Modifying the worksheet's contents may damage the workbook's =FDS functionality.

Sheet Cover
C2: CoreWeave Analyst Model
C3: Ticker: | D3: CRWV
C4: Date: | D4: =TODAY() -> 45975
B6: Kash Rangan
B7: (415) 249-7318
B8: kash.rangan@gs.com
B10: Matthew Martino
B11: (212) 902-0695
B12: matt.martino@gs.com
B14: Nishad Patwardhan
B15: (332) 245-7726
B16: nishad.patwardhan@gs.com
B18: Selina Zhang
B19: (212) 357-9979
B20: selina.zhang@gs.com

Sheet Revenue and CapEx Build
B2: CoreWeave, Inc.
B3: Fiscal Year Ends Dec. 31
B4: ($ millions, except per share amounts)
C6: =Dates!C3 -> 2022 (A) | H6: =Dates!H3 -> 2023 (A) | M6: =Dates!M3 -> 2024 (A) | R6: =Dates!R3 -> 2025 (E) | W6: =Dates!W3 -> 2026 (E) | AB6: =Dates!AB3 -> 2027 (E) | AG6: =Dates!AG3 -> 2028 (E)
C7: =Dates!C4 -> 1Q22 (A) | D7: =Dates!D4 -> 2Q22 (A) | E7: =Dates!E4 -> 3Q22 (A) | F7: =Dates!F4 -> 4Q22 (A) | G7: =Dates!G4 -> FY22 (A) | H7: =Dates!H4 -> 1Q23 (A) | I7: =Dates!I4 -> 2Q23 (A) | J7: =Dates!J4 -> 3Q23 (A) | ... AK7: =Dates!AK4 -> FY28 (E)
C8: =Dates!C5 -> 44651 | D8: =Dates!D5 -> 44742 | E8: =Dates!E5 -> 44834 | F8: =Dates!F5 -> 44926 | G8: =Dates!G5 -> 44926 | H8: =Dates!H5 -> 45016 | I8: =Dates!I5 -> 45107 | J8: =Dates!J5 -> 45199 | ... AK8: =Dates!AK5 -> 47118
A10: TREV | B10: Total Revenue | G10: 15.83 | H10: =M10/(1+M11) -> 7.9236843 | I10: =N10/(1+N11) -> 29.8436 | J10: =O10/(1+O11) -> 75.178825 | K10: =L10-J10-I10-H10 -> 115.99689 | L10: 228.943 | M10: 188.684 | N10: 395.371 | O10: 583.941 | P10: 747.43 | Q10: =SUM(M10:P10) -> 1915.426 | R10: 981.632 | S10: 1212.788 | T10: 1364.676 | U10: =U16*U23 -> 1542.8798 | V10: =SUM(R10:U10) -> 5101.9758 | W10: =W16*W23 -> 2227.1272 | X10: =X16*X23 -> 2964.1923 | Y10: =Y16*Y23 -> 3289.6841 | Z10: =Z16*Z23 -> 3520.6358 | AA10: =SUM(W10:Z10) -> 12001.639 | AB10: =AB16*AB23 -> 3811.6134 | AC10: =AC16*AC23 -> 4153.968 | AD10: =AD16*AD23 -> 4473.8327 | AE10: =AE16*AE23 -> 4771.4757 | AF10: =SUM(AB10:AE10) -> 17210.89 | AG10: =AG16*AG23 -> 5118.4482 | AH10: =AH16*AH23 -> 5329.7807 | AI10: =AI16*AI23 -> 5519.2672 | AJ10: =AJ16*AJ23 -> 5687.5931 | AK10: =SUM(AG10:AJ10) -> 21655.089
A11: TREVYY | B11: % yoy | H11: =IFERROR(H10/C10-1,"") | I11: =IFERROR(I10/D10-1,"") | J11: =IFERROR(J10/E10-1,"") | K11: =IFERROR(K10/F10-1,"") | L11: =IFERROR(L10/G10-1,"") -> 13.462603 | M11: 22.81266 | N11: 12.2481 | O11: 6.76736 | P11: =IFERROR(P10/K10-1,"") -> 5.4435348 | Q11: =IFERROR(Q10/L10-1,"") -> 7.3663881 | R11: =IFERROR(R10/M10-1,"") -> 4.2025185 | S11: =IFERROR(S10/N10-1,"") -> 2.0674683 | T11: =IFERROR(T10/O10-1,"") -> 1.3370101 | U11: =IFERROR(U10/P10-1,"") -> 1.0642466 | V11: =IFERROR(V10/Q10-1,"") -> 1.6636246 | W11: =IFERROR(W10/R10-1,"") -> 1.2688005 | ... AK11: =IFERROR(AK10/AF10-1,"") -> 0.25822019
A12: TREVQQ | B12: % qoq | H12: =IFERROR(H10/F10-1,"") | I12: =IFERROR(I10/H10-1,"") -> 2.7663793 | J12: =IFERROR(J10/I10-1,"") -> 1.5190937 | K12: =IFERROR(K10/J10-1,"") -> 0.5429463 | M12: =IFERROR(M10/K10-1,"") -> 0.62662981 | N12: =IFERROR(N10/M10-1,"") -> 1.0954135 | O12: =IFERROR(O10/N10-1,"") -> 0.47694444 | P12: =IFERROR(P10/O10-1,"") -> 0.2799752 | R12: =IFERROR(R10/P10-1,"") -> 0.31334306 | S12: =IFERROR(S10/R10-1,"") -> 0.23548132 | T12: =IFERROR(T10/S10-1,"") -> 0.12523871 | U12: =IFERROR(U10/T10-1,"") -> 0.13058326 | W12: =IFERROR(W10/U10-1,"") -> 0.44348713 | X12: =IFERROR(X10/W10-1,"") -> 0.33094883 | Y12: =IFERROR(Y10/X10-1,"") -> 0.10980793 | Z12: =IFERROR(Z10/Y10-1,"") -> 0.070204816 | AB12: =IFERROR(AB10/Z10-1,"") -> 0.082649169 | AC12: =IFERROR(AC10/AB10-1,"") -> 0.089818799 | AD12: =IFERROR(AD10/AC10-1,"") -> 0.077002222 | AE12: =IFERROR(AE10/AD10-1,"") -> 0.066529754 | AG12: =IFERROR(AG10/AE10-1,"") -> 0.072718069 | AH12: =IFERROR(AH10/AG10-1,"") -> 0.041288386 | AI12: =IFERROR(AI10/AH10-1,"") -> 0.035552396 | AJ12: =IFERROR(AJ10/AI10-1,"") -> 0.030497879
B13: Net New Revenue (yoy) | H13: =H10-C10 -> 7.9236843 | I13: =I10-D10 -> 29.8436 | J13: =J10-E10 -> 75.178825 | K13: =K10-F10 -> 115.99689 | L13: =L10-G10 -> 213.113 | M13: =M10-H10 -> 180.76032 | N13: =N10-I10 -> 365.5274 | O13: =O10-J10 -> 508.76217 | ... AK13: =AK10-AF10 -> 4444.1993
B14: Net New Revenue (qoq) | H14: =H10-F10 -> 7.9236843 | I14: =I10-H10 -> 21.919916 | J14: =J10-I10 -> 45.335225 | K14: =K10-J10 -> 40.818065 | M14: =M10-K10 -> 72.68711 | N14: =N10-M10 -> 206.687 | O14: =O10-N10 -> 188.57 | P14: =P10-O10 -> 163.489 | R14: =R10-P10 -> 234.202 | S14: =S10-R10 -> 231.156 | T14: =T10-S10 -> 151.888 | U14: =U10-T10 -> 178.20384 | W14: =W10-U10 -> 684.24736 | X14: =X10-W10 -> 737.06513 | Y14: =Y10-X10 -> 325.49181 | Z14: =Z10-Y10 -> 230.95167 | AB14: =AB10-Z10 -> 290.97762 | AC14: =AC10-AB10 -> 342.35454 | AD14: =AD10-AC10 -> 319.86477 | AE14: =AE10-AD10 -> 297.64299 | AG14: =AG10-AE10 -> 346.9725 | AH14: =AH10-AG10 -> 211.33246 | AI14: =AI10-AH10 -> 189.48647 | AJ14: =AJ10-AI10 -> 168.32594
B16: Revenue / Average Net Assets | O16: =O$10/O$23 -> 0.086095277 | P16: =P$10/P$23 -> 0.097257296 | R16: =R$10/R$23 -> 0.10414591 | S16: =S$10/S$23 -> 0.1070543 | T16: =T$10/T$23 -> 0.10389865 | U16: 0.0976 | V16: =AVERAGE(R16:U16) -> 0.10317472 | W16: 0.098 | X16: 0.101 | Y16: 0.103 | Z16: 0.105 | AA16: =AVERAGE(W16:Z16) -> 0.10175 | AB16: 0.106 | AC16: =AB16 -> 0.106 | AD16: =AC16 -> 0.106 | AE16: =AD16 -> 0.106 | AF16: =AVERAGE(AB16:AE16) -> 0.106 | AG16: 0.108 | AH16: =AG16 -> 0.108 | AI16: =AH16 -> 0.108 | AJ16: =AI16 -> 0.108 | AK16: =AVERAGE(AG16:AJ16) -> 0.108
B17: Revenue / Average Net Assets, Annualized | O17: =O16*4 -> 0.34438111 | P17: =P16*4 -> 0.38902918 | R17: =R16*4 -> 0.41658366 | S17: =S16*4 -> 0.42821721 | T17: =T16*4 -> 0.4155946 | U17: =U16*4 -> 0.3904 | W17: =W16*4 -> 0.392 | X17: =X16*4 -> 0.404 | Y17: =Y16*4 -> 0.412 | Z17: =Z16*4 -> 0.42 | AB17: =AB16*4 -> 0.424 | AC17: =AC16*4 -> 0.424 | AD17: =AD16*4 -> 0.424 | AE17: =AE16*4 -> 0.424 | AG17: =AG16*4 -> 0.432 | AH17: =AH16*4 -> 0.432 | AI17: =AI16*4 -> 0.432 | AJ17: =AJ16*4 -> 0.432
B18: Revenue / Average Gross Assets | O18: =O$10/O$28 -> 0.080338949 | P18: =P$10/P$28 -> 0.088204788 | R18: =R$10/R$28 -> 0.092537485 | S18: =S$10/S$28 -> 0.093253366 | T18: =T$10/T$28 -> 0.088622363 | U18: =U$10/U$28 -> 0.082175834 | W18: =W$10/W$28 -> 0.083496471 | X18: =X$10/X$28 -> 0.08573449 | Y18: =Y$10/Y$28 -> 0.085200041 | Z18: =Z$10/Z$28 -> 0.084261617 | AB18: =AB$10/AB$28 -> 0.082922964 | AC18: =AC$10/AC$28 -> 0.081183094 | AD18: =AD$10/AD$28 -> 0.079357218 | AE18: =AE$10/AE$28 -> 0.077468268 | AG18: =AG$10/AG$28 -> 0.076872621 | AH18: =AH$10/AH$28 -> 0.074703951 | AI18: =AI$10/AI$28 -> 0.072522393 | AJ18: =AJ$10/AJ$28 -> 0.070332762
A20: NAEXCIP | B20: Net Assets (ex. CIP) | O20: =O25+O115 -> 6656.25 | P20: =P25+P115 -> 8713.908 | Q20: =Q25+Q115 -> 8713.908 | R20: =R25+R115 -> 10137.182 | S20: =S25+S115 -> 12520.254 | T20: =T25+T115 -> 13749.115 | U20: =U25+U115 -> 17867.275 | V20: =V25+V115 -> 17867.275 | ... AK20: =AK25+AK115 -> 53401.082
B21: % yoy | M21: =IFERROR(M20/H20-1,"") | N21: =IFERROR(N20/I20-1,"") | O21: =IFERROR(O20/J20-1,"") | P21: =IFERROR(P20/K20-1,"") | Q21: =IFERROR(Q20/L20-1,"") | R21: =IFERROR(R20/M20-1,"") | S21: =IFERROR(S20/N20-1,"") | T21: =IFERROR(T20/O20-1,"") -> 1.0655947 | ... AK21: =IFERROR(AK20/AF20-1,"") -> 0.15162077
B22: % qoq | M22: =IFERROR(M20/K20-1,"") | N22: =IFERROR(N20/M20-1,"") | O22: =IFERROR(O20/N20-1,"") | P22: =IFERROR(P20/O20-1,"") -> 0.30913172 | R22: =IFERROR(R20/P20-1,"") -> 0.1633336 | S22: =IFERROR(S20/R20-1,"") -> 0.23508229 | T22: =IFERROR(T20/S20-1,"") -> 0.098149846 | U22: =IFERROR(U20/T20-1,"") -> 0.29952183 | W22: =IFERROR(W20/U20-1,"") -> 0.54384483 | X22: =IFERROR(X20/W20-1,"") -> 0.12790889 | Y22: =IFERROR(Y20/X20-1,"") -> 0.053104148 | Z22: =IFERROR(Z20/Y20-1,"") -> 0.046701387 | AB22: =IFERROR(AB20/Z20-1,"") -> 0.097021411 | AC22: =IFERROR(AC20/AB20-1,"") -> 0.083253192 | AD22: =IFERROR(AD20/AC20-1,"") -> 0.071231669 | AE22: =IFERROR(AE20/AD20-1,"") -> 0.062140492 | AG22: =IFERROR(AG20/AE20-1,"") -> 0.044108716 | AH22: =IFERROR(AH20/AG20-1,"") -> 0.038587201 | AI22: =IFERROR(AI20/AH20-1,"") -> 0.032630345 | AJ22: =IFERROR(AJ20/AI20-1,"") -> 0.028432797
B23: Average Net Assets (ex. CIP) | O23: =O28+AVERAGE(N115:O115) -> 6782.4975 | P23: =AVERAGE(O20:P20) -> 7685.079 | Q23: =P23 -> 7685.079 | R23: =AVERAGE(Q20:R20) -> 9425.545 | S23: =AVERAGE(R20:S20) -> 11328.718 | T23: =AVERAGE(S20:T20) -> 13134.684 | U23: =AVERAGE(T20:U20) -> 15808.195 | V23: =U23 -> 15808.195 | W23: =AVERAGE(V20:W20) -> 22725.788 | X23: =AVERAGE(W20:X20) -> 29348.439 | Y23: =AVERAGE(X20:Y20) -> 31938.681 | Z23: =AVERAGE(Y20:Z20) -> 33529.865 | AA23: =Z23 -> 33529.865 | AB23: =AVERAGE(AA20:AB20) -> 35958.617 | AC23: =AVERAGE(AB20:AC20) -> 39188.377 | AD23: =AVERAGE(AC20:AD20) -> 42205.969 | AE23: =AVERAGE(AD20:AE20) -> 45013.922 | AF23: =AE23 -> 45013.922 | AG23: =AVERAGE(AF20:AG20) -> 47393.039 | AH23: =AVERAGE(AG20:AH20) -> 49349.821 | AI23: =AVERAGE(AH20:AI20) -> 51104.326 | AJ23: =AVERAGE(AI20:AJ20) -> 52662.899 | AK23: =AJ23 -> 52662.899
B25: Gross Assets (ex. CIP) | O25: =O31-O59 -> 7268.467 | P25: =P31-P59 -> 9679.139 | Q25: =P25 -> 9679.139 | R25: =R31-R59 -> 11536.739 | S25: =S31-S59 -> 14473.861 | T25: =T31-T59 -> 16323.693 | U25: =U31-U59 -> 21227.002 | V25: =U25 -> 21227.002 | W25: =W31-W59 -> 32119.617 | X25: =X31-X59 -> 37028.572 | Y25: =Y31-Y59 -> 40194.024 | Z25: =Z31-Z59 -> 43370.378 | AA25: =Z25 -> 43370.378 | AB25: =AB31-AB59 -> 48561.054 | AC25: =AC31-AC59 -> 53774.734 | AD25: =AD31-AD59 -> 58977.02 | AE25: =AE31-AE59 -> 64208.276 | AF25: =AE25 -> 64208.276 | AG25: =AG31-AG59 -> 68958.727 | AH25: =AH31-AH59 -> 73732.005 | AI25: =AI31-AI59 -> 78476.628 | AJ25: =AJ31-AJ59 -> 83257.191 | AK25: =AJ25 -> 83257.191
B26: % yoy | M26: =IFERROR(M25/H25-1,"") | N26: =IFERROR(N25/I25-1,"") | O26: =IFERROR(O25/J25-1,"") | Q26: =IFERROR(Q25/L25-1,"") | S26: =IFERROR(S25/N25-1,"") | T26: =IFERROR(T25/O25-1,"") -> 1.2458234 | U26: =IFERROR(U25/P25-1,"") -> 1.1930672 | V26: =IFERROR(V25/Q25-1,"") -> 1.1930672 | W26: =IFERROR(W25/R25-1,"") -> 1.7841157 | X26: =IFERROR(X25/S25-1,"") -> 1.5583064 | Y26: =IFERROR(Y25/T25-1,"") -> 1.4623119 | Z26: =IFERROR(Z25/U25-1,"") -> 1.0431702 | ... AK26: =IFERROR(AK25/AF25-1,"") -> 0.29667383
B27: % qoq | M27: =IFERROR(M25/K25-1,"") | N27: =IFERROR(N25/M25-1,"") | O27: =IFERROR(O25/N25-1,"") | P27: =IFERROR(P25/O25-1,"") -> 0.33166168 | R27: =IFERROR(R25/P25-1,"") -> 0.1919179 | S27: =IFERROR(S25/R25-1,"") -> 0.25458858 | T27: =IFERROR(T25/S25-1,"") -> 0.12780501 | U27: =IFERROR(U25/T25-1,"") -> 0.30037988 | W27: =IFERROR(W25/U25-1,"") -> 0.51314899 | X27: =IFERROR(X25/W25-1,"") -> 0.15283356 | Y27: =IFERROR(Y25/X25-1,"") -> 0.085486734 | Z27: =IFERROR(Z25/Y25-1,"") -> 0.079025536 | AB27: =IFERROR(AB25/Z25-1,"") -> 0.11968253 | AC27: =IFERROR(AC25/AB25-1,"") -> 0.1073634 | AD27: =IFERROR(AD25/AC25-1,"") -> 0.0967422 | AE27: =IFERROR(AE25/AD25-1,"") -> 0.088699898 | AG27: =IFERROR(AG25/AE25-1,"") -> 0.073985024 | AH27: =IFERROR(AH25/AG25-1,"") -> 0.069219356 | AI27: =IFERROR(AI25/AH25-1,"") -> 0.064349565 | AJ27: =IFERROR(AJ25/AI25-1,"") -> 0.060917032
B28: Average Gross Assets (ex. CIP) | O28: =AVERAGE(O25,N25) -> 7268.467 | P28: =AVERAGE(P25,O25) -> 8473.803 | Q28: =AVERAGE(Q25,L25) -> 9679.139 | R28: =AVERAGE(R25,Q25) -> 10607.939 | S28: =AVERAGE(S25,R25) -> 13005.3 | T28: =AVERAGE(T25,S25) -> 15398.777 | U28: =AVERAGE(U25,T25) -> 18775.348 | V28: =AVERAGE(V25,Q25) -> 15453.071 | W28: =AVERAGE(W25,V25) -> 26673.309 | X28: =AVERAGE(X25,W25) -> 34574.094 | Y28: =AVERAGE(Y25,X25) -> 38611.298 | Z28: =AVERAGE(Z25,Y25) -> 41782.201 | AA28: =AVERAGE(AA25,V25) -> 32298.69 | AB28: =AVERAGE(AB25,AA25) -> 45965.716 | AC28: =AVERAGE(AC25,AB25) -> 51167.894 | AD28: =AVERAGE(AD25,AC25) -> 56375.877 | AE28: =AVERAGE(AE25,AD25) -> 61592.648 | AF28: =AVERAGE(AF25,AA25) -> 53789.327 | AG28: =AVERAGE(AG25,AF25) -> 66583.501 | AH28: =AVERAGE(AH25,AG25) -> 71345.366 | AI28: =AVERAGE(AI25,AH25) -> 76104.316 | AJ28: =AVERAGE(AJ25,AI25) -> 80866.909 | AK28: =AVERAGE(AK25,AF25) -> 73732.733
B30: Balance Sheet Pulls
B31: =BS!B20 -> Property, Plant, and Equipment, Gross | M31: =BS!M20 -> 5268.215 | N31: =BS!N20 -> 7385.5522 | O31: =BS!O20 -> 9728.807 | P31: =BS!P20 -> 12880.005 | Q31: =BS!Q20 -> 12880.005 | R31: =BS!R20 -> 15610.549 | S31: =BS!S20 -> 18585.117 | T31: =BS!T20 -> 23233.759 | ... AK31: =BS!AK20 -> 100089.77
B32: =BS!B22 -> Property and Equipment, Net | M32: =BS!M22 -> 5072.433 | N32: =BS!N22 -> 7025.8302 | O32: =BS!O22 -> 9116.59 | P32: =BS!P22 -> 11914.774 | Q32: =BS!Q22 -> 11914.774 | R32: =BS!R22 -> 14210.992 | S32: =BS!S22 -> 16631.51 | T32: =BS!T22 -> 20659.181 | ... AK32: =BS!AK22 -> 70233.659
A34: CAPEXFL | B34: CapEx (including Finance Leases) | M34: 1100 | N34: 2600 | O34: 2200 | P34: 2400 | Q34: =SUM(M34:P34) -> 8300 | R34: 1900 | S34: 2900 | T34: 1900 | U34: =U46-U66+U73 -> 6323.333 | V34: =SUM(R34:U34) -> 13023.333 | W34: =W46-W66+W73 -> 12383.64 | X34: =X46-X66+X73 -> 6399.9805 | Y34: =Y46-Y66+Y73 -> 4656.4769 | Z34: =Z46-Z66+Z73 -> 4667.3795 | AA34: =SUM(W34:Z34) -> 28107.477 | AB34: =AB46-AB66+AB73 -> 6681.7016 | AC34: =AC46-AC66+AC73 -> 6704.705 | AD34: =AD46-AD66+AD73 -> 6693.3113 | AE34: =AE46-AE66+AE73 -> 6722.2808 | AF34: =SUM(AB34:AE34) -> 26801.999 | AG34: =AG46-AG66+AG73 -> 6241.476 | AH34: =AH46-AH66+AH73 -> 6264.3038 | AI34: =AI46-AI66+AI73 -> 6235.6476 | AJ34: =AJ46-AJ66+AJ73 -> 6271.5884 | AK34: =SUM(AG34:AJ34) -> 25013.016
A35: CAPEXFLYY | B35: % yoy | M35: =IFERROR(M34/H34-1,"") | N35: =IFERROR(N34/I34-1,"") | O35: =IFERROR(O34/J34-1,"") | P35: =IFERROR(P34/K34-1,"") | Q35: =IFERROR(Q34/L34-1,"") | R35: =IFERROR(R34/M34-1,"") -> 0.72727273 | S35: =IFERROR(S34/N34-1,"") -> 0.11538462 | T35: =IFERROR(T34/O34-1,"") -> -0.13636364 | ... AK35: =IFERROR(AK34/AF34-1,"") -> -0.06674811
A36: CAPEXFYQQ | B36: % qoq | M36: =IFERROR(M34/K34-1,"") | N36: =IFERROR(N34/M34-1,"") -> 1.3636364 | O36: =IFERROR(O34/N34-1,"") -> -0.15384615 | P36: =IFERROR(P34/O34-1,"") -> 0.090909091 | R36: =IFERROR(R34/P34-1,"") -> -0.20833333 | S36: =IFERROR(S34/R34-1,"") -> 0.52631579 | T36: =IFERROR(T34/S34-1,"") -> -0.34482759 | U36: =IFERROR(U34/T34-1,"") -> 2.32807 | W36: =IFERROR(W34/U34-1,"") -> 0.95840386 | X36: =IFERROR(X34/W34-1,"") -> -0.48319068 | Y36: =IFERROR(Y34/X34-1,"") -> -0.27242327 | Z36: =IFERROR(Z34/Y34-1,"") -> 0.0023413777 | AB36: =IFERROR(AB34/Z34-1,"") -> 0.43157453 | AC36: =IFERROR(AC34/AB34-1,"") -> 0.0034427537 | AD36: =IFERROR(AD34/AC34-1,"") -> -0.001699363 | AE36: =IFERROR(AE34/AD34-1,"") -> 0.0043281354 | AG36: =IFERROR(AG34/AE34-1,"") -> -0.071524057 | AH36: =IFERROR(AH34/AG34-1,"") -> 0.0036574329 | AI36: =IFERROR(AI34/AH34-1,"") -> -0.0045745223 | AJ36: =IFERROR(AJ34/AI34-1,"") -> 0.0057637635
B37: Net New CapEx (yoy) | M37: =M34-H34 -> 1100 | N37: =N34-I34 -> 2600 | O37: =O34-J34 -> 2200 | P37: =P34-K34 -> 2400 | Q37: =Q34-L34 -> 8300 | R37: =R34-M34 -> 800 | S37: =S34-N34 -> 300 | T37: =T34-O34 -> -300 | ... AK37: =AK34-AF34 -> -1788.9828
B38: Net New CapEx (qoq) | M38: =M34-K34 -> 1100 | N38: =N34-M34 -> 1500 | O38: =O34-N34 -> -400 | P38: =P34-O34 -> 200 | R38: =R34-P34 -> -500 | S38: =S34-R34 -> 1000 | T38: =T34-S34 -> -1000 | U38: =U34-T34 -> 4423.333 | W38: =W34-U34 -> 6060.3068 | X38: =X34-W34 -> -5983.6593 | Y38: =Y34-X34 -> -1743.5036 | Z38: =Z34-Y34 -> 10.902571 | AB38: =AB34-Z34 -> 2014.3221 | AC38: =AC34-AB34 -> 23.003453 | AD38: =AD34-AC34 -> -11.393728 | AE38: =AE34-AD34 -> 28.969558 | AG38: =AG34-AE34 -> -480.8048 | AH38: =AH34-AG34 -> 22.82778 | AI38: =AI34-AH34 -> -28.656198 | AJ38: =AJ34-AI34 -> 35.940798
B40: CapEx Efficiency
B41: CapEx / Revenue | P41: =P46/P10 -> 4.2160443 | Q41: =Q46/Q10 -> 4.5431554 | R41: =R46/R10 -> 1.4336931 | S41: =S46/S10 -> 2.0226058 | T41: =T46/T10 -> 2.4026113 | U41: =U46/U10 -> 5.4173642 | V41: =V46/V10 -> 3.0375446 | W41: =W46/W10 -> 3.9600768 | ... AK41: =AK46/AK10 -> 1.1444152
B42: CapEx / NTM Revenue | P42: =P46/(T10+R10+S10+U10) -> 0.61764267 | Q42: =Q46/V10 -> 1.705629 | R42: =R46/(S10+T10+U10+W10) -> 0.22171964 | S42: =S46/(T10+U10+W10+X10) -> 0.30288057 | T42: =T46/(U10+V10+X10+Y10) -> 0.25419444 | U42: =U46/(Y10+W10+X10+Z10) -> 0.69643335 | V42: =V46/AA10 -> 1.2912802 | W42: =W46/(X10+Y10+Z10+AB10) -> 0.64916187 | X42: =X46/(Y10+Z10+AB10+AC10) -> 0.34345092 | Y42: =Y46/(Z10+AC10+AB10+AD10) -> 0.22483311 | Z42: =Z46/(AD10+AB10+AC10+AE10) -> 0.20003491 | AA42: =AA46/AF10 -> 1.2158301 | AB42: =AB46/(AC10+AD10+AE10+AG10) -> 0.23091132 | AC42: =AC46/(AD10+AE10+AG10+AH10) -> 0.34834693 | AD42: =AD46/(AE10+AH10+AG10+AI10) -> 0.27466343 | AE42: =AE46/(AI10+AG10+AH10+AJ10) -> 0.27510225 | AF42: =AF46/AK10 -> 1.0523963
B43: CapEx / Net New Revenue (yoy) | P43: =P46/P13 -> 4.9905492 | Q43: =Q46/Q13 -> 5.1598967 | R43: =R46/R13 -> 1.774844 | S43: =S46/S13 -> 3.0009065 | T43: =T46/T13 -> 4.1996145 | U43: =U46/U13 -> 10.507692 | V43: =V46/V13 -> 4.8634039 | W43: =W46/W13 -> 7.0811954 | ... AK43: =AK46/AK13 -> 5.5763504
B45: CapEx Breakdown
B46: Total Purchase of P&E (incl. CIP) | G46: =-CF!G40 -> 72.404 | L46: =-CF!L40 -> 2943.13 | M46: =-CF!M40 -> 1741.935 | P46: =-CF!P40 -> 3151.198 | Q46: =-CF!Q40 -> 8702.078 | R46: =-CF!R40 -> 1407.359 | S46: =-CF!S40 -> 2452.992 | T46: =-CF!T40 -> 3278.786 | U46: =+U52+U66+U80+U87+U93 -> 8358.342 | V46: =SUM(R46:U46) -> 15497.479 | W46: =+W52+W66+W80+W87+W93 -> 8819.5948 | X46: =+X52+X66+X80+X87+X93 -> 5074.7969 | Y46: =+Y52+Y66+Y80+Y87+Y93 -> 3588.3477 | Z46: =+Z52+Z66+Z80+Z87+Z93 -> 3442.7788 | AA46: =SUM(W46:Z46) -> 20925.518 | AB46: =+AB52+AB66+AB80+AB87+AB93 -> 4275.9522 | AC46: =+AC52+AC66+AC80+AC87+AC93 -> 6860.1832 | AD46: =+AD52+AD66+AD80+AD87+AD93 -> 5696.2371 | AE46: =+AE52+AE66+AE80+AE87+AE93 -> 5957.3637 | AF46: =SUM(AB46:AE46) -> 22789.736 | AG46: =+AG52+AG66+AG80+AG87+AG93 -> 5527.3864 | AH46: =+AH52+AH66+AH80+AH87+AH93 -> 6317.1606 | AI46: =+AI52+AI66+AI80+AI87+AI93 -> 6489.2091 | AJ46: =+AJ52+AJ66+AJ80+AJ87+AJ93 -> 6448.6564 | AK46: =SUM(AG46:AJ46) -> 24782.413
B47: % yoy | L47: =IFERROR(L46/G46-1,"") -> 39.648721 | M47: =IFERROR(M46/H46-1,"") | N47: =IFERROR(N46/I46-1,"") | O47: =IFERROR(O46/J46-1,"") | P47: =IFERROR(P46/K46-1,"") | Q47: =IFERROR(Q46/L46-1,"") -> 1.9567427 | R47: =IFERROR(R46/M46-1,"") -> -0.19207146 | S47: =IFERROR(S46/N46-1,"") | ... AK47: =IFERROR(AK46/AF46-1,"") -> 0.087437445
B48: % qoq | M48: =IFERROR(M46/K46-1,"") | N48: =IFERROR(N46/M46-1,"") -> -1 | O48: =IFERROR(O46/N46-1,"") | P48: =IFERROR(P46/O46-1,"") | R48: =IFERROR(R46/P46-1,"") -> -0.55338922 | S48: =IFERROR(S46/R46-1,"") -> 0.74297532 | T48: =IFERROR(T46/S46-1,"") -> 0.33664765 | U48: =IFERROR(U46/T46-1,"") -> 1.5492185 | W48: =IFERROR(W46/U46-1,"") -> 0.055184723 | X48: =IFERROR(X46/W46-1,"") -> -0.42459977 | Y48: =IFERROR(Y46/X46-1,"") -> -0.29290811 | Z48: =IFERROR(Z46/Y46-1,"") -> -0.040567129 | AB48: =IFERROR(AB46/Z46-1,"") -> 0.2420061 | AC48: =IFERROR(AC46/AB46-1,"") -> 0.60436387 | AD48: =IFERROR(AD46/AC46-1,"") -> -0.16966692 | AE48: =IFERROR(AE46/AD46-1,"") -> 0.045841937 | AG48: =IFERROR(AG46/AE46-1,"") -> -0.072175757 | AH48: =IFERROR(AH46/AG46-1,"") -> 0.14288384 | AI48: =IFERROR(AI46/AH46-1,"") -> 0.027235094 | AJ48: =IFERROR(AJ46/AI46-1,"") -> -0.0062492386
B49: Net New CapEx (yoy) | P49: =P46-K46 -> 3151.198 | Q49: =Q46-L46 -> 5758.948 | R49: =R46-M46 -> -334.576 | S49: =S46-N46 -> 2452.992 | T49: =T46-O46 -> 3278.786 | U49: =U46-P46 -> 5207.144 | V49: =V46-Q46 -> 6795.401 | W49: =W46-R46 -> 7412.2358 | ... AK49: =AK46-AF46 -> 1992.6763
B50: Net New CapEx (qoq) | P50: =P46-O46 -> 3151.198 | R50: =R46-P46 -> -1743.839 | S50: =S46-R46 -> 1045.633 | T50: =T46-S46 -> 825.794 | U50: =U46-T46 -> 5079.556 | W50: =W46-U46 -> 461.25279 | X50: =X46-W46 -> -3744.7979 | Y50: =Y46-X46 -> -1486.4491 | Z50: =Z46-Y46 -> -145.56896 | AB50: =AB46-Z46 -> 833.17346 | AC50: =AC46-AB46 -> 2584.231 | AD50: =AD46-AC46 -> -1163.9461 | AE50: =AE46-AD46 -> 261.12654 | AG50: =AG46-AE46 -> -429.97723 | AH50: =AH46-AG46 -> 789.77419 | AI50: =AI46-AH46 -> 172.04846 | AJ50: =AJ46-AI46 -> -40.552616
...

Sheet KPI Summary
B2: CoreWeave, Inc.
B3: Fiscal Year Ends Dec. 31
B4: ($ millions, except per share amounts)
C6: =Dates!C3 -> 2022 (A) | H6: =Dates!H3 -> 2023 (A) | M6: =Dates!M3 -> 2024 (A) | R6: =Dates!R3 -> 2025 (E) | W6: =Dates!W3 -> 2026 (E) | AB6: =Dates!AB3 -> 2027 (E) | AG6: =Dates!AG3 -> 2028 (E)
C7: =Dates!C4 -> 1Q22 (A) | D7: =Dates!D4 -> 2Q22 (A) | E7: =Dates!E4 -> 3Q22 (A) | F7: =Dates!F4 -> 4Q22 (A) | G7: =Dates!G4 -> FY22 (A) | H7: =Dates!H4 -> 1Q23 (A) | I7: =Dates!I4 -> 2Q23 (A) | J7: =Dates!J4 -> 3Q23 (A) | ... AK7: =Dates!AK4 -> FY28 (E)
C8: =Dates!C5 -> 44651 | D8: =Dates!D5 -> 44742 | E8: =Dates!E5 -> 44834 | F8: =Dates!F5 -> 44926 | G8: =Dates!G5 -> 44926 | H8: =Dates!H5 -> 45016 | I8: =Dates!I5 -> 45107 | J8: =Dates!J5 -> 45199 | ... AK8: =Dates!AK5 -> 47118
A10: TREV | B10: Total Revenue | G10: ='Revenue and CapEx Build'!G10 -> 15.83 | H10: ='Revenue and CapEx Build'!H10 -> 7.9236843 | I10: ='Revenue and CapEx Build'!I10 -> 29.8436 | J10: ='Revenue and CapEx Build'!J10 -> 75.178825 | K10: ='Revenue and CapEx Build'!K10 -> 115.99689 | L10: ='Revenue and CapEx Build'!L10 -> 228.943 | M10: ='Revenue and CapEx Build'!M10 -> 188.684 | N10: ='Revenue and CapEx Build'!N10 -> 395.371 | ... AK10: ='Revenue and CapEx Build'!AK10 -> 21655.089
A11: TREVYY | B11: % yoy | H11: =IFERROR(H10/C10-1,"") | I11: =IFERROR(I10/D10-1,"") | J11: =IFERROR(J10/E10-1,"") | K11: =IFERROR(K10/F10-1,"") | L11: =IFERROR(L10/G10-1,"") -> 13.462603 | M11: =IFERROR(M10/H10-1,"") -> 22.81266 | N11: =IFERROR(N10/I10-1,"") -> 12.2481 | O11: =IFERROR(O10/J10-1,"") -> 6.76736 | ... AK11: =IFERROR(AK10/AF10-1,"") -> 0.25822019
A12: TREVQQ | B12: % qoq | H12: =IFERROR(H10/F10-1,"") | I12: =IFERROR(I10/H10-1,"") -> 2.7663793 | J12: =IFERROR(J10/I10-1,"") -> 1.5190937 | K12: =IFERROR(K10/J10-1,"") -> 0.5429463 | M12: =IFERROR(M10/K10-1,"") -> 0.62662981 | N12: =IFERROR(N10/M10-1,"") -> 1.0954135 | O12: =IFERROR(O10/N10-1,"") -> 0.47694444 | P12: =IFERROR(P10/O10-1,"") -> 0.2799752 | R12: =IFERROR(R10/P10-1,"") -> 0.31334306 | S12: =IFERROR(S10/R10-1,"") -> 0.23548132 | T12: =IFERROR(T10/S10-1,"") -> 0.12523871 | U12: =IFERROR(U10/T10-1,"") -> 0.13058326 | W12: =IFERROR(W10/U10-1,"") -> 0.44348713 | X12: =IFERROR(X10/W10-1,"") -> 0.33094883 | Y12: =IFERROR(Y10/X10-1,"") -> 0.10980793 | Z12: =IFERROR(Z10/Y10-1,"") -> 0.070204816 | AB12: =IFERROR(AB10/Z10-1,"") -> 0.082649169 | AC12: =IFERROR(AC10/AB10-1,"") -> 0.089818799 | AD12: =IFERROR(AD10/AC10-1,"") -> 0.077002222 | AE12: =IFERROR(AE10/AD10-1,"") -> 0.066529754 | AG12: =IFERROR(AG10/AE10-1,"") -> 0.072718069 | AH12: =IFERROR(AH10/AG10-1,"") -> 0.041288386 | AI12: =IFERROR(AI10/AH10-1,"") -> 0.035552396 | AJ12: =IFERROR(AJ10/AI10-1,"") -> 0.030497879
B13: Net New Revenue (yoy) | H13: ='Revenue and CapEx Build'!H13 -> 7.9236843 | I13: ='Revenue and CapEx Build'!I13 -> 29.8436 | J13: ='Revenue and CapEx Build'!J13 -> 75.178825 | K13: ='Revenue and CapEx Build'!K13 -> 115.99689 | L13: ='Revenue and CapEx Build'!L13 -> 213.113 | M13: ='Revenue and CapEx Build'!M13 -> 180.76032 | N13: ='Revenue and CapEx Build'!N13 -> 365.5274 | O13: ='Revenue and CapEx Build'!O13 -> 508.76217 | ... AK13: ='Revenue and CapEx Build'!AK13 -> 4444.1993
B14: Net New Revenue (qoq) | H14: ='Revenue and CapEx Build'!H14 -> 7.9236843 | I14: ='Revenue and CapEx Build'!I14 -> 21.919916 | J14: ='Revenue and CapEx Build'!J14 -> 45.335225 | K14: ='Revenue and CapEx Build'!K14 -> 40.818065 | L14: ='Revenue and CapEx Build'!L14 -> 0 | M14: ='Revenue and CapEx Build'!M14 -> 72.68711 | N14: ='Revenue and CapEx Build'!N14 -> 206.687 | O14: ='Revenue and CapEx Build'!O14 -> 188.57 | ... AK14: ='Revenue and CapEx Build'!AK14 -> 0
B16: Revenue / Average Net Assets | O16: ='Revenue and CapEx Build'!O16 -> 0.086095277 | P16: ='Revenue and CapEx Build'!P16 -> 0.097257296 | Q16: ='Revenue and CapEx Build'!Q16 -> 0 | R16: ='Revenue and CapEx Build'!R16 -> 0.10414591 | S16: ='Revenue and CapEx Build'!S16 -> 0.1070543 | T16: ='Revenue and CapEx Build'!T16 -> 0.10389865 | U16: ='Revenue and CapEx Build'!U16 -> 0.0976 | V16: ='Revenue and CapEx Build'!V16 -> 0.10317472 | ... AK16: ='Revenue and CapEx Build'!AK16 -> 0.108
B17: Revenue / Average Net Assets, Annualized | O17: ='Revenue and CapEx Build'!O17 -> 0.34438111 | P17: ='Revenue and CapEx Build'!P17 -> 0.38902918 | Q17: ='Revenue and CapEx Build'!Q17 -> 0 | R17: ='Revenue and CapEx Build'!R17 -> 0.41658366 | S17: ='Revenue and CapEx Build'!S17 -> 0.42821721 | T17: ='Revenue and CapEx Build'!T17 -> 0.4155946 | U17: ='Revenue and CapEx Build'!U17 -> 0.3904 | V17: ='Revenue and CapEx Build'!V17 -> 0 | ... AK17: ='Revenue and CapEx Build'!AK17 -> 0
B18: Revenue / Average Gross Assets | O18: ='Revenue and CapEx Build'!O18 -> 0.080338949 | P18: ='Revenue and CapEx Build'!P18 -> 0.088204788 | Q18: ='Revenue and CapEx Build'!Q18 -> 0 | R18: ='Revenue and CapEx Build'!R18 -> 0.092537485 | S18: ='Revenue and CapEx Build'!S18 -> 0.093253366 | T18: ='Revenue and CapEx Build'!T18 -> 0.088622363 | U18: ='Revenue and CapEx Build'!U18 -> 0.082175834 | V18: ='Revenue and CapEx Build'!V18 -> 0 | ... AK18: ='Revenue and CapEx Build'!AK18 -> 0
B20: Revenue from Customer Commitments
B21: Committed Contracts Revenue | G21: =G$10*G24 -> 3.166 | J21: =J$10*J24 -> 63.150213 | L21: =L$10*L24 -> 201.46984 | M21: =M$10*M24 -> 177.36296 | O21: =O$10*O24 -> 554.74395 | Q21: =Q$10*Q24 -> 1838.809 | R21: =R$10*R24 -> 961.99936
B22: % yoy | H22: =IFERROR(H21/C21-1,"") | I22: =IFERROR(I21/D21-1,"") | J22: =IFERROR(J21/E21-1,"") | L22: =IFERROR(L21/G21-1,"") -> 62.635452 | M22: =IFERROR(M21/H21-1,"") | N22: =IFERROR(N21/I21-1,"") | O22: =IFERROR(O21/J21-1,"") -> 7.7845143 | Q22: =IFERROR(Q21/L21-1,"") -> 8.1269689 | R22: =IFERROR(R21/M21-1,"") -> 4.4239023
B23: % qoq | H23: =IFERROR(H21/F21-1,"") | I23: =IFERROR(I21/H21-1,"") | J23: =IFERROR(J21/I21-1,"") | M23: =IFERROR(M21/K21-1,"") | O23: =IFERROR(O21/N21-1,"")
B24: % of Total Revenue | G24: 0.2 | J24: 0.84 | L24: 0.88 | M24: 0.94 | O24: 0.95 | Q24: 0.96 | R24: 0.98
B26: On-Demand Services Revenue | G26: =G$10*G29 -> 12.664 | J26: =J$10*J29 -> 12.028612 | L26: =L$10*L29 -> 27.47316 | M26: =M$10*M29 -> 11.32104 | O26: =O$10*O29 -> 29.19705 | Q26: =Q$10*Q29 -> 76.61704 | R26: =R$10*R29 -> 19.63264 | S26: =S$10*S29 -> 1212.788 | T26: =T$10*T29 -> 1364.676
B27: % yoy | H27: =IFERROR(H26/C26-1,"") | I27: =IFERROR(I26/D26-1,"") | J27: =IFERROR(J26/E26-1,"") | L27: =IFERROR(L26/G26-1,"") -> 1.1693904 | M27: =IFERROR(M26/H26-1,"") | N27: =IFERROR(N26/I26-1,"") | O27: =IFERROR(O26/J26-1,"") -> 1.4273 | Q27: =IFERROR(Q26/L26-1,"") -> 1.788796 | R27: =IFERROR(R26/M26-1,"") -> 0.73417283 | S27: =IFERROR(S26/N26-1,"") | T27: =IFERROR(T26/O26-1,"") -> 45.740201
B28: % qoq | H28: =IFERROR(H26/F26-1,"") | I28: =IFERROR(I26/H26-1,"") | J28: =IFERROR(J26/I26-1,"") | O28: =IFERROR(O26/N26-1,"") | R28: =IFERROR(R26/Q26-1,"") -> -0.74375622 | S28: =IFERROR(S26/R26-1,"") -> 60.774066 | T28: =IFERROR(T26/S26-1,"") -> 0.12523871
B29: % of Total Revenue | G29: =1-G24 -> 0.8 | J29: =1-J24 -> 0.16 | L29: =1-L24 -> 0.12 | M29: =1-M24 -> 0.06 | O29: =1-O24 -> 0.05 | Q29: =1-Q24 -> 0.04 | R29: =1-R24 -> 0.02 | S29: =1-S24 -> 1 | T29: =1-T24 -> 1
B31: Remaining Performance Obligations
A32: RPO | B32: RPO | K32: 9900 | L32: =K32 -> 9900 | M32: 15911.178 | N32: 16200 | O32: 15000 | P32: 15100 | Q32: =P32 -> 15100 | R32: 14665.098 | S32: 30100 | T32: 50000
A33: RPOYY | B33: % yoy | H33: =IFERROR(H32/C32-1,"") | I33: =IFERROR(I32/D32-1,"") | J33: =IFERROR(J32/E32-1,"") | M33: =IFERROR(M32/H32-1,"") | N33: =IFERROR(N32/I32-1,"") | O33: =IFERROR(O32/J32-1,"") | P33: =IFERROR(P32/K32-1,"") -> 0.52525253 | Q33: =Q32/L32-1 -> 0.52525253 | R33: =IFERROR(R32/M32-1,"") -> -0.078314755 | S33: =IFERROR(S32/N32-1,"") -> 0.85802469 | T33: =IFERROR(T32/O32-1,"") -> 2.3333333
A34: RPOQQ | B34: % qoq | H34: =IFERROR(H32/F32-1,"") | I34: =IFERROR(I32/H32-1,"") | J34: =IFERROR(J32/I32-1,"") | K34: =IFERROR(K32/J32-1,"") | M34: =IFERROR(M32/K32-1,"") -> 0.6071897 | O34: =IFERROR(O32/N32-1,"") -> -0.074074074 | P34: =P32/O32-1 -> 0.0066666667 | R34: =R32/Q32-1 -> -0.028801457 | S34: =S32/R32-1 -> 1.0524923 | T34: =T32/S32-1 -> 0.66112957
A36: 24MCRPO | B36: 24-Month cRPO | K36: =K32*K39 -> 4059 | L36: =K36 -> 4059 | N36: =N32*N39 -> 7290 | O36: =O32*O39 -> 7500 | P36: =P32*P39 -> 8154 | Q36: =P36 -> 8154 | R36: =R32*R39 -> 8505.7568 | S36: =S32*S39 -> 15050 | T36: =T32*T39 -> 20000
A37: 24MCRPOYY | B37: % yoy | H37: =IFERROR(H36/C36-1,"") | I37: =IFERROR(I36/D36-1,"") | J37: =IFERROR(J36/E36-1,"") | M37: =IFERROR(M36/H36-1,"") | N37: =IFERROR(N36/I36-1,"") | O37: =IFERROR(O36/J36-1,"") | Q37: =Q36/L36-1 -> 1.0088692
A38: 24MCRPOQQ | B38: % qoq | H38: =IFERROR(H36/F36-1,"") | I38: =IFERROR(I36/H36-1,"") | J38: =IFERROR(J36/I36-1,"") | N38: =IFERROR(N36/M36-1,"") | O38: =IFERROR(O36/N36-1,"") -> 0.028806584 | P38: =P36/O36-1 -> 0.0872 | R38: =R36/Q36-1 -> 0.043139176 | S38: =S36/R36-1 -> 0.76938987 | T38: =T36/S36-1 -> 0.32890365
B39: % of Total RPO | K39: 0.41 | L39: =K39 -> 0.41 | N39: 0.45 | O39: 0.5 | P39: 0.54 | Q39: =P39 -> 0.54 | R39: 0.58 | S39: 0.5 | T39: 0.4
B41: Next 24-Month Revenue (GSe) | K41: =SUM(M10:P10,R10:U10) -> 7017.4018 | L41: =Q10+V10 -> 7017.4018 | M41: =SUM(N10:P10,R10:U10,W10) -> 9055.845 | N41: =SUM(O10:P10,R10:U10,W10:X10) -> 11624.666 | O41: =SUM(P10,R10:U10,W10:Y10) -> 14330.409 | P41: =SUM(R10:U10,W10:Z10) -> 17103.615 | Q41: =V10+AA10 -> 17103.615 | R41: =SUM(S10:U10,W10:Z10,AB10) -> 19933.597 | S41: =SUM(T10:U10,W10:Z10,AB10:AC10) -> 22874.777 | T41: =SUM(U10:V10,X10:AA10,AC10:AD10) -> 37048.808
B42: Assumed non-Contracted Revenue to be Added | K42: =K41-K36 -> 2958.4018 | L42: =K42 -> 2958.4018 | N42: =N41-N36 -> 4334.6664 | O42: =O41-O36 -> 6830.4095 | P42: =P41-P36 -> 8949.6153 | Q42: =P42 -> 8949.6153 | R42: =R41-R36 -> 11427.84 | S42: =S41-S36 -> 7824.7767 | T42: =T41-T36 -> 17048.808
B43: % N24M Covered by cRPO | K43: =(K41-K42)/K41 -> 0.57841921 | L43: =K43 -> 0.57841921 | N43: =(N41-N42)/N41 -> 0.62711477 | O43: =(O41-O42)/O41 -> 0.52336257 | P43: =(P41-P42)/P41 -> 0.47674131 | Q43: =P43 -> 0.47674131 | R43: =(R41-R42)/R41 -> 0.42670457 | S43: =(S41-S42)/S41 -> 0.65792992 | T43: =(T41-T42)/T41 -> 0.53982843
A45: 24MCRPO | B45: 25 to 48-Month cRPO | K45: =K$32*K48 -> 3960 | L45: =K45 -> 3960 | N45: =N$32*N48 -> 6480 | P45: =P$32*P48 -> 6342 | Q45: =P45 -> 6342 | R45: =R$32*R48 -> 5866.0392 | S45: =S$32*S48 -> 12040 | T45: =T$32*T48 -> 19500
A46: 24MCRPOYY | B46: % yoy | H46: =IFERROR(H45/C45-1,"") | I46: =IFERROR(I45/D45-1,"") | J46: =IFERROR(J45/E45-1,"") | P46: =P45/K45-1 -> 0.60151515 | Q46: =Q45/L45-1 -> 0.60151515
A47: 24MCRPOQQ | B47: % qoq | H47: =IFERROR(H45/F45-1,"") | I47: =IFERROR(I45/H45-1,"") | J47: =IFERROR(J45/I45-1,"") | R47: =R45/Q45-1 -> -0.075049007 | S47: =S45/R45-1 -> 1.0524923 | T47: =T45/S45-1 -> 0.61960133
B48: % of Total RPO | K48: 0.4 | L48: =K48 -> 0.4 | N48: 0.4 | P48: 0.42 | Q48: =P48 -> 0.42 | R48: 0.4 | S48: 0.4 | T48: 0.39
A50: RPO | B50: Backlog (non-GAAP metric) | M50: 15911.178 | N50: 16200 | R50: 25856.694 | S50: 30100 | T50: 55600
A51: RPOYY | B51: % yoy | H51: =IFERROR(H50/C50-1,"") | I51: =IFERROR(I50/D50-1,"") | J51: =IFERROR(J50/E50-1,"") | K51: =IFERROR(K50/F50-1,"") | R51: =R50/M50-1 -> 0.62506472 | S51: =S50/N50-1 -> 0.85802469
...

Sheet Depreciation Build
B2: CoreWeave, Inc.
B3: Fiscal Year Ends Dec. 31
B4: ($ millions, except per share amounts)
C6: =Dates!C3 -> 2022 (A) | H6: =Dates!H3 -> 2023 (A) | M6: =Dates!M3 -> 2024 (A) | R6: =Dates!R3 -> 2025 (E) | W6: =Dates!W3 -> 2026 (E) | AB6: =Dates!AB3 -> 2027 (E) | AG6: =Dates!AG3 -> 2028 (E)
C7: =Dates!C4 -> 1Q22 (A) | D7: =Dates!D4 -> 2Q22 (A) | E7: =Dates!E4 -> 3Q22 (A) | F7: =Dates!F4 -> 4Q22 (A) | G7: =Dates!G4 -> FY22 (A) | H7: =Dates!H4 -> 1Q23 (A) | I7: =Dates!I4 -> 2Q23 (A) | J7: =Dates!J4 -> 3Q23 (A) | ... AK7: =Dates!AK4 -> FY28 (E)
C8: =Dates!C5 -> 44651 | D8: =Dates!D5 -> 44742 | E8: =Dates!E5 -> 44834 | F8: =Dates!F5 -> 44926 | G8: =Dates!G5 -> 44926 | H8: =Dates!H5 -> 45016 | I8: =Dates!I5 -> 45107 | J8: =Dates!J5 -> 45199 | ... AK8: =Dates!AK5 -> 47118
B9: Metrics
A10: TREV | B10: Total Revenue | G10: ='Revenue and CapEx Build'!G10 -> 15.83 | H10: ='Revenue and CapEx Build'!H10 -> 7.9236843 | I10: ='Revenue and CapEx Build'!I10 -> 29.8436 | J10: ='Revenue and CapEx Build'!J10 -> 75.178825 | K10: ='Revenue and CapEx Build'!K10 -> 115.99689 | L10: ='Revenue and CapEx Build'!L10 -> 228.943 | M10: ='Revenue and CapEx Build'!M10 -> 188.684 | N10: ='Revenue and CapEx Build'!N10 -> 395.371 | ... AK10: ='Revenue and CapEx Build'!AK10 -> 21655.089
A11: TREVYY | B11: % yoy | H11: =IFERROR(H10/C10-1,"") | I11: =IFERROR(I10/D10-1,"") | J11: =IFERROR(J10/E10-1,"") | K11: =IFERROR(K10/F10-1,"") | L11: =IFERROR(L10/G10-1,"") -> 13.462603 | M11: =IFERROR(M10/H10-1,"") -> 22.81266 | N11: =IFERROR(N10/I10-1,"") -> 12.2481 | O11: =IFERROR(O10/J10-1,"") -> 6.76736 | ... AK11: =IFERROR(AK10/AF10-1,"") -> 0.25822019
A12: TREVQQ | B12: % qoq | H12: =IFERROR(H10/F10-1,"") | I12: =IFERROR(I10/H10-1,"") -> 2.7663793 | J12: =IFERROR(J10/I10-1,"") -> 1.5190937 | K12: =IFERROR(K10/J10-1,"") -> 0.5429463 | M12: =IFERROR(M10/K10-1,"") -> 0.62662981 | N12: =IFERROR(N10/M10-1,"") -> 1.0954135 | O12: =IFERROR(O10/N10-1,"") -> 0.47694444 | P12: =IFERROR(P10/O10-1,"") -> 0.2799752 | R12: =IFERROR(R10/P10-1,"") -> 0.31334306 | S12: =IFERROR(S10/R10-1,"") -> 0.23548132 | T12: =IFERROR(T10/S10-1,"") -> 0.12523871 | U12: =IFERROR(U10/T10-1,"") -> 0.13058326 | W12: =IFERROR(W10/U10-1,"") -> 0.44348713 | X12: =IFERROR(X10/W10-1,"") -> 0.33094883 | Y12: =IFERROR(Y10/X10-1,"") -> 0.10980793 | Z12: =IFERROR(Z10/Y10-1,"") -> 0.070204816 | AB12: =IFERROR(AB10/Z10-1,"") -> 0.082649169 | AC12: =IFERROR(AC10/AB10-1,"") -> 0.089818799 | AD12: =IFERROR(AD10/AC10-1,"") -> 0.077002222 | AE12: =IFERROR(AE10/AD10-1,"") -> 0.066529754 | AG12: =IFERROR(AG10/AE10-1,"") -> 0.072718069 | AH12: =IFERROR(AH10/AG10-1,"") -> 0.041288386 | AI12: =IFERROR(AI10/AH10-1,"") -> 0.035552396 | AJ12: =IFERROR(AJ10/AI10-1,"") -> 0.030497879
B14: Total CapEx (Including CIP) | F14: ='Revenue and CapEx Build'!F46 -> 0 | G14: ='Revenue and CapEx Build'!G46 -> 72.404 | H14: ='Revenue and CapEx Build'!H46 -> 0 | I14: ='Revenue and CapEx Build'!I46 -> 0 | J14: ='Revenue and CapEx Build'!J46 -> 0 | K14: ='Revenue and CapEx Build'!K46 -> 0 | L14: ='Revenue and CapEx Build'!L46 -> 2943.13 | M14: ='Revenue and CapEx Build'!M46 -> 1741.935 | ... AK14: ='Revenue and CapEx Build'!AK46 -> 24782.413
B15: % yoy | M15: =IFERROR(M14/H14-1,"") | N15: =IFERROR(N14/I14-1,"") | O15: =IFERROR(O14/J14-1,"") | P15: =IFERROR(P14/K14-1,"") | Q15: =IFERROR(Q14/L14-1,"") -> 1.9567427 | R15: =IFERROR(R14/M14-1,"") -> -0.19207146 | S15: =IFERROR(S14/N14-1,"") | T15: =IFERROR(T14/O14-1,"") | ... AK15: =IFERROR(AK14/AF14-1,"") -> 0.087437445
B16: % qoq | R16: =IFERROR(R14/P14-1,"") -> -0.55338922 | S16: =IFERROR(S14/R14-1,"") -> 0.74297532 | T16: =IFERROR(T14/S14-1,"") -> 0.33664765 | U16: =IFERROR(U14/T14-1,"") -> 1.5492185 | W16: =IFERROR(W14/U14-1,"") -> 0.055184723 | X16: =IFERROR(X14/W14-1,"") -> -0.42459977 | Y16: =IFERROR(Y14/X14-1,"") -> -0.29290811 | Z16: =IFERROR(Z14/Y14-1,"") -> -0.040567129 | AB16: =IFERROR(AB14/Z14-1,"") -> 0.2420061 | AC16: =IFERROR(AC14/AB14-1,"") -> 0.60436387 | AD16: =IFERROR(AD14/AC14-1,"") -> -0.16966692 | AE16: =IFERROR(AE14/AD14-1,"") -> 0.045841937 | AG16: =IFERROR(AG14/AE14-1,"") -> -0.072175757 | AH16: =IFERROR(AH14/AG14-1,"") -> 0.14288384 | AI16: =IFERROR(AI14/AH14-1,"") -> 0.027235094 | AJ16: =IFERROR(AJ14/AI14-1,"") -> -0.0062492386
B18: CapEx (Fixed Assets) | M18: 1200 | N18: 1900 | O18: =Q18-P18-N18-M18 -> 2679.4319 | P18: ='Revenue and CapEx Build'!P52 -> 2340.018 | Q18: ='Revenue and CapEx Build'!Q52 -> 8119.4499 | R18: ='Revenue and CapEx Build'!R52 -> 483.104 | S18: ='Revenue and CapEx Build'!S52 -> 2359.475 | T18: ='Revenue and CapEx Build'!T52 -> 382.361 | U18: ='Revenue and CapEx Build'!U52 -> 4758.361 | V18: ='Revenue and CapEx Build'!V52 -> 7983.301 | W18: ='Revenue and CapEx Build'!W52 -> 10758.361 | ... AK18: ='Revenue and CapEx Build'!AK52 -> 18033.444
B19: % yoy | M19: =IFERROR(M18/H18-1,"") | N19: =IFERROR(N18/I18-1,"") | O19: =IFERROR(O18/J18-1,"") | P19: =IFERROR(P18/K18-1,"") | Q19: =IFERROR(Q18/L18-1,"") | R19: =IFERROR(R18/M18-1,"") -> -0.59741333 | S19: =IFERROR(S18/N18-1,"") -> 0.24182895 | T19: =IFERROR(T18/O18-1,"") -> -0.85729774 | ... AK19: =IFERROR(AK18/AF18-1,"") -> -0.099833059
B20: % qoq | R20: =IFERROR(R18/P18-1,"") -> -0.79354689 | S20: =IFERROR(S18/R18-1,"") -> 3.8839898 | T20: =IFERROR(T18/S18-1,"") -> -0.83794658 | U20: =IFERROR(U18/T18-1,"") -> 11.444682 | W20: =IFERROR(W18/U18-1,"") -> 1.2609384 | X20: =IFERROR(X18/W18-1,"") -> -0.55770577 | Y20: =IFERROR(Y18/X18-1,"") -> -0.36777369 | Z20: =IFERROR(Z18/Y18-1,"") -> 0 | AB20: =IFERROR(AB18/Z18-1,"") -> 0.66481383 | AC20: =IFERROR(AC18/AB18-1,"") -> 0 | AD20: =IFERROR(AD18/AC18-1,"") -> 0 | AE20: =IFERROR(AE18/AD18-1,"") -> 0 | AG20: =IFERROR(AG18/AE18-1,"") -> -0.099833059 | AH20: =IFERROR(AH18/AG18-1,"") -> 0 | AI20: =IFERROR(AI18/AH18-1,"") -> 0 | AJ20: =IFERROR(AJ18/AI18-1,"") -> 0
B22: Depreciation and Amortization
B23: Total Depreciation and Amortization (from C/F) | G23: =CF!G14 -> 11.695 | H23: =CF!H14 -> 0 | I23: =CF!I14 -> 0 | J23: =CF!J14 -> 0 | K23: =CF!K14 -> 0 | L23: =CF!L14 -> 103.21 | M23: =CF!M14 -> 79.51 | N23: =CF!N14 -> 164.46 | ... T23: =CF!T14 -> 630.479 | U23: =U28+U39 -> 785.14888 | V23: =V28+V39 -> 2123.8544 | W23: =W28+W39 -> 1175.5895 | X23: =X28+X39 -> 1380.678 | Y23: =Y28+Y39 -> 1513.2448 | Z23: =Z28+Z39 -> 1646.1934 | AA23: =AA28+AA39 -> 5715.7057 | AB23: =AB28+AB39 -> 1863.3324 | ... AK23: =AK28+AK39 -> 12018.204
B24: % yoy | M24: =IFERROR(M23/H23-1,"") | N24: =IFERROR(N23/I23-1,"") | O24: =IFERROR(O23/J23-1,"") | P24: =IFERROR(P23/K23-1,"") | Q24: =IFERROR(Q23/L23-1,"") -> 7.3655944 | R24: =IFERROR(R23/M23-1,"") -> 4.577877 | S24: =IFERROR(S23/N23-1,"") -> 2.4019275 | T24: =IFERROR(T23/O23-1,"") -> 1.4819663 | ... AK24: =IFERROR(AK23/AF23-1,"") -> 0.37155393
B25: % qoq | M25: =IFERROR(M23/K23-1,"") | N25: =IFERROR(N23/M23-1,"") -> 1.0684191 | O25: =IFERROR(O23/N23-1,"") -> 0.54459443 | P25: =IFERROR(P23/O23-1,"") -> 0.43852156 | R25: =IFERROR(R23/P23-1,"") -> 0.21366705 | S25: =IFERROR(S23/R23-1,"") -> 0.2615215 | T25: =IFERROR(T23/S23-1,"") -> 0.12689975 | U25: =IFERROR(U23/T23-1,"") -> 0.24532122 | W25: =IFERROR(W23/U23-1,"") -> 0.49728224 | X25: =IFERROR(X23/W23-1,"") -> 0.17445595 | Y25: =IFERROR(Y23/X23-1,"") -> 0.096015677 | Z25: =IFERROR(Z23/Y23-1,"") -> 0.087856643 | AB25: =IFERROR(AB23/Z23-1,"") -> 0.13190369 | AC25: =IFERROR(AC23/AB23-1,"") -> 0.11708688 | AD25: =IFERROR(AD23/AC23-1,"") -> 0.10462308 | AE25: =IFERROR(AE23/AD23-1,"") -> 0.095282643 | AG25: =IFERROR(AG23/AE23-1,"") -> 0.074157272 | AH25: =IFERROR(AH23/AG23-1,"") -> 0.073911359 | AI25: =IFERROR(AI23/AH23-1,"") -> 0.068428497 | AJ25: =IFERROR(AJ23/AI23-1,"") -> 0.064551646
B26: % of Revenue | G26: =IFERROR(G23/G$10,"") -> 0.73878711 | H26: =IFERROR(H23/H$10,"") -> 0 | I26: =IFERROR(I23/I$10,"") -> 0 | J26: =IFERROR(J23/J$10,"") -> 0 | K26: =IFERROR(K23/K$10,"") -> 0 | L26: =IFERROR(L23/L$10,"") -> 0.4508109 | M26: =IFERROR(M23/M$10,"") -> 0.42139238 | N26: =IFERROR(N23/N$10,"") -> 0.41596374 | ... AK26: =IFERROR(AK23/AK$10,"") -> 0.55498289
B28: Fixed Asset Depreciation | M28: ='Revenue and CapEx Build'!M106 -> 79 | N28: ='Revenue and CapEx Build'!N106 -> 164 | O28: ='Revenue and CapEx Build'!O106 -> 253 | P28: ='Revenue and CapEx Build'!P106 -> 357.527 | Q28: ='Revenue and CapEx Build'!Q106 -> 853.527 | R28: ='Revenue and CapEx Build'!R106 -> 443 | S28: ='Revenue and CapEx Build'!S106 -> 553 | T28: ='Revenue and CapEx Build'!T106 -> 621 | U28: 760 | V28: =V58 -> 2059.8218 | W28: =W58 -> 1144.463 | X28: =X58 -> 1342.728 | Y28: =Y58 -> 1468.0764 | Z28: =Z58 -> 1593.4248 | AA28: =AA58 -> 5548.6922 | AB28: =AB58 -> 1802.1065 | AC28: =AC58 -> 2010.7882 | ... AK28: =AK58 -> 11580.09
B29: % yoy | M29: =IFERROR(M28/H28-1,"") | N29: =IFERROR(N28/I28-1,"") | O29: =IFERROR(O28/J28-1,"") | P29: =IFERROR(P28/K28-1,"") | Q29: =IFERROR(Q28/L28-1,"") | R29: =IFERROR(R28/M28-1,"") -> 4.6075949 | S29: =IFERROR(S28/N28-1,"") -> 2.3719512 | T29: =IFERROR(T28/O28-1,"") -> 1.4545455 | ... AK29: =IFERROR(AK28/AF28-1,"") -> 0.36872147
B30: % qoq | M30: =IFERROR(M28/K28-1,"") | N30: =IFERROR(N28/M28-1,"") -> 1.0759494 | O30: =IFERROR(O28/N28-1,"") -> 0.54268293 | P30: =IFERROR(P28/O28-1,"") -> 0.4131502 | R30: =IFERROR(R28/P28-1,"") -> 0.23906726 | S30: =IFERROR(S28/R28-1,"") -> 0.248307 | T30: =IFERROR(T28/S28-1,"") -> 0.12296564 | U30: =IFERROR(U28/T28-1,"") -> 0.22383253 | W30: =IFERROR(W28/U28-1,"") -> 0.50587236 | X30: =IFERROR(X28/W28-1,"") -> 0.17323849 | Y30: =IFERROR(Y28/X28-1,"") -> 0.09335351 | Z30: =IFERROR(Z28/Y28-1,"") -> 0.085382732 | AB30: =IFERROR(AB28/Z28-1,"") -> 0.13096427 | AC30: =IFERROR(AC28/AB28-1,"") -> 0.11579877 | AD30: =IFERROR(AD28/AC28-1,"") -> 0.10378105 | AE30: =IFERROR(AE28/AD28-1,"") -> 0.09402322 | AG30: =IFERROR(AG28/AE28-1,"") -> 0.076230155 | AH30: =IFERROR(AH28/AG28-1,"") -> 0.071883048 | AI30: =IFERROR(AI28/AH28-1,"") -> 0.067062398 | AJ30: =IFERROR(AJ28/AI28-1,"") -> 0.062847682
B31: % of Revenue | G31: =IFERROR(G28/G$10,"") -> 0 | H31: =IFERROR(H28/H$10,"") -> 0 | I31: =IFERROR(I28/I$10,"") -> 0 | J31: =IFERROR(J28/J$10,"") -> 0 | K31: =IFERROR(K28/K$10,"") -> 0 | L31: =IFERROR(L28/L$10,"") -> 0 | M31: =IFERROR(M28/M$10,"") -> 0.41868945 | N31: =IFERROR(N28/N$10,"") -> 0.41480028 | ... AK31: =IFERROR(AK28/AK$10,"") -> 0.53475144
B33: T&I Depreciation | G33: 11 | L33: 101 | M33: 77 | N33: 158 | O33: 256 | P33: =Q33-O33-N33-M33 -> 352 | Q33: 843 | R33: 429 | S33: 537 | T33: 349 | U33: =U28*U37 -> 427.11755 | V33: =SUM(R33:U33) -> 1742.1176 | W33: =W28*W37 -> 643.18452 | X33: =X28*X37 -> 754.60883 | Y33: =Y28*Y37 -> 825.05422 | Z33: =Z28*Z37 -> 895.4996 | AA33: =SUM(W33:Z33) -> 3118.3472 | AB33: =AB28*AB37 -> 1012.778 | AC33: =AC28*AC37 -> 1130.0565 | AD33: =AD28*AD37 -> 1247.3349 | AE33: =AE28*AE37 -> 1364.6134 | AF33: =SUM(AB33:AE33) -> 4754.7829 | AG33: =AG28*AG37 -> 1468.6381 | AH33: =AH28*AH37 -> 1574.2083 | AI33: =AI28*AI37 -> 1679.7784 | AJ33: =AJ28*AJ37 -> 1785.3486 | AK33: =SUM(AG33:AJ33) -> 6507.9734
B34: % yoy | M34: =IFERROR(M33/H33-1,"") | N34: =IFERROR(N33/I33-1,"") | O34: =IFERROR(O33/J33-1,"") | P34: =IFERROR(P33/K33-1,"") | Q34: =IFERROR(Q33/L33-1,"") -> 7.3465347 | R34: =IFERROR(R33/M33-1,"") -> 4.5714286 | S34: =IFERROR(S33/N33-1,"") -> 2.3987342 | T34: =IFERROR(T33/O33-1,"") -> 0.36328125 | ... AK34: =IFERROR(AK33/AF33-1,"") -> 0.36872147
B35: % qoq | M35: =IFERROR(M33/K33-1,"") | N35: =IFERROR(N33/M33-1,"") -> 1.0519481 | O35: =IFERROR(O33/N33-1,"") -> 0.62025316 | P35: =IFERROR(P33/O33-1,"") -> 0.375 | R35: =IFERROR(R33/P33-1,"") -> 0.21875 | S35: =IFERROR(S33/R33-1,"") -> 0.25174825 | T35: =IFERROR(T33/S33-1,"") -> -0.35009311 | U35: =IFERROR(U33/T33-1,"") -> 0.22383253 | W35: =IFERROR(W33/U33-1,"") -> 0.50587236 | X35: =IFERROR(X33/W33-1,"") -> 0.17323849 | Y35: =IFERROR(Y33/X33-1,"") -> 0.09335351 | Z35: =IFERROR(Z33/Y33-1,"") -> 0.085382732 | AB35: =IFERROR(AB33/Z33-1,"") -> 0.13096427 | AC35: =IFERROR(AC33/AB33-1,"") -> 0.11579877 | AD35: =IFERROR(AD33/AC33-1,"") -> 0.10378105 | AE35: =IFERROR(AE33/AD33-1,"") -> 0.09402322 | AG35: =IFERROR(AG33/AE33-1,"") -> 0.076230155 | AH35: =IFERROR(AH33/AG33-1,"") -> 0.071883048 | AI35: =IFERROR(AI33/AH33-1,"") -> 0.067062398 | AJ35: =IFERROR(AJ33/AI33-1,"") -> 0.062847682
B36: Implied Other Depreciation | G36: =G23-G33 -> 0.695 | L36: =L23-L33 -> 2.21 | M36: =M23-M33 -> 2.51 | Q36: =Q23-Q33 -> 20.413 | R36: =R23-R33 -> 14.497 | S36: =S23-S33 -> 22.481 | T36: =T23-T33 -> 281.479 | U36: =U23-U33 -> 358.03132 | V36: =V23-V33 -> 381.73681 | W36: =W23-W33 -> 532.40495 | X36: =X23-X33 -> 626.06921 | ... AK36: =AK23-AK33 -> 5510.2305
B37: % of Fixed Asset Depreciation | M37: =M33/M28 -> 0.97468354 | N37: =N33/N28 -> 0.96341463 | O37: =O33/O28 -> 1.0118577 | P37: =P33/P28 -> 0.98454103 | Q37: =Q33/Q28 -> 0.98766647 | R37: =R33/R28 -> 0.96839729 | S37: =S33/S28 -> 0.97106691 | T37: =T33/T28 -> 0.56199678 | U37: =T37 -> 0.56199678 | V37: =V33/V23 -> 0.82026225 | W37: =U37 -> 0.56199678 | X37: =W37 -> 0.56199678 | Y37: =X37 -> 0.56199678 | Z37: =Y37 -> 0.56199678 | AA37: =AA33/AA23 -> 0.54557518 | AB37: =Z37 -> 0.56199678 | AC37: =AB37 -> 0.56199678 | AD37: =AC37 -> 0.56199678 | AE37: =AD37 -> 0.56199678 | AF37: =AF33/AF23 -> 0.54263026 | AG37: =AE37 -> 0.56199678 | AH37: =AG37 -> 0.56199678 | AI37: =AH37 -> 0.56199678 | AJ37: =AI37 -> 0.56199678 | AK37: =AK33/AK23 -> 0.54150965
B39: Total Amortization | M39: =SUM(M40:M42) -> 1.82 | N39: =SUM(N40:N42) -> 3.839 | O39: =SUM(O40:O42) -> 6.672 | P39: =SUM(P40:P42) -> 8.412 | Q39: =SUM(Q40:Q42) -> 20.743 | R39: =SUM(R40:R42) -> 14.988778 | S39: =SUM(S40:S42) -> 14.492236 | T39: =SUM(T40:T42) -> 9.4026528 | ... AK39: =SUM(AK40:AK42) -> 438.11369
B40: Amortization - Capitalized Internally Developed Software | M40: ='Revenue and CapEx Build'!M111 -> 0.954 | N40: ='Revenue and CapEx Build'!N111 -> 1.364 | O40: ='Revenue and CapEx Build'!O111 -> 1.839 | P40: ='Revenue and CapEx Build'!P111 -> 2.415 | Q40: ='Revenue and CapEx Build'!Q111 -> 6.572 | R40: ='Revenue and CapEx Build'!R111 -> 3.6747778 | S40: ='Revenue and CapEx Build'!S111 -> 4.1191111 | T40: ='Revenue and CapEx Build'!T111 -> 3.4444444 | ... AK40: ='Revenue and CapEx Build'!AK111 -> 158.26141
B41: Amortization - Capitalized Labor | M41: ='Revenue and CapEx Build'!M112 -> 0.036 | N41: ='Revenue and CapEx Build'!N112 -> 0.075 | O41: ='Revenue and CapEx Build'!O112 -> 0.441 | P41: ='Revenue and CapEx Build'!P112 -> 0.662 | Q41: ='Revenue and CapEx Build'!Q112 -> 1.214 | R41: ='Revenue and CapEx Build'!R112 -> 2.0144167 | S41: ='Revenue and CapEx Build'!S112 -> 2.2358333 | T41: ='Revenue and CapEx Build'!T112 -> 1.873125 | ... AK41: ='Revenue and CapEx Build'!AK112 -> 104.97195
B42: Amortization - Capitalized Interest | M42: ='Revenue and CapEx Build'!M113 -> 0.83 | N42: ='Revenue and CapEx Build'!N113 -> 2.4 | O42: ='Revenue and CapEx Build'!O113 -> 4.392 | P42: ='Revenue and CapEx Build'!P113 -> 5.335 | Q42: ='Revenue and CapEx Build'!Q113 -> 12.957 | R42: ='Revenue and CapEx Build'!R113 -> 9.2995833 | S42: ='Revenue and CapEx Build'!S113 -> 8.1372917 | T42: ='Revenue and CapEx Build'!T113 -> 4.0850833 | ... AK42: ='Revenue and CapEx Build'!AK113 -> 174.88033
B44: Accumulated P&E Depreciation and Amortization | K44: =BS!K21 -> -116.796 | L44: =BS!L21 -> -116.796 | M44: =BS!M21 -> -195.782 | N44: =BS!N21 -> -359.722 | O44: =BS!O21 -> -612.217 | P44: =BS!P21 -> -965.231 | Q44: =BS!Q21 -> -965.231 | R44: =BS!R21 -> -1399.557 | ... AK44: =BS!AK21 -> -29856.109
B45: Accumulated Amortization | K45: ='Revenue and CapEx Build'!K116 -> -2.347 | L45: ='Revenue and CapEx Build'!L116 -> -2.347 | O45: ='Revenue and CapEx Build'!O116 -> -3.92 | P45: ='Revenue and CapEx Build'!P116 -> -4.441 | Q45: ='Revenue and CapEx Build'!Q116 -> -4.441 | R45: ='Revenue and CapEx Build'!R116 -> -4.955 | S45: ='Revenue and CapEx Build'!S116 -> -11.055 | T45: ='Revenue and CapEx Build'!T116 -> -20.564
B46: Accumulated Depreciation (Implied) | K46: =K44-K45 -> -114.449 | L46: =K46 -> -114.449 | O46: =O44-O45 -> -608.297 | P46: =P44-P45 -> -960.79 | Q46: =P46 -> -960.79 | R46: =R44-R45 -> -1394.602 | S46: =S44-S45 -> -1942.552 | T46: =T44-T45 -> -2554.014
B48: Property and Equipment, Net, Breakdown
B49: Technology Equipment | K49: ='Revenue and CapEx Build'!K120 -> 1298.127 | L49: ='Revenue and CapEx Build'!L120 -> 1298.127 | M49: 2500 | N49: 4000 | O49: ='Revenue and CapEx Build'!O120 -> 6886.183 | P49: ='Revenue and CapEx Build'!P120 -> 9146.575 | Q49: ='Revenue and CapEx Build'!Q120 -> 9146.575 | R49: ='Revenue and CapEx Build'!R120 -> 10746.445 | S49: ='Revenue and CapEx Build'!S120 -> 13170.295 | T49: ='Revenue and CapEx Build'!T120 -> 14628.79
B50: Software | K50: ='Revenue and CapEx Build'!K121 -> 14.937 | L50: ='Revenue and CapEx Build'!L121 -> 14.937 | O50: ='Revenue and CapEx Build'!O121 -> 69.209 | P50: ='Revenue and CapEx Build'!P121 -> 245.458 | Q50: ='Revenue and CapEx Build'!Q121 -> 245.458 | R50: ='Revenue and CapEx Build'!R121 -> 245.458 | S50: ='Revenue and CapEx Build'!S121 -> 459.742 | T50: ='Revenue and CapEx Build'!T121 -> 541.567
...

Sheet IS (GAAP)
B2: CoreWeave, Inc.
B3: Fiscal Year Ends Dec. 31
B4: ($ millions, except per share amounts)
C6: =Dates!C3 -> 2022 (A) | H6: =Dates!H3 -> 2023 (A) | M6: =Dates!M3 -> 2024 (A) | R6: =Dates!R3 -> 2025 (E) | W6: =Dates!W3 -> 2026 (E) | AB6: =Dates!AB3 -> 2027 (E) | AG6: =Dates!AG3 -> 2028 (E)
C7: =Dates!C4 -> 1Q22 (A) | D7: =Dates!D4 -> 2Q22 (A) | E7: =Dates!E4 -> 3Q22 (A) | F7: =Dates!F4 -> 4Q22 (A) | G7: =Dates!G4 -> FY22 (A) | H7: =Dates!H4 -> 1Q23 (A) | I7: =Dates!I4 -> 2Q23 (A) | J7: =Dates!J4 -> 3Q23 (A) | ... AK7: =Dates!AK4 -> FY28 (E)
C8: =Dates!C5 -> 44651 | D8: =Dates!D5 -> 44742 | E8: =Dates!E5 -> 44834 | F8: =Dates!F5 -> 44926 | G8: =Dates!G5 -> 44926 | H8: =Dates!H5 -> 45016 | I8: =Dates!I5 -> 45107 | J8: =Dates!J5 -> 45199 | ... AK8: =Dates!AK5 -> 47118
A10: TREV | B10: Total Revenue | G10: ='KPI Summary'!G10 -> 15.83 | H10: ='KPI Summary'!H10 -> 7.9236843 | I10: ='KPI Summary'!I10 -> 29.8436 | J10: ='KPI Summary'!J10 -> 75.178825 | K10: ='KPI Summary'!K10 -> 115.99689 | L10: ='KPI Summary'!L10 -> 228.943 | M10: ='KPI Summary'!M10 -> 188.684 | N10: ='KPI Summary'!N10 -> 395.371 | ... AK10: ='KPI Summary'!AK10 -> 21655.089
A11: TREVYY | B11: % yoy | H11: =IFERROR(H10/C10-1,"") | I11: =IFERROR(I10/D10-1,"") | J11: =IFERROR(J10/E10-1,"") | K11: =IFERROR(K10/F10-1,"") | L11: =IFERROR(L10/G10-1,"") -> 13.462603 | M11: =IFERROR(M10/H10-1,"") -> 22.81266 | N11: =IFERROR(N10/I10-1,"") -> 12.2481 | O11: =IFERROR(O10/J10-1,"") -> 6.76736 | ... AK11: =IFERROR(AK10/AF10-1,"") -> 0.25822019
A12: TREVQQ | B12: % qoq | H12: =IFERROR(H10/F10-1,"") | I12: =IFERROR(I10/H10-1,"") -> 2.7663793 | J12: =IFERROR(J10/I10-1,"") -> 1.5190937 | K12: =IFERROR(K10/J10-1,"") -> 0.5429463 | M12: =IFERROR(M10/K10-1,"") -> 0.62662981 | N12: =IFERROR(N10/M10-1,"") -> 1.0954135 | O12: =IFERROR(O10/N10-1,"") -> 0.47694444 | P12: =IFERROR(P10/O10-1,"") -> 0.2799752 | R12: =IFERROR(R10/P10-1,"") -> 0.31334306 | S12: =IFERROR(S10/R10-1,"") -> 0.23548132 | T12: =IFERROR(T10/S10-1,"") -> 0.12523871 | U12: =IFERROR(U10/T10-1,"") -> 0.13058326 | W12: =IFERROR(W10/U10-1,"") -> 0.44348713 | X12: =IFERROR(X10/W10-1,"") -> 0.33094883 | Y12: =IFERROR(Y10/X10-1,"") -> 0.10980793 | Z12: =IFERROR(Z10/Y10-1,"") -> 0.070204816 | AB12: =IFERROR(AB10/Z10-1,"") -> 0.082649169 | AC12: =IFERROR(AC10/AB10-1,"") -> 0.089818799 | AD12: =IFERROR(AD10/AC10-1,"") -> 0.077002222 | AE12: =IFERROR(AE10/AD10-1,"") -> 0.066529754 | AG12: =IFERROR(AG10/AE10-1,"") -> 0.072718069 | AH12: =IFERROR(AH10/AG10-1,"") -> 0.041288386 | AI12: =IFERROR(AI10/AH10-1,"") -> 0.035552396 | AJ12: =IFERROR(AJ10/AI10-1,"") -> 0.030497879
A14: GAAPCOGS | B14: Cost of Revenue | G14: 12.122 | H14: =M14/(1+M15) -> 4.7868239 | I14: =N14/(1+N15) -> 9.7875371 | J14: =O14/(1+O15) -> 19.315417 | K14: =L14-J14-I14-H14 -> 34.890222 | L14: 68.78 | M14: 59.22 | N14: 108.838 | O14: 143.134 | P14: 182.158 | Q14: =SUM(M14:P14) -> 493.35 | R14: 262.394 | S14: 312.667 | T14: 368.824 | U14: ='IS (Non-GAAP)'!U14+'IS (Non-GAAP)'!U102 -> 426.87781 | V14: =SUM(R14:U14) -> 1370.7628 | W14: ='IS (Non-GAAP)'!W14+'IS (Non-GAAP)'!W102 -> 553.04022 | X14: ='IS (Non-GAAP)'!X14+'IS (Non-GAAP)'!X102 -> 736.30537 | Y14: ='IS (Non-GAAP)'!Y14+'IS (Non-GAAP)'!Y102 -> 815.57849 | Z14: ='IS (Non-GAAP)'!Z14+'IS (Non-GAAP)'!Z102 -> 871.14612 | AA14: =SUM(W14:Z14) -> 2976.0702 | AB14: ='IS (Non-GAAP)'!AB14+'IS (Non-GAAP)'!AB102 -> 880.9401 | AC14: ='IS (Non-GAAP)'!AC14+'IS (Non-GAAP)'!AC102 -> 967.70163 | AD14: ='IS (Non-GAAP)'!AD14+'IS (Non-GAAP)'!AD102 -> 1028.0868 | AE14: ='IS (Non-GAAP)'!AE14+'IS (Non-GAAP)'!AE102 -> 1105.2569 | AF14: =SUM(AB14:AE14) -> 3981.9854 | AG14: ='IS (Non-GAAP)'!AG14+'IS (Non-GAAP)'!AG102 -> 1102.096 | AH14: ='IS (Non-GAAP)'!AH14+'IS (Non-GAAP)'!AH102 -> 1146.1389 | AI14: ='IS (Non-GAAP)'!AI14+'IS (Non-GAAP)'!AI102 -> 1181.1142 | AJ14: ='IS (Non-GAAP)'!AJ14+'IS (Non-GAAP)'!AJ102 -> 1215.5768 | AK14: =SUM(AG14:AJ14) -> 4644.9259
A15: GAAPCOGSYY | B15: % yoy | H15: =IFERROR(H14/C14-1,"") | I15: =IFERROR(I14/D14-1,"") | J15: =IFERROR(J14/E14-1,"") | K15: =IFERROR(K14/F14-1,"") | L15: =IFERROR(L14/G14-1,"") -> 4.6739812 | M15: 11.37146 | N15: 10.12006 | O15: 6.41035 | P15: =IFERROR(P14/K14-1,"") -> 4.2208897 | Q15: =IFERROR(Q14/L14-1,"") -> 6.17287 | R15: =IFERROR(R14/M14-1,"") -> 3.4308342 | S15: =IFERROR(S14/N14-1,"") -> 1.8727742 | T15: =IFERROR(T14/O14-1,"") -> 1.5767742 | U15: =IFERROR(U14/P14-1,"") -> 1.343448 | V15: =IFERROR(V14/Q14-1,"") -> 1.7784794 | W15: =IFERROR(W14/R14-1,"") -> 1.107671 | ... AK15: =IFERROR(AK14/AF14-1,"") -> 0.16648492
A16: GAAPCOGSQQ | B16: % qoq | H16: =IFERROR(H14/F14-1,"") | I16: =IFERROR(I14/H14-1,"") -> 1.0446829 | J16: =IFERROR(J14/I14-1,"") -> 0.97347062 | K16: =IFERROR(K14/J14-1,"") -> 0.80634061 | M16: =IFERROR(M14/K14-1,"") -> 0.69732368 | N16: =IFERROR(N14/M14-1,"") -> 0.83785883 | O16: =IFERROR(O14/N14-1,"") -> 0.31511053 | P16: =IFERROR(P14/O14-1,"") -> 0.27263962 | R16: =IFERROR(R14/P14-1,"") -> 0.44047475 | S16: =IFERROR(S14/R14-1,"") -> 0.19159356 | T16: =IFERROR(T14/S14-1,"") -> 0.17960642 | U16: =IFERROR(U14/T14-1,"") -> 0.15740247 | W16: =IFERROR(W14/U14-1,"") -> 0.29554691 | X16: =IFERROR(X14/W14-1,"") -> 0.33137761 | Y16: =IFERROR(Y14/X14-1,"") -> 0.10766337 | Z16: =IFERROR(Z14/Y14-1,"") -> 0.068132784 | AB16: =IFERROR(AB14/Z14-1,"") -> 0.011242628 | AC16: =IFERROR(AC14/AB14-1,"") -> 0.09848744 | AD16: =IFERROR(AD14/AC14-1,"") -> 0.062400569 | AE16: =IFERROR(AE14/AD14-1,"") -> 0.075061878 | AG16: =IFERROR(AG14/AE14-1,"") -> -0.0028599041 | AH16: =IFERROR(AH14/AG14-1,"") -> 0.039962914 | AI16: =IFERROR(AI14/AH14-1,"") -> 0.030515746 | AJ16: =IFERROR(AJ14/AI14-1,"") -> 0.029178052
A18: GAAPGP | B18: Gross Profit | G18: =G10-G14 -> 3.708 | H18: =H10-H14 -> 3.1368604 | I18: =I10-I14 -> 20.056063 | J18: =J10-J14 -> 55.863408 | K18: =K10-K14 -> 81.106668 | L18: =L10-L14 -> 160.163 | M18: =M10-M14 -> 129.464 | N18: =N10-N14 -> 286.533 | ... AK18: =AK10-AK14 -> 17010.163
A19: GAAPGPYY | B19: % yoy | H19: =IFERROR(H18/C18-1,"") | I19: =IFERROR(I18/D18-1,"") | J19: =IFERROR(J18/E18-1,"") | K19: =IFERROR(K18/F18-1,"") | L19: =IFERROR(L18/G18-1,"") -> 42.193905 | M19: =IFERROR(M18/H18-1,"") -> 40.27184 | N19: =IFERROR(N18/I18-1,"") -> 13.286602 | O19: =IFERROR(O18/J18-1,"") -> 6.8908003 | ... AK19: =IFERROR(AK18/AF18-1,"") -> 0.2858331
A20: GAAPGPQQ | B20: % qoq | H20: =IFERROR(H18/F18-1,"") | I20: =IFERROR(I18/H18-1,"") -> 5.393674 | J20: =IFERROR(J18/I18-1,"") -> 1.7853626 | K20: =IFERROR(K18/J18-1,"") -> 0.45187468 | M20: =IFERROR(M18/K18-1,"") -> 0.59621894 | N20: =IFERROR(N18/M18-1,"") -> 1.2132253 | O20: =IFERROR(O18/N18-1,"") -> 0.53841617 | P20: =IFERROR(P18/O18-1,"") -> 0.28235713 | R20: =IFERROR(R18/P18-1,"") -> 0.27237507 | S20: =IFERROR(S18/R18-1,"") -> 0.25149255 | T20: =IFERROR(T18/S18-1,"") -> 0.10635348 | U20: =IFERROR(U18/T18-1,"") -> 0.12065049 | W20: =IFERROR(W18/U18-1,"") -> 0.5000752 | X20: =IFERROR(X18/W18-1,"") -> 0.33080718 | Y20: =IFERROR(Y18/X18-1,"") -> 0.11051669 | Z20: =IFERROR(Z18/Y18-1,"") -> 0.070887853 | AB20: =IFERROR(AB18/Z18-1,"") -> 0.10612748 | AC20: =IFERROR(AC18/AB18-1,"") -> 0.087213066 | AD20: =IFERROR(AD18/AC18-1,"") -> 0.081436894 | AE20: =IFERROR(AE18/AD18-1,"") -> 0.063984074 | AG20: =IFERROR(AG18/AE18-1,"") -> 0.095502599 | AH20: =IFERROR(AH18/AG18-1,"") -> 0.041652098 | AI20: =IFERROR(AI18/AH18-1,"") -> 0.036932223 | AJ20: =IFERROR(AJ18/AI18-1,"") -> 0.030857217
A21: GAAPGPM | B21: Gross Margin | C21: =IFERROR(C18/C$10,"") | D21: =IFERROR(D18/D$10,"") | E21: =IFERROR(E18/E$10,"") | F21: =IFERROR(F18/F$10,"") | G21: =IFERROR(G18/G$10,"") -> 0.23423879 | H21: =IFERROR(H18/H$10,"") -> 0.39588407 | I21: =IFERROR(I18/I$10,"") -> 0.672039 | J21: =IFERROR(J18/J$10,"") -> 0.74307371 | ... AK21: =IFERROR(AK18/AK$10,"") -> 0.78550419
B23: Technology and Infrastructure | G23: 18.106 | H23: =M23/(1+M24) -> 8.8592249 | I23: =N23/(1+N24) -> 17.162371 | J23: =O23/(1+O24) -> 39.900803 | K23: =L23-J23-I23-H23 -> 65.932601 | L23: 131.855 | M23: 92.881 | N23: 182.886 | O23: 285.509 | P23: 399.409 | Q23: =SUM(M23:P23) -> 960.685 | R23: 561.402 | S23: 669.913 | T23: 747.479 | U23: ='IS (Non-GAAP)'!U23+'IS (Non-GAAP)'!U103 -> 918.00515 | V23: =SUM(R23:U23) -> 2896.7991 | W23: ='IS (Non-GAAP)'!W23+'IS (Non-GAAP)'!W103 -> 1249.5854 | X23: ='IS (Non-GAAP)'!X23+'IS (Non-GAAP)'!X103 -> 1614.4329 | Y23: ='IS (Non-GAAP)'!Y23+'IS (Non-GAAP)'!Y103 -> 1807.4273 | Z23: ='IS (Non-GAAP)'!Z23+'IS (Non-GAAP)'!Z103 -> 1915.6002 | AA23: =SUM(W23:Z23) -> 6587.0458 | AB23: ='IS (Non-GAAP)'!AB23+'IS (Non-GAAP)'!AB103 -> 2097.7557 | AC23: ='IS (Non-GAAP)'!AC23+'IS (Non-GAAP)'!AC103 -> 2289.3596 | AD23: ='IS (Non-GAAP)'!AD23+'IS (Non-GAAP)'!AD103 -> 2456.7758 | AE23: ='IS (Non-GAAP)'!AE23+'IS (Non-GAAP)'!AE103 -> 2712.6216 | AF23: =SUM(AB23:AE23) -> 9556.5128 | AG23: ='IS (Non-GAAP)'!AG23+'IS (Non-GAAP)'!AG103 -> 2888.1232 | AH23: ='IS (Non-GAAP)'!AH23+'IS (Non-GAAP)'!AH103 -> 3066.4277 | AI23: ='IS (Non-GAAP)'!AI23+'IS (Non-GAAP)'!AI103 -> 3185.8296 | AJ23: ='IS (Non-GAAP)'!AJ23+'IS (Non-GAAP)'!AJ103 -> 3392.3536 | AK23: =SUM(AG23:AJ23) -> 12532.734
